Workbook

Sheet Resumen
A1: Fondo General de Participaciones 2027 con población de la Encuesta Intercensal 2025
A2: Cambio por entidad al sustituir la población ENOE 3T-2025 (DOF enero 2026) por la EIC 2025. Variables económicas del DOF de agosto 2026 y RFP del PPEF 2027. Todo lo demás constante.
F5: Monto redistribuido: | G5: =-SUMIF(G7:G38,"<0") -> 8.7680552e+09 | X5: Datos de la gráfica (ordenados)
A6: Entidad | B6: FGP 2027 con población ENOE 3T-2025 (pesos) | C6: Cambio primera parte (Cuadro 3) | D6: Cambio segunda parte (Cuadro 4) | E6: Cambio tercera parte (Cuadro 5) | F6: FGP 2027 con EIC 2025 (pesos) | G6: Cambio FGP (pesos) | H6: Cambio FGP (%) | X6: Entidad | Y6: Cambio FGP (%) | Z6: Gana | AA6: Pierde
A7: Aguascalientes | B7: ='Cuadro 7'!F7 -> 1.2224846e+10 | C7: ='Cuadro 3'!L7 -> 1.3300984e+08 | D7: ='Cuadro 4'!M7 -> 69267997 | E7: ='Cuadro 5'!J7 -> 5618893.4 | F7: =B7+G7 -> 1.2432742e+10 | G7: =C7+D7+E7 -> 2.0789673e+08 | H7: =G7/B7 -> 0.017006082 | X7: =INDEX($A$7:$A$38,MATCH(Y7,$H$7:$H$38,0)) -> Guerrero | Y7: =SMALL($H$7:$H$38,1) -> -0.041932115 | Z7: =IF(Y7>=0,Y7*100,0) -> 0 | AA7: =IF(Y7<0,Y7*100,0) -> -4.1932115
A8: Baja California | B8: ='Cuadro 7'!F8 -> 3.3375251e+10 | C8: ='Cuadro 3'!L8 -> 8.9717367e+08 | D8: ='Cuadro 4'!M8 -> 4.7515691e+08 | E8: ='Cuadro 5'!J8 -> 1.8479651e+08 | F8: =B8+G8 -> 3.4932378e+10 | G8: =C8+D8+E8 -> 1.5571271e+09 | H8: =G8/B8 -> 0.046655142 | X8: =INDEX($A$7:$A$38,MATCH(Y8,$H$7:$H$38,0)) -> Tlaxcala | Y8: =SMALL($H$7:$H$38,2) -> -0.030443403 | Z8: =IF(Y8>=0,Y8*100,0) -> 0 | AA8: =IF(Y8<0,Y8*100,0) -> -3.0443403
A9: Baja California Sur | B9: ='Cuadro 7'!F9 -> 7.4062421e+09 | C9: ='Cuadro 3'!L9 -> 3.2488481e+08 | D9: ='Cuadro 4'!M9 -> 1.5667143e+08 | E9: ='Cuadro 5'!J9 -> 12351371 | F9: =B9+G9 -> 7.9001497e+09 | G9: =C9+D9+E9 -> 4.9390761e+08 | H9: =G9/B9 -> 0.066688019 | X9: =INDEX($A$7:$A$38,MATCH(Y9,$H$7:$H$38,0)) -> Veracruz | Y9: =SMALL($H$7:$H$38,3) -> -0.019052761 | Z9: =IF(Y9>=0,Y9*100,0) -> 0 | AA9: =IF(Y9<0,Y9*100,0) -> -1.9052761
A10: Campeche | B10: ='Cuadro 7'!F10 -> 7.5991356e+09 | C10: ='Cuadro 3'!L10 -> 1.381878e+08 | D10: ='Cuadro 4'!M10 -> 77971976 | E10: ='Cuadro 5'!J10 -> 3565762.7 | F10: =B10+G10 -> 7.8188611e+09 | G10: =C10+D10+E10 -> 2.1972554e+08 | H10: =G10/B10 -> 0.028914543 | X10: =INDEX($A$7:$A$38,MATCH(Y10,$H$7:$H$38,0)) -> Chiapas | Y10: =SMALL($H$7:$H$38,4) -> -0.015345852 | Z10: =IF(Y10>=0,Y10*100,0) -> 0 | AA10: =IF(Y10<0,Y10*100,0) -> -1.5345852
A11: Coahuila | B11: ='Cuadro 7'!F11 -> 2.8877688e+10 | C11: ='Cuadro 3'!L11 -> -1.6599195e+08 | D11: ='Cuadro 4'!M11 -> -87844176 | E11: ='Cuadro 5'!J11 -> -11903172 | F11: =B11+G11 -> 2.8611949e+10 | G11: =C11+D11+E11 -> -2.6573929e+08 | H11: =G11/B11 -> -0.0092022358 | X11: =INDEX($A$7:$A$38,MATCH(Y11,$H$7:$H$38,0)) -> Chihuahua | Y11: =SMALL($H$7:$H$38,5) -> -0.014658746 | Z11: =IF(Y11>=0,Y11*100,0) -> 0 | AA11: =IF(Y11<0,Y11*100,0) -> -1.4658746
A12: Colima | B12: ='Cuadro 7'!F12 -> 6.3908501e+09 | C12: ='Cuadro 3'!L12 -> 1.3069625e+08 | D12: ='Cuadro 4'!M12 -> 64567421 | E12: ='Cuadro 5'!J12 -> 2635678 | F12: =B12+G12 -> 6.5887495e+09 | G12: =C12+D12+E12 -> 1.9789935e+08 | H12: =G12/B12 -> 0.030966044 | X12: =INDEX($A$7:$A$38,MATCH(Y12,$H$7:$H$38,0)) -> Oaxaca | Y12: =SMALL($H$7:$H$38,6) -> -0.012882858 | Z12: =IF(Y12>=0,Y12*100,0) -> 0 | AA12: =IF(Y12<0,Y12*100,0) -> -1.2882858
A13: Chiapas | B13: ='Cuadro 7'!F13 -> 5.0691977e+10 | C13: ='Cuadro 3'!L13 -> -4.8882514e+08 | D13: ='Cuadro 4'!M13 -> -2.694997e+08 | E13: ='Cuadro 5'!J13 -> -19586725 | F13: =B13+G13 -> 4.9914065e+10 | G13: =C13+D13+E13 -> -7.7791156e+08 | H13: =G13/B13 -> -0.015345852 | X13: =INDEX($A$7:$A$38,MATCH(Y13,$H$7:$H$38,0)) -> Michoacán | Y13: =SMALL($H$7:$H$38,7) -> -0.01067688 | Z13: =IF(Y13>=0,Y13*100,0) -> 0 | AA13: =IF(Y13<0,Y13*100,0) -> -1.067688
A14: Chihuahua | B14: ='Cuadro 7'!F14 -> 3.3916363e+10 | C14: ='Cuadro 3'!L14 -> -3.0246052e+08 | D14: ='Cuadro 4'!M14 -> -1.5002785e+08 | E14: ='Cuadro 5'!J14 -> -44682967 | F14: =B14+G14 -> 3.3419191e+10 | G14: =C14+D14+E14 -> -4.9717134e+08 | H14: =G14/B14 -> -0.014658746 | X14: =INDEX($A$7:$A$38,MATCH(Y14,$H$7:$H$38,0)) -> Sinaloa | Y14: =SMALL($H$7:$H$38,8) -> -0.010650212 | Z14: =IF(Y14>=0,Y14*100,0) -> 0 | AA14: =IF(Y14<0,Y14*100,0) -> -1.0650212
A15: Ciudad de México | B15: ='Cuadro 7'!F15 -> 1.1346411e+11 | C15: ='Cuadro 3'!L15 -> -5.8690615e+08 | D15: ='Cuadro 4'!M15 -> -2.9947763e+08 | E15: ='Cuadro 5'!J15 -> -2.8341154e+08 | F15: =B15+G15 -> 1.1229432e+11 | G15: =C15+D15+E15 -> -1.1697953e+09 | H15: =G15/B15 -> -0.010309827 | X15: =INDEX($A$7:$A$38,MATCH(Y15,$H$7:$H$38,0)) -> Ciudad de México | Y15: =SMALL($H$7:$H$38,9) -> -0.010309827 | Z15: =IF(Y15>=0,Y15*100,0) -> 0 | AA15: =IF(Y15<0,Y15*100,0) -> -1.0309827
A16: Durango | B16: ='Cuadro 7'!F16 -> 1.6000942e+10 | C16: ='Cuadro 3'!L16 -> -14297637 | D16: ='Cuadro 4'!M16 -> -7538696.3 | E16: ='Cuadro 5'!J16 -> 410655.92 | F16: =B16+G16 -> 1.5979516e+10 | G16: =C16+D16+E16 -> -21425677 | H16: =G16/B16 -> -0.001339026 | X16: =INDEX($A$7:$A$38,MATCH(Y16,$H$7:$H$38,0)) -> Coahuila | Y16: =SMALL($H$7:$H$38,10) -> -0.0092022358 | Z16: =IF(Y16>=0,Y16*100,0) -> 0 | AA16: =IF(Y16<0,Y16*100,0) -> -0.92022358
A17: Guanajuato | B17: ='Cuadro 7'!F17 -> 5.2243079e+10 | C17: ='Cuadro 3'!L17 -> 3.8643376e+08 | D17: ='Cuadro 4'!M17 -> 1.8465759e+08 | E17: ='Cuadro 5'!J17 -> 62699211 | F17: =B17+G17 -> 5.287687e+10 | G17: =C17+D17+E17 -> 6.3379055e+08 | H17: =G17/B17 -> 0.01213157 | X17: =INDEX($A$7:$A$38,MATCH(Y17,$H$7:$H$38,0)) -> México | Y17: =SMALL($H$7:$H$38,11) -> -0.0082856551 | Z17: =IF(Y17>=0,Y17*100,0) -> 0 | AA17: =IF(Y17<0,Y17*100,0) -> -0.82856551
A18: Guerrero | B18: ='Cuadro 7'!F18 -> 2.8316544e+10 | C18: ='Cuadro 3'!L18 -> -7.7403553e+08 | D18: ='Cuadro 4'!M18 -> -3.9025311e+08 | E18: ='Cuadro 5'!J18 -> -23083955 | F18: =B18+G18 -> 2.7129172e+10 | G18: =C18+D18+E18 -> -1.1873726e+09 | H18: =G18/B18 -> -0.041932115 | X18: =INDEX($A$7:$A$38,MATCH(Y18,$H$7:$H$38,0)) -> Tabasco | Y18: =SMALL($H$7:$H$38,12) -> -0.0065921311 | Z18: =IF(Y18>=0,Y18*100,0) -> 0 | AA18: =IF(Y18<0,Y18*100,0) -> -0.65921311
A19: Hidalgo | B19: ='Cuadro 7'!F19 -> 2.5163766e+10 | C19: ='Cuadro 3'!L19 -> -26846721 | D19: ='Cuadro 4'!M19 -> -13752490 | E19: ='Cuadro 5'!J19 -> 637152.12 | F19: =B19+G19 -> 2.5123804e+10 | G19: =C19+D19+E19 -> -39962059 | H19: =G19/B19 -> -0.0015880794 | X19: =INDEX($A$7:$A$38,MATCH(Y19,$H$7:$H$38,0)) -> Jalisco | Y19: =SMALL($H$7:$H$38,13) -> -0.0058565064 | Z19: =IF(Y19>=0,Y19*100,0) -> 0 | AA19: =IF(Y19<0,Y19*100,0) -> -0.58565064
A20: Jalisco | B20: ='Cuadro 7'!F20 -> 7.813887e+10 | C20: ='Cuadro 3'!L20 -> -2.785258e+08 | D20: ='Cuadro 4'!M20 -> -1.4278943e+08 | E20: ='Cuadro 5'!J20 -> -36305557 | F20: =B20+G20 -> 7.7681249e+10 | G20: =C20+D20+E20 -> -4.5762079e+08 | H20: =G20/B20 -> -0.0058565064 | X20: =INDEX($A$7:$A$38,MATCH(Y20,$H$7:$H$38,0)) -> Zacatecas | Y20: =SMALL($H$7:$H$38,14) -> -0.0050179534 | Z20: =IF(Y20>=0,Y20*100,0) -> 0 | AA20: =IF(Y20<0,Y20*100,0) -> -0.50179534
A21: México | B21: ='Cuadro 7'!F21 -> 1.6380318e+11 | C21: ='Cuadro 3'!L21 -> -7.8918001e+08 | D21: ='Cuadro 4'!M21 -> -3.9328382e+08 | E21: ='Cuadro 5'!J21 -> -1.7475281e+08 | F21: =B21+G21 -> 1.6244596e+11 | G21: =C21+D21+E21 -> -1.3572166e+09 | H21: =G21/B21 -> -0.0082856551 | X21: =INDEX($A$7:$A$38,MATCH(Y21,$H$7:$H$38,0)) -> Hidalgo | Y21: =SMALL($H$7:$H$38,15) -> -0.0015880794 | Z21: =IF(Y21>=0,Y21*100,0) -> 0 | AA21: =IF(Y21<0,Y21*100,0) -> -0.15880794
A22: Michoacán | B22: ='Cuadro 7'!F22 -> 3.7856667e+10 | C22: ='Cuadro 3'!L22 -> -2.657923e+08 | D22: ='Cuadro 4'!M22 -> -1.2631091e+08 | E22: ='Cuadro 5'!J22 -> -12087854 | F22: =B22+G22 -> 3.7452476e+10 | G22: =C22+D22+E22 -> -4.0419107e+08 | H22: =G22/B22 -> -0.01067688 | X22: =INDEX($A$7:$A$38,MATCH(Y22,$H$7:$H$38,0)) -> Durango | Y22: =SMALL($H$7:$H$38,16) -> -0.001339026 | Z22: =IF(Y22>=0,Y22*100,0) -> 0 | AA22: =IF(Y22<0,Y22*100,0) -> -0.1339026
A23: Morelos | B23: ='Cuadro 7'!F23 -> 1.5907079e+10 | C23: ='Cuadro 3'!L23 -> 42546314 | D23: ='Cuadro 4'!M23 -> 21062998 | E23: ='Cuadro 5'!J23 -> 2123402 | F23: =B23+G23 -> 1.5972812e+10 | G23: =C23+D23+E23 -> 65732714 | H23: =G23/B23 -> 0.0041322932 | X23: =INDEX($A$7:$A$38,MATCH(Y23,$H$7:$H$38,0)) -> San Luis Potosí | Y23: =SMALL($H$7:$H$38,17) -> 0.00031146269 | Z23: =IF(Y23>=0,Y23*100,0) -> 0.031146269 | AA23: =IF(Y23<0,Y23*100,0) -> 0
A24: Nayarit | B24: ='Cuadro 7'!F24 -> 1.0141825e+10 | C24: ='Cuadro 3'!L24 -> 2.0529531e+08 | D24: ='Cuadro 4'!M24 -> 1.0638601e+08 | E24: ='Cuadro 5'!J24 -> 5659284.2 | F24: =B24+G24 -> 1.0459165e+10 | G24: =C24+D24+E24 -> 3.1734061e+08 | H24: =G24/B24 -> 0.031290286 | X24: =INDEX($A$7:$A$38,MATCH(Y24,$H$7:$H$38,0)) -> Sonora | Y24: =SMALL($H$7:$H$38,18) -> 0.0012058401 | Z24: =IF(Y24>=0,Y24*100,0) -> 0.12058401 | AA24: =IF(Y24<0,Y24*100,0) -> 0
A25: Nuevo León | B25: ='Cuadro 7'!F25 -> 5.6885674e+10 | C25: ='Cuadro 3'!L25 -> 5.4595525e+08 | D25: ='Cuadro 4'!M25 -> 2.6287322e+08 | E25: ='Cuadro 5'!J25 -> 1.6572839e+08 | F25: =B25+G25 -> 5.786023e+10 | G25: =C25+D25+E25 -> 9.7455686e+08 | H25: =G25/B25 -> 0.017131851 | X25: =INDEX($A$7:$A$38,MATCH(Y25,$H$7:$H$38,0)) -> Morelos | Y25: =SMALL($H$7:$H$38,19) -> 0.0041322932 | Z25: =IF(Y25>=0,Y25*100,0) -> 0.41322932 | AA25: =IF(Y25<0,Y25*100,0) -> 0
A26: Oaxaca | B26: ='Cuadro 7'!F26 -> 3.3500007e+10 | C26: ='Cuadro 3'!L26 -> -2.8359455e+08 | D26: ='Cuadro 4'!M26 -> -1.4062934e+08 | E26: ='Cuadro 5'!J26 -> -7351930.7 | F26: =B26+G26 -> 3.3068431e+10 | G26: =C26+D26+E26 -> -4.3157581e+08 | H26: =G26/B26 -> -0.012882858 | X26: =INDEX($A$7:$A$38,MATCH(Y26,$H$7:$H$38,0)) -> Tamaulipas | Y26: =SMALL($H$7:$H$38,20) -> 0.010029154 | Z26: =IF(Y26>=0,Y26*100,0) -> 1.0029154 | AA26: =IF(Y26<0,Y26*100,0) -> 0
A27: Puebla | B27: ='Cuadro 7'!F27 -> 5.2991526e+10 | C27: ='Cuadro 3'!L27 -> 8.8618652e+08 | D27: ='Cuadro 4'!M27 -> 4.229256e+08 | E27: ='Cuadro 5'!J27 -> 68806857 | F27: =B27+G27 -> 5.4369445e+10 | G27: =C27+D27+E27 -> 1.377919e+09 | H27: =G27/B27 -> 0.026002629 | X27: =INDEX($A$7:$A$38,MATCH(Y27,$H$7:$H$38,0)) -> Guanajuato | Y27: =SMALL($H$7:$H$38,21) -> 0.01213157 | Z27: =IF(Y27>=0,Y27*100,0) -> 1.213157 | AA27: =IF(Y27<0,Y27*100,0) -> 0
A28: Querétaro | B28: ='Cuadro 7'!F28 -> 2.051149e+10 | C28: ='Cuadro 3'!L28 -> 2.989565e+08 | D28: ='Cuadro 4'!M28 -> 1.4688157e+08 | E28: ='Cuadro 5'!J28 -> 33433674 | F28: =B28+G28 -> 2.0990762e+10 | G28: =C28+D28+E28 -> 4.7927174e+08 | H28: =G28/B28 -> 0.023366013 | X28: =INDEX($A$7:$A$38,MATCH(Y28,$H$7:$H$38,0)) -> Aguascalientes | Y28: =SMALL($H$7:$H$38,22) -> 0.017006082 | Z28: =IF(Y28>=0,Y28*100,0) -> 1.7006082 | AA28: =IF(Y28<0,Y28*100,0) -> 0
A29: Quintana Roo | B29: ='Cuadro 7'!F29 -> 1.5501734e+10 | C29: ='Cuadro 3'!L29 -> 7.5078843e+08 | D29: ='Cuadro 4'!M29 -> 4.084407e+08 | E29: ='Cuadro 5'!J29 -> 93059432 | F29: =B29+G29 -> 1.6754023e+10 | G29: =C29+D29+E29 -> 1.2522886e+09 | H29: =G29/B29 -> 0.080783772 | X29: =INDEX($A$7:$A$38,MATCH(Y29,$H$7:$H$38,0)) -> Nuevo León | Y29: =SMALL($H$7:$H$38,23) -> 0.017131851 | Z29: =IF(Y29>=0,Y29*100,0) -> 1.7131851 | AA29: =IF(Y29<0,Y29*100,0) -> 0
A30: San Luis Potosí | B30: ='Cuadro 7'!F30 -> 2.3065042e+10 | C30: ='Cuadro 3'!L30 -> 3575503.6 | D30: ='Cuadro 4'!M30 -> 1390396 | E30: ='Cuadro 5'!J30 -> 2218000.7 | F30: =B30+G30 -> 2.3072226e+10 | G30: =C30+D30+E30 -> 7183900.2 | H30: =G30/B30 -> 0.00031146269 | X30: =INDEX($A$7:$A$38,MATCH(Y30,$H$7:$H$38,0)) -> Querétaro | Y30: =SMALL($H$7:$H$38,24) -> 0.023366013 | Z30: =IF(Y30>=0,Y30*100,0) -> 2.3366013 | AA30: =IF(Y30<0,Y30*100,0) -> 0
A31: Sinaloa | B31: ='Cuadro 7'!F31 -> 2.5669044e+10 | C31: ='Cuadro 3'!L31 -> -1.7652595e+08 | D31: ='Cuadro 4'!M31 -> -85860340 | E31: ='Cuadro 5'!J31 -> -10994463 | F31: =B31+G31 -> 2.5395664e+10 | G31: =C31+D31+E31 -> -2.7338076e+08 | H31: =G31/B31 -> -0.010650212 | X31: =INDEX($A$7:$A$38,MATCH(Y31,$H$7:$H$38,0)) -> Puebla | Y31: =SMALL($H$7:$H$38,25) -> 0.026002629 | Z31: =IF(Y31>=0,Y31*100,0) -> 2.6002629 | AA31: =IF(Y31<0,Y31*100,0) -> 0
A32: Sonora | B32: ='Cuadro 7'!F32 -> 2.6073392e+10 | C32: ='Cuadro 3'!L32 -> 17290539 | D32: ='Cuadro 4'!M32 -> 8465150.8 | E32: ='Cuadro 5'!J32 -> 5684652.1 | F32: =B32+G32 -> 2.6104832e+10 | G32: =C32+D32+E32 -> 31440342 | H32: =G32/B32 -> 0.0012058401 | X32: =INDEX($A$7:$A$38,MATCH(Y32,$H$7:$H$38,0)) -> Campeche | Y32: =SMALL($H$7:$H$38,26) -> 0.028914543 | Z32: =IF(Y32>=0,Y32*100,0) -> 2.8914543 | AA32: =IF(Y32<0,Y32*100,0) -> 0
A33: Tabasco | B33: ='Cuadro 7'!F33 -> 2.5422742e+10 | C33: ='Cuadro 3'!L33 -> -1.0468583e+08 | D33: ='Cuadro 4'!M33 -> -60417504 | E33: ='Cuadro 5'!J33 -> -2486714 | F33: =B33+G33 -> 2.5255152e+10 | G33: =C33+D33+E33 -> -1.6759004e+08 | H33: =G33/B33 -> -0.0065921311 | X33: =INDEX($A$7:$A$38,MATCH(Y33,$H$7:$H$38,0)) -> Colima | Y33: =SMALL($H$7:$H$38,27) -> 0.030966044 | Z33: =IF(Y33>=0,Y33*100,0) -> 3.0966044 | AA33: =IF(Y33<0,Y33*100,0) -> 0
A34: Tamaulipas | B34: ='Cuadro 7'!F34 -> 3.0423354e+10 | C34: ='Cuadro 3'!L34 -> 1.9080256e+08 | D34: ='Cuadro 4'!M34 -> 92722423 | E34: ='Cuadro 5'!J34 -> 21595509 | F34: =B34+G34 -> 3.0728475e+10 | G34: =C34+D34+E34 -> 3.051205e+08 | H34: =G34/B34 -> 0.010029154 | X34: =INDEX($A$7:$A$38,MATCH(Y34,$H$7:$H$38,0)) -> Nayarit | Y34: =SMALL($H$7:$H$38,28) -> 0.031290286 | Z34: =IF(Y34>=0,Y34*100,0) -> 3.1290286 | AA34: =IF(Y34<0,Y34*100,0) -> 0
A35: Tlaxcala | B35: ='Cuadro 7'!F35 -> 1.1699868e+10 | C35: ='Cuadro 3'!L35 -> -2.3555414e+08 | D35: ='Cuadro 4'!M35 -> -1.1778023e+08 | E35: ='Cuadro 5'!J35 -> -2849438.2 | F35: =B35+G35 -> 1.1343685e+10 | G35: =C35+D35+E35 -> -3.5618381e+08 | H35: =G35/B35 -> -0.030443403 | X35: =INDEX($A$7:$A$38,MATCH(Y35,$H$7:$H$38,0)) -> Yucatán | Y35: =SMALL($H$7:$H$38,29) -> 0.033272313 | Z35: =IF(Y35>=0,Y35*100,0) -> 3.3272313 | AA35: =IF(Y35<0,Y35*100,0) -> 0
A36: Veracruz | B36: ='Cuadro 7'!F36 -> 6.77041e+10 | C36: ='Cuadro 3'!L36 -> -8.3085809e+08 | D36: ='Cuadro 4'!M36 -> -3.9473337e+08 | E36: ='Cuadro 5'!J36 -> -64358598 | F36: =B36+G36 -> 6.641415e+10 | G36: =C36+D36+E36 -> -1.2899501e+09 | H36: =G36/B36 -> -0.019052761 | X36: =INDEX($A$7:$A$38,MATCH(Y36,$H$7:$H$38,0)) -> Baja California | Y36: =SMALL($H$7:$H$38,30) -> 0.046655142 | Z36: =IF(Y36>=0,Y36*100,0) -> 4.6655142 | AA36: =IF(Y36<0,Y36*100,0) -> 0
A37: Yucatán | B37: ='Cuadro 7'!F37 -> 1.9441213e+10 | C37: ='Cuadro 3'!L37 -> 4.2020829e+08 | D37: ='Cuadro 4'!M37 -> 2.0309742e+08 | E37: ='Cuadro 5'!J37 -> 23548430 | F37: =B37+G37 -> 2.0088067e+10 | G37: =C37+D37+E37 -> 6.4685414e+08 | H37: =G37/B37 -> 0.033272313 | X37: =INDEX($A$7:$A$38,MATCH(Y37,$H$7:$H$38,0)) -> Baja California Sur | Y37: =SMALL($H$7:$H$38,31) -> 0.066688019 | Z37: =IF(Y37>=0,Y37*100,0) -> 6.6688019 | AA37: =IF(Y37<0,Y37*100,0) -> 0
A38: Zacatecas | B38: ='Cuadro 7'!F38 -> 1.414289e+10 | C38: ='Cuadro 3'!L38 -> -47911022 | D38: ='Cuadro 4'!M38 -> -22340198 | E38: ='Cuadro 5'!J38 -> -717141.58 | F38: =B38+G38 -> 1.4071921e+10 | G38: =C38+D38+E38 -> -70968361 | H38: =G38/B38 -> -0.0050179534 | X38: =INDEX($A$7:$A$38,MATCH(Y38,$H$7:$H$38,0)) -> Quintana Roo | Y38: =SMALL($H$7:$H$38,32) -> 0.080783772 | Z38: =IF(Y38>=0,Y38*100,0) -> 8.0783772 | AA38: =IF(Y38<0,Y38*100,0) -> 0
A39: Totales | B39: =SUM(B7:B38) -> 1.1445505e+12 | C39: =SUM(C7:C38) -> 0.00011539459 | D39: =SUM(D7:D38) -> 3.862381e-05 | E39: =SUM(E7:E38) -> 3.3006072e-06 | F39: =SUM(F7:F38) -> 1.1445505e+12 | G39: =SUM(G7:G38) -> 0.00015720725 | H39: =G39/B39 -> 1.3735283e-16
A41: Notas:
A42: • Se recalcularon población, resultado y coeficiente de los Cuadros 3, 4 y 5 del DOF (primera, segunda y tercera parte del crecimiento del FGP).
A43: • La parte fija del FGP (FGP de 2007) no depende de la población. Monto redistribuido = suma de las pérdidas.
...

Sheet Población
A1: Población por entidad federativa (personas): ENOE 3T-2025 vs. Encuesta Intercensal 2025
A6: Entidad | B6: Población ENOE 3T-2025 (DOF enero 2026) | C6: EIC 2025: personas en viviendas particulares | D6: EIC 2025: personas en viviendas colectivas | E6: Población EIC 2025 (total) | F6: Cambio (personas) | G6: Cambio (%) | H6: Población ENOE 1T-2026 (DOF agosto 2026, solo validación)
A7: Aguascalientes | B7: 1503564 | C7: 1534416 | D7: 4758 | E7: =C7+D7 -> 1539174 | F7: =E7-B7 -> 35610 | G7: =E7/B7-1 -> 0.023683727 | H7: 1531396
A8: Baja California | B8: 3778283 | C8: 3978593 | D8: 31085 | E8: =C8+D8 -> 4009678 | F8: =E8-B8 -> 231395 | G8: =E8/B8-1 -> 0.061243427 | H8: 3830329
A9: Baja California Sur | B9: 881164 | C9: 955465 | D9: 6049 | E9: =C9+D9 -> 961514 | F9: =E9-B9 -> 80350 | G9: =E9/B9-1 -> 0.091186204 | H9: 928591
A10: Campeche | B10: 925978 | C10: 967098 | D10: 1575 | E10: =C10+D10 -> 968673 | F10: =E10-B10 -> 42695 | G10: =E10/B10-1 -> 0.046108007 | H10: 935371
A11: Coahuila | B11: 3452989 | C11: 3404559 | D11: 10569 | E11: =C11+D11 -> 3415128 | F11: =E11-B11 -> -37861 | G11: =E11/B11-1 -> -0.010964703 | H11: 3590747
A12: Colima | B12: 728776 | C12: 758987 | D12: 3225 | E12: =C12+D12 -> 762212 | F12: =E12-B12 -> 33436 | G12: =E12/B12-1 -> 0.045879667 | H12: 762355
A13: Chiapas | B13: 5975155 | C13: 5840294 | D13: 20434 | E13: =C13+D13 -> 5860728 | F13: =E13-B13 -> -114427 | G13: =E13/B13-1 -> -0.019150466 | H13: 5891372
A14: Chihuahua | B14: 3976037 | C14: 3886377 | D14: 17567 | E14: =C14+D14 -> 3903944 | F14: =E14-B14 -> -72093 | G14: =E14/B14-1 -> -0.018131874 | H14: 4015493
A15: Ciudad de México | B15: 9350964 | C15: 9165819 | D15: 50588 | E15: =C15+D15 -> 9216407 | F15: =E15-B15 -> -134557 | G15: =E15/B15-1 -> -0.014389639 | H15: 9336468
A16: Durango | B16: 1944614 | C16: 1931226 | D16: 12064 | E16: =C16+D16 -> 1943290 | F16: =E16-B16 -> -1324 | G16: =E16/B16-1 -> -0.00068085492 | H16: 1968132
A17: Guanajuato | B17: 6345807 | C17: 6423384 | D17: 23551 | E17: =C17+D17 -> 6446935 | F17: =E17-B17 -> 101128 | G17: =E17/B17-1 -> 0.015936192 | H17: 6402249
A18: Guerrero | B18: 3606579 | C18: 3404404 | D18: 14498 | E18: =C18+D18 -> 3418902 | F18: =E18-B18 -> -187677 | G18: =E18/B18-1 -> -0.052037402 | H18: 3569633
... A38: Zacatecas | B38: 1695685 | C38: 1681468 | D38: 4951 | E38: =C38+D38 -> 1686419 | F38: =E38-B38 -> -9266 | G38: =E38/B38-1 -> -0.0054644583 | H38: 1689186
A39: Totales | B39: =SUM(B7:B38) -> 130760049 | C39: =SUM(C7:C38) -> 130393389 | D39: =SUM(D7:D38) -> 517925 | E39: =SUM(E7:E38) -> 130911314 | F39: =SUM(F7:F38) -> 151265 | G39: =E39/B39-1 -> 0.0011568136 | H39: =SUM(H7:H38) -> 131150866
A41: Fuentes: ENOE 3T-2025 según DOF de enero 2026 (Acuerdo 23/2026, Cuadros 3-5). EIC 2025: INEGI (22-sep-2026). ENOE 1T-2026 según DOF 31-ago-2026 (Acuerdo 140/2026), solo para validar la réplica.
A42: Azul = dato capturado; negro = fórmula; verde = vínculo a otra hoja.

Sheet Cuadro 3
A1: Cuadro 3. Coeficientes de la primera parte del crecimiento del FGP 2027 (recalculado con EIC 2025)
A2: Art. 2o LCF. Variables del DOF de agosto 2026 (último cálculo publicado). PIB a miles de pesos corrientes.
A3: Primera parte del crecimiento del FGP 2027 (60%; hoja Cuadro 7): | F3: ='Cuadro 7'!F48 -> 5.2723346e+11
A4: Columnas en amarillo = recalculadas con la población de la EIC 2025.
A6: Entidad | B6: PIB 2023 (1) | C6: PIB 2024 (2) | D6: Variación 2024/2023 (3=2/1) | E6: Población EIC 2025 (4) | F6: Resultado variación PIB por población (5=3*4) | G6: Coeficientes de participación (6=(5/Σ5)100) | H6: Coeficiente con ENOE 3T-2025 | I6: Cambio en coeficiente (puntos porcentuales) | J6: Monto 2027 con ENOE 3T-2025 (pesos) | K6: Monto 2027 con EIC 2025 (pesos) | L6: Cambio (pesos) | M6: Cambio (%)
A7: Aguascalientes | B7: 424228389 | C7: 435924518 | D7: =C7/B7 -> 1.0275704 | E7: =Población!E7 -> 1539174 | F7: =D7*E7 -> 1581609.6 | G7: =F7/F$39*100 -> 1.1421788 | H7: =D7*Población!B7/SUMPRODUCT($D$7:$D$38,Población!$B$7:$B$38)*100 -> 1.116951 | I7: =G7-H7 -> 0.025227883 | J7: =H7/100*$F$3 -> 5.8889392e+09 | K7: =G7/100*$F$3 -> 6.021949e+09 | L7: =K7-J7 -> 1.3300984e+08 | M7: =L7/J7 -> 0.022586384
A8: Baja California | B8: 1248914231 | C8: 1294477582 | D8: =C8/B8 -> 1.0364824 | E8: =Población!E8 -> 4009678 | F8: =D8*E8 -> 4155960.6 | G8: =F8/F$39*100 -> 3.0012781 | H8: =D8*Población!B8/SUMPRODUCT($D$7:$D$38,Población!$B$7:$B$38)*100 -> 2.8311118 | I8: =G8-H8 -> 0.1701663 | J8: =H8/100*$F$3 -> 1.4926569e+10 | K8: =G8/100*$F$3 -> 1.5823742e+10 | L8: =K8-J8 -> 8.9717367e+08 | M8: =L8/J8 -> 0.060105821
A9: Baja California Sur | B9: 235221280 | C9: 252768859 | D9: =C9/B9 -> 1.0746003 | E9: =Población!E9 -> 961514 | F9: =D9*E9 -> 1033243.2 | G9: =F9/F$39*100 -> 0.74616933 | H9: =D9*Población!B9/SUMPRODUCT($D$7:$D$38,Población!$B$7:$B$38)*100 -> 0.68454866 | I9: =G9-H9 -> 0.061620674 | J9: =H9/100*$F$3 -> 3.6091696e+09 | K9: =G9/100*$F$3 -> 3.9340544e+09 | L9: =K9-J9 -> 3.2488481e+08 | M9: =L9/J9 -> 0.0900165
A10: Campeche | B10: 600870526 | C10: 522953325 | D10: =C10/B10 -> 0.87032614 | E10: =Población!E10 -> 968673 | F10: =D10*E10 -> 843061.43 | G10: =F10/F$39*100 -> 0.6088272 | H10: =D10*Población!B10/SUMPRODUCT($D$7:$D$38,Población!$B$7:$B$38)*100 -> 0.58261722 | I10: =G10-H10 -> 0.026209982 | J10: =H10/100*$F$3 -> 3.0717529e+09 | K10: =G10/100*$F$3 -> 3.2099407e+09 | L10: =K10-J10 -> 1.381878e+08 | M10: =L10/J10 -> 0.044986625
A11: Coahuila | B11: 1180432300 | C11: 1238076976 | D11: =C11/B11 -> 1.0488335 | E11: =Población!E11 -> 3415128 | F11: =D11*E11 -> 3581900.8 | G11: =F11/F$39*100 -> 2.5867137 | H11: =D11*Población!B11/SUMPRODUCT($D$7:$D$38,Población!$B$7:$B$38)*100 -> 2.6181973 | I11: =G11-H11 -> -0.031483576 | J11: =H11/100*$F$3 -> 1.3804012e+10 | K11: =G11/100*$F$3 -> 1.363802e+10 | L11: =K11-J11 -> -1.6599195e+08 | M11: =L11/J11 -> -0.012024906
A12: Colima | B12: 204308084 | C12: 214770793 | D12: =C12/B12 -> 1.0512105 | E12: =Población!E12 -> 762212 | F12: =D12*E12 -> 801245.22 | G12: =F12/F$39*100 -> 0.5786291 | H12: =D12*Población!B12/SUMPRODUCT($D$7:$D$38,Población!$B$7:$B$38)*100 -> 0.55384004 | I12: =G12-H12 -> 0.024789066 | J12: =H12/100*$F$3 -> 2.92003e+09 | K12: =G12/100*$F$3 -> 3.0507263e+09 | L12: =K12-J12 -> 1.3069625e+08 | M12: =L12/J12 -> 0.04475853
A13: Chiapas | B13: 499718477 | C13: 530926151 | D13: =C13/B13 -> 1.0624505 | E13: =Población!E13 -> 5860728 | F13: =D13*E13 -> 6226733.5 | G13: =F13/F$39*100 -> 4.4967123 | H13: =D13*Población!B13/SUMPRODUCT($D$7:$D$38,Población!$B$7:$B$38)*100 -> 4.5894274 | I13: =G13-H13 -> -0.092715121 | J13: =H13/100*$F$3 -> 2.4196997e+10 | K13: =G13/100*$F$3 -> 2.3708172e+10 | L13: =K13-J13 -> -4.8882514e+08 | M13: =L13/J13 -> -0.020201893
A14: Chihuahua | B14: 1236374958 | C14: 1286224656 | D14: =C14/B14 -> 1.0403192 | E14: =Población!E14 -> 3903944 | F14: =D14*E14 -> 4061348.1 | G14: =F14/F$39*100 -> 2.9329525 | H14: =D14*Población!B14/SUMPRODUCT($D$7:$D$38,Población!$B$7:$B$38)*100 -> 2.99032 | I14: =G14-H14 -> -0.057367474 | J14: =H14/100*$F$3 -> 1.5765968e+10 | K14: =G14/100*$F$3 -> 1.5463507e+10 | L14: =K14-J14 -> -3.0246052e+08 | M14: =L14/J14 -> -0.019184393
A15: Ciudad de México | B15: 4710565535 | C15: 5021817466 | D15: =C15/B15 -> 1.0660753 | E15: =Población!E15 -> 9216407 | F15: =D15*E15 -> 9825383.7 | G15: =F15/F$39*100 -> 7.0955218 | H15: =D15*Población!B15/SUMPRODUCT($D$7:$D$38,Población!$B$7:$B$38)*100 -> 7.2068399 | I15: =G15-H15 -> -0.11131808 | J15: =H15/100*$F$3 -> 3.7996872e+10 | K15: =G15/100*$F$3 -> 3.7409965e+10 | L15: =K15-J15 -> -5.8690615e+08 | M15: =L15/J15 -> -0.01544617
A16: Durango | B16: 412994711 | C16: 454692285 | D16: =C16/B16 -> 1.1009639 | E16: =Población!E16 -> 1943290 | F16: =D16*E16 -> 2139492.2 | G16: =F16/F$39*100 -> 1.5450607 | H16: =D16*Población!B16/SUMPRODUCT($D$7:$D$38,Población!$B$7:$B$38)*100 -> 1.5477725 | I16: =G16-H16 -> -0.0027118228 | J16: =H16/100*$F$3 -> 8.1603744e+09 | K16: =G16/100*$F$3 -> 8.1460768e+09 | L16: =K16-J16 -> -14297637 | M16: =L16/J16 -> -0.001752081
A17: Guanajuato | B17: 1413105293 | C17: 1520603357 | D17: =C17/B17 -> 1.0760722 | E17: =Población!E17 -> 6446935 | F17: =D17*E17 -> 6937367.7 | G17: =F17/F$39*100 -> 5.0099055 | H17: =D17*Población!B17/SUMPRODUCT($D$7:$D$38,Población!$B$7:$B$38)*100 -> 4.9366109 | I17: =G17-H17 -> 0.073294619 | J17: =H17/100*$F$3 -> 2.6027465e+10 | K17: =G17/100*$F$3 -> 2.6413898e+10 | L17: =K17-J17 -> 3.8643376e+08 | M17: =L17/J17 -> 0.014847153
A18: Guerrero | B18: 407085984 | C18: 432049345 | D18: =C18/B18 -> 1.0613221 | E18: =Población!E18 -> 3418902 | F18: =D18*E18 -> 3628556.2 | G18: =F18/F$39*100 -> 2.6204066 | H18: =D18*Población!B18/SUMPRODUCT($D$7:$D$38,Población!$B$7:$B$38)*100 -> 2.7672173 | I18: =G18-H18 -> -0.14681077 | J18: =H18/100*$F$3 -> 1.4589696e+10 | K18: =G18/100*$F$3 -> 1.381566e+10 | L18: =K18-J18 -> -7.7403553e+08 | M18: =L18/J18 -> -0.053053576
... A38: Zacatecas | B38: 306036555 | C38: 347383977 | D38: =C38/B38 -> 1.1351062 | E38: =Población!E38 -> 1686419 | F38: =D38*E38 -> 1914264.6 | G38: =F38/F$39*100 -> 1.3824097 | H38: =D38*Población!B38/SUMPRODUCT($D$7:$D$38,Población!$B$7:$B$38)*100 -> 1.391497 | I38: =G38-H38 -> -0.0090872499 | J38: =H38/100*$F$3 -> 7.3364378e+09 | K38: =G38/100*$F$3 -> 7.2885268e+09 | L38: =K38-J38 -> -47911022 | M38: =L38/J38 -> -0.0065305566
A39: Totales | E39: =SUM(E7:E38) -> 130911314 | F39: =SUM(F7:F38) -> 1.3847302e+08 | G39: =SUM(G7:G38) -> 100 | H39: =SUM(H7:H38) -> 100 | I39: =SUM(I7:I38) -> 1.9984014e-14 | J39: =SUM(J7:J38) -> 5.2723346e+11 | K39: =SUM(K7:K38) -> 5.2723346e+11 | L39: =SUM(L7:L38) -> 0.00011539459 | M39: =L39/J39 -> 2.1886811e-16

Sheet Cuadro 4
A1: Cuadro 4. Coeficientes de la segunda parte del crecimiento del FGP 2027 (recalculado con EIC 2025)
A2: Art. 2o LCF. Media móvil de 3 años del crecimiento de impuestos y derechos locales (IE). Variables del DOF de agosto 2026.
A3: Segunda parte del crecimiento del FGP 2027 (30%; hoja Cuadro 7): | F3: ='Cuadro 7'!F49 -> 2.6361673e+11
A4: Columnas en amarillo = recalculadas con la población de la EIC 2025.
A6: Entidad | B6: Crecimiento IE 2023/2022 (1) | C6: Crecimiento IE 2024/2023 (2) | D6: Crecimiento IE 2025/2024 (3) | E6: Media móvil IE (4=((1+2+3)/3)) | F6: Población EIC 2025 (5) | G6: Resultado media móvil por población (6=4*5) | H6: Coeficientes de participación (7=(6/Σ6)100) | I6: Coeficiente con ENOE 3T-2025 | J6: Cambio en coeficiente (puntos porcentuales) | K6: Monto 2027 con ENOE 3T-2025 (pesos) | L6: Monto 2027 con EIC 2025 (pesos) | M6: Cambio (pesos) | N6: Cambio (%)
A7: Aguascalientes | B7: 1.169 | C7: 1.12 | D7: 1.114 | E7: 1.1343807 | F7: =Población!E7 -> 1539174 | G7: =E7*F7 -> 1746009.2 | H7: =G7/G$39*100 -> 1.193922 | I7: =E7*Población!B7/SUMPRODUCT($E$7:$E$38,Población!$B$7:$B$38)*100 -> 1.1676459 | J7: =H7-I7 -> 0.026276024 | K7: =I7/100*$F$3 -> 3.0781101e+09 | L7: =H7/100*$F$3 -> 3.1473781e+09 | M7: =L7-K7 -> 69267997 | N7: =M7/K7 -> 0.022503418
A8: Baja California | B8: 1.286 | C8: 1.11 | D8: 1.087 | E8: 1.1610329 | F8: =Población!E8 -> 4009678 | G8: =E8*F8 -> 4655368.1 | H8: =G8/G$39*100 -> 3.183343 | I8: =E8*Población!B8/SUMPRODUCT($E$7:$E$38,Población!$B$7:$B$38)*100 -> 3.0030977 | J8: =H8-I8 -> 0.18024535 | K8: =I8/100*$F$3 -> 7.9166679e+09 | L8: =H8/100*$F$3 -> 8.3918248e+09 | M8: =L8-K8 -> 4.7515691e+08 | N8: =M8/K8 -> 0.060019811
A9: Baja California Sur | B9: 1.142 | C9: 1.057 | D9: 1.088 | E9: 1.0955555 | F9: =Población!E9 -> 961514 | G9: =E9*F9 -> 1053392 | H9: =G9/G$39*100 -> 0.72030996 | I9: =E9*Población!B9/SUMPRODUCT($E$7:$E$38,Población!$B$7:$B$38)*100 -> 0.66087844 | J9: =H9-I9 -> 0.059431518 | K9: =I9/100*$F$3 -> 1.7421861e+09 | L9: =H9/100*$F$3 -> 1.8988576e+09 | M9: =L9-K9 -> 1.5667143e+08 | N9: =M9/K9 -> 0.089928063
A10: Campeche | B10: 1.201 | C10: 0.998 | D10: 0.919 | E10: 1.039131 | F10: =Población!E10 -> 968673 | G10: =E10*F10 -> 1006578.1 | H10: =G10/G$39*100 -> 0.68829863 | I10: =E10*Población!B10/SUMPRODUCT($E$7:$E$38,Población!$B$7:$B$38)*100 -> 0.65872086 | J10: =H10-I10 -> 0.02957778 | K10: =I10/100*$F$3 -> 1.7364984e+09 | L10: =H10/100*$F$3 -> 1.8144704e+09 | M10: =L10-K10 -> 77971976 | N10: =M10/K10 -> 0.044901842
A11: Coahuila | B11: 1.027 | C11: 1.229 | D11: 1.238 | E11: 1.1645209 | F11: =Población!E11 -> 3415128 | G11: =E11*F11 -> 3976988 | H11: =G11/G$39*100 -> 2.7194664 | I11: =E11*Población!B11/SUMPRODUCT($E$7:$E$38,Población!$B$7:$B$38)*100 -> 2.7527891 | J11: =H11-I11 -> -0.033322686 | K11: =I11/100*$F$3 -> 7.2568125e+09 | L11: =H11/100*$F$3 -> 7.1689684e+09 | M11: =L11-K11 -> -87844176 | N11: =M11/K11 -> -0.012105063
A12: Colima | B12: 1.089 | C12: 1.083 | D12: 1.124 | E12: 1.0989132 | F12: =Población!E12 -> 762212 | G12: =E12*F12 -> 837604.86 | H12: =G12/G$39*100 -> 0.57275462 | I12: =E12*Población!B12/SUMPRODUCT($E$7:$E$38,Población!$B$7:$B$38)*100 -> 0.5482617 | J12: =H12-I12 -> 0.024492915 | K12: =I12/100*$F$3 -> 1.4453096e+09 | L12: =H12/100*$F$3 -> 1.509877e+09 | M12: =L12-K12 -> 64567421 | N12: =M12/K12 -> 0.044673765
A13: Chiapas | B13: 1.085 | C13: 1.068 | D13: 1.544 | E13: 1.2322761 | F13: =Población!E13 -> 5860728 | G13: =E13*F13 -> 7222035.1 | H13: =G13/G$39*100 -> 4.9384312 | I13: =E13*Población!B13/SUMPRODUCT($E$7:$E$38,Población!$B$7:$B$38)*100 -> 5.0406629 | J13: =H13-I13 -> -0.10223164 | K13: =I13/100*$F$3 -> 1.3288031e+10 | L13: =H13/100*$F$3 -> 1.3018531e+10 | M13: =L13-K13 -> -2.694997e+08 | N13: =M13/K13 -> -0.020281387
A14: Chihuahua | B14: 1.092 | C14: 1.039 | D14: 1.125 | E14: 1.0853561 | F14: =Población!E14 -> 3903944 | G14: =E14*F14 -> 4237169.6 | H14: =G14/G$39*100 -> 2.8973787 | I14: =E14*Población!B14/SUMPRODUCT($E$7:$E$38,Población!$B$7:$B$38)*100 -> 2.95429 | J14: =H14-I14 -> -0.056911354 | K14: =I14/100*$F$3 -> 7.7880028e+09 | L14: =H14/100*$F$3 -> 7.637975e+09 | M14: =L14-K14 -> -1.5002785e+08 | N14: =M14/K14 -> -0.01926397
A15: Ciudad de México | B15: 1.105 | C15: 1.08 | D15: 1.244 | E15: 1.142993 | F15: =Población!E15 -> 9216407 | G15: =E15*F15 -> 10534289 | H15: =G15/G$39*100 -> 7.2033522 | I15: =E15*Población!B15/SUMPRODUCT($E$7:$E$38,Población!$B$7:$B$38)*100 -> 7.3169556 | J15: =H15-I15 -> -0.11360342 | K15: =I15/100*$F$3 -> 1.9288719e+10 | L15: =H15/100*$F$3 -> 1.8989241e+10 | M15: =L15-K15 -> -2.9947763e+08 | N15: =M15/K15 -> -0.01552605
A16: Durango | B16: 1.32 | C16: 1.093 | D16: 1.103 | E16: 1.1718711 | F16: =Población!E16 -> 1943290 | G16: =E16*F16 -> 2277285.4 | H16: =G16/G$39*100 -> 1.5572089 | I16: =E16*Población!B16/SUMPRODUCT($E$7:$E$38,Población!$B$7:$B$38)*100 -> 1.5600686 | J16: =H16-I16 -> -0.0028597185 | K16: =I16/100*$F$3 -> 4.1126018e+09 | L16: =H16/100*$F$3 -> 4.1050631e+09 | M16: =L16-K16 -> -7538696.3 | N16: =M16/K16 -> -0.0018330723
A17: Guanajuato | B17: 1.114 | C17: 1.067 | D17: 1.096 | E17: 1.0920659 | F17: =Población!E17 -> 6446935 | G17: =E17*F17 -> 7040478.1 | H17: =G17/G$39*100 -> 4.8142824 | I17: =E17*Población!B17/SUMPRODUCT($E$7:$E$38,Población!$B$7:$B$38)*100 -> 4.7442347 | J17: =H17-I17 -> 0.070047749 | K17: =I17/100*$F$3 -> 1.2506596e+10 | L17: =H17/100*$F$3 -> 1.2691254e+10 | M17: =L17-K17 -> 1.8465759e+08 | N17: =M17/K17 -> 0.014764815
A18: Guerrero | B18: 1.078 | C18: 1.009 | D18: 1.298 | E18: 1.1285073 | F18: =Población!E18 -> 3418902 | G18: =E18*F18 -> 3858256 | H18: =G18/G$39*100 -> 2.6382774 | I18: =E18*Población!B18/SUMPRODUCT($E$7:$E$38,Población!$B$7:$B$38)*100 -> 2.7863154 | J18: =H18-I18 -> -0.14803807 | K18: =I18/100*$F$3 -> 7.3451936e+09 | L18: =H18/100*$F$3 -> 6.9549405e+09 | M18: =L18-K18 -> -3.9025311e+08 | N18: =M18/K18 -> -0.053130405
... A38: Zacatecas | B38: 1.171 | C38: 1.016 | D38: 1.126 | E38: 1.104233 | F38: =Población!E38 -> 1686419 | G38: =E38*F38 -> 1862199.6 | H38: =G38/G$39*100 -> 1.273373 | I38: =E38*Población!B38/SUMPRODUCT($E$7:$E$38,Población!$B$7:$B$38)*100 -> 1.2818475 | J38: =H38-I38 -> -0.0084744992 | K38: =I38/100*$F$3 -> 3.3791645e+09 | L38: =H38/100*$F$3 -> 3.3568243e+09 | M38: =L38-K38 -> -22340198 | N38: =M38/K38 -> -0.0066111602
A39: Totales | F39: =SUM(F7:F38) -> 130911314 | G39: =SUM(G7:G38) -> 1.4624148e+08 | H39: =SUM(H7:H38) -> 100 | I39: =SUM(I7:I38) -> 100 | J39: =SUM(J7:J38) -> 1.5321078e-14 | K39: =SUM(K7:K38) -> 2.6361673e+11 | L39: =SUM(L7:L38) -> 2.6361673e+11 | M39: =SUM(M7:M38) -> 3.862381e-05 | N39: =M39/K39 -> 1.4651502e-16
A41: Columna (4): media móvil implícita en el DOF = Resultado (6) / Población (5) del Cuadro 4 original, para no perder precisión por el redondeo a 3 decimales.

Sheet Cuadro 5
A1: Cuadro 5. Coeficientes de la tercera parte del crecimiento del FGP 2027 (recalculado con EIC 2025)
A2: Art. 2o LCF. Impuestos y derechos locales 2025 × población. Variables del DOF de agosto 2026.
A3: Tercera parte del crecimiento del FGP 2027 (10%; hoja Cuadro 7): | F3: ='Cuadro 7'!F50 -> 8.7872244e+10
A4: Columnas en amarillo = recalculadas con la población de la EIC 2025.
A6: Entidad | B6: Impuestos y derechos locales de 2025 (1) | C6: Población EIC 2025 (2) | D6: Resultado IE 2025 por población (3=2*1) | E6: Coeficientes de participación (4=(3/Σ3)100) | F6: Coeficiente con ENOE 3T-2025 | G6: Cambio en coeficiente (puntos porcentuales) | H6: Monto 2027 con ENOE 3T-2025 (pesos) | I6: Monto 2027 con EIC 2025 (pesos) | J6: Cambio (pesos) | K6: Cambio (%)
A7: Aguascalientes | B7: 5999239609 | C7: =Población!E7 -> 1539174 | D7: =B7*C7 -> 9.2338736e+15 | E7: =D7/D$39*100 -> 0.25267134 | F7: =B7*Población!B7/SUMPRODUCT($B$7:$B$38,Población!$B$7:$B$38)*100 -> 0.24627695 | G7: =E7-F7 -> 0.0063943893 | H7: =F7/100*$F$3 -> 2.1640908e+08 | I7: =E7/100*$F$3 -> 2.2202797e+08 | J7: =I7-H7 -> 5618893.4 | K7: =J7/H7 -> 0.025964222
A8: Baja California | B8: 32050362891 | C8: =Población!E8 -> 4009678 | D8: =B8*C8 -> 1.2851163e+17 | E8: =D8/D$39*100 -> 3.5165314 | F8: =B8*Población!B8/SUMPRODUCT($B$7:$B$38,Población!$B$7:$B$38)*100 -> 3.30623 | G8: =E8-F8 -> 0.21030134 | H8: =F8/100*$F$3 -> 2.9052585e+09 | I8: =E8/100*$F$3 -> 3.090055e+09 | J8: =I8-H8 -> 1.8479651e+08 | K8: =J8/H8 -> 0.063607595
A9: Baja California Sur | B9: 6240882605 | C9: =Población!E9 -> 961514 | D9: =B9*C9 -> 6.000696e+15 | E9: =D9/D$39*100 -> 0.1642002 | F9: =B9*Población!B9/SUMPRODUCT($B$7:$B$38,Población!$B$7:$B$38)*100 -> 0.15014414 | G9: =E9-F9 -> 0.014056056 | H9: =F9/100*$F$3 -> 1.3193503e+08 | I9: =E9/100*$F$3 -> 1.442864e+08 | J9: =I9-H9 -> 12351371 | K9: =J9/H9 -> 0.093617076
A10: Campeche | B10: 3313630825 | C10: =Población!E10 -> 968673 | D10: =B10*C10 -> 3.2098247e+15 | E10: =D10/D$39*100 -> 0.08783212 | F10: =B10*Población!B10/SUMPRODUCT($B$7:$B$38,Población!$B$7:$B$38)*100 -> 0.083774226 | G10: =E10-F10 -> 0.0040578942 | H10: =F10/100*$F$3 -> 73614292 | I10: =E10/100*$F$3 -> 77180055 | J10: =I10-H10 -> 3565762.7 | K10: =J10/H10 -> 0.048438457
A11: Coahuila | B11: 16399735233 | C11: =Población!E11 -> 3415128 | D11: =B11*C11 -> 5.6007195e+16 | E11: =D11/D$39*100 -> 1.5325543 | F11: =B11*Población!B11/SUMPRODUCT($B$7:$B$38,Población!$B$7:$B$38)*100 -> 1.5461003 | G11: =E11-F11 -> -0.013545997 | H11: =F11/100*$F$3 -> 1.358593e+09 | I11: =E11/100*$F$3 -> 1.3466899e+09 | J11: =I11-H11 -> -11903172 | K11: =J11/H11 -> -0.0087613962
A12: Colima | B12: 3126852128 | C12: =Población!E12 -> 762212 | D12: =B12*C12 -> 2.3833242e+15 | E12: =D12/D$39*100 -> 0.065216153 | F12: =B12*Población!B12/SUMPRODUCT($B$7:$B$38,Población!$B$7:$B$38)*100 -> 0.06221671 | G12: =E12-F12 -> 0.0029994432 | H12: =F12/100*$F$3 -> 54671219 | I12: =E12/100*$F$3 -> 57306897 | J12: =I12-H12 -> 2635678 | K12: =J12/H12 -> 0.048209608
A13: Chiapas | B13: 8053623880 | C13: =Población!E13 -> 5860728 | D13: =B13*C13 -> 4.7200099e+16 | E13: =D13/D$39*100 -> 1.2915611 | F13: =B13*Población!B13/SUMPRODUCT($B$7:$B$38,Población!$B$7:$B$38)*100 -> 1.3138511 | G13: =E13-F13 -> -0.022290002 | H13: =F13/100*$F$3 -> 1.1545104e+09 | I13: =E13/100*$F$3 -> 1.1349237e+09 | J13: =I13-H13 -> -19586725 | K13: =J13/H13 -> -0.016965394
A14: Chihuahua | B14: 29378013855 | C14: =Población!E14 -> 3903944 | D14: =B14*C14 -> 1.1469012e+17 | E14: =D14/D$39*100 -> 3.138326 | F14: =B14*Población!B14/SUMPRODUCT($B$7:$B$38,Población!$B$7:$B$38)*100 -> 3.189176 | G14: =E14-F14 -> -0.050849921 | H14: =F14/100*$F$3 -> 2.8024005e+09 | I14: =E14/100*$F$3 -> 2.7577175e+09 | J14: =I14-H14 -> -44682967 | K14: =J14/H14 -> -0.015944533
A15: Ciudad de México | B15: 103599810122 | C15: =Población!E15 -> 9216407 | D15: =B15*C15 -> 9.5481802e+17 | E15: =D15/D$39*100 -> 26.127187 | F15: =B15*Población!B15/SUMPRODUCT($B$7:$B$38,Población!$B$7:$B$38)*100 -> 26.449714 | G15: =E15-F15 -> -0.32252681 | H15: =F15/100*$F$3 -> 2.3241957e+10 | I15: =E15/100*$F$3 -> 2.2958545e+10 | J15: =I15-H15 -> -2.8341154e+08 | K15: =J15/H15 -> -0.012193962
A16: Durango | B16: 5695831479 | C16: =Población!E16 -> 1943290 | D16: =B16*C16 -> 1.1068652e+16 | E16: =D16/D$39*100 -> 0.30287735 | F16: =B16*Población!B16/SUMPRODUCT($B$7:$B$38,Población!$B$7:$B$38)*100 -> 0.30241002 | G16: =E16-F16 -> 0.00046733291 | H16: =F16/100*$F$3 -> 2.6573447e+08 | I16: =E16/100*$F$3 -> 2.6614512e+08 | J16: =I16-H16 -> 410655.92 | K16: =J16/H16 -> 0.0015453619
A17: Guanajuato | B17: 22628728014 | C17: =Población!E17 -> 6446935 | D17: =B17*C17 -> 1.4588594e+17 | E17: =D17/D$39*100 -> 3.9919536 | F17: =B17*Población!B17/SUMPRODUCT($B$7:$B$38,Población!$B$7:$B$38)*100 -> 3.9206009 | G17: =E17-F17 -> 0.071352691 | H17: =F17/100*$F$3 -> 3.44512e+09 | I17: =E17/100*$F$3 -> 3.5078192e+09 | J17: =I17-H17 -> 62699211 | K17: =J17/H17 -> 0.018199427
A18: Guerrero | B18: 5343602918 | C18: =Población!E18 -> 3418902 | D18: =B18*C18 -> 1.8269255e+16 | E18: =D18/D$39*100 -> 0.49991122 | F18: =B18*Población!B18/SUMPRODUCT($B$7:$B$38,Población!$B$7:$B$38)*100 -> 0.52618112 | G18: =E18-F18 -> -0.026269905 | H18: =F18/100*$F$3 -> 4.6236716e+08 | I18: =E18/100*$F$3 -> 4.392832e+08 | J18: =I18-H18 -> -23083955 | K18: =J18/H18 -> -0.049925594
... A38: Zacatecas | B38: 5425831297 | C38: =Población!E38 -> 1686419 | D38: =B38*C38 -> 9.150225e+15 | E38: =D38/D$39*100 -> 0.25038241 | F38: =B38*Población!B38/SUMPRODUCT($B$7:$B$38,Población!$B$7:$B$38)*100 -> 0.25119853 | G38: =E38-F38 -> -0.00081611844 | H38: =F38/100*$F$3 -> 2.2073379e+08 | I38: =E38/100*$F$3 -> 2.2001665e+08 | J38: =I38-H38 -> -717141.58 | K38: =J38/H38 -> -0.0032488981
A39: Totales | C39: =SUM(C7:C38) -> 130911314 | D39: =SUM(D7:D38) -> 3.6544999e+18 | E39: =SUM(E7:E38) -> 100 | F39: =SUM(F7:F38) -> 100 | G39: =SUM(G7:G38) -> 1.6653345e-16 | H39: =SUM(H7:H38) -> 8.7872244e+10 | I39: =SUM(I7:I38) -> 8.7872244e+10 | J39: =SUM(J7:J38) -> 3.3006072e-06 | K39: =J39/H39 -> 3.7561431e-17

Sheet Cuadro 7
A1: Cuadro 7. Integración del FGP 2027 (anual): población ENOE 3T-2025 vs. EIC 2025
A2: FGP de 2007 = 12 × monto mensual del DOF de agosto 2026 (Cuadro 7). Crecimiento 2027 = 20% de la RFP del PPEF 2027 − FGP de 2007. Sin resarcimiento BET.
A6: Entidad | B6: FGP de 2007 (parte fija, no cambia) | C6: Primera parte ENOE 3T-2025 | D6: Segunda parte ENOE 3T-2025 | E6: Tercera parte ENOE 3T-2025 | F6: FGP total ENOE 3T-2025 | G6: Primera parte EIC 2025 | H6: Segunda parte EIC 2025 | I6: Tercera parte EIC 2025 | J6: FGP total EIC 2025 | K6: Cambio (pesos) | L6: Cambio (%)
A7: Aguascalientes | B7: 3041387268 | C7: ='Cuadro 3'!J7 -> 5.8889392e+09 | D7: ='Cuadro 4'!K7 -> 3.0781101e+09 | E7: ='Cuadro 5'!H7 -> 2.1640908e+08 | F7: =SUM(B7:E7) -> 1.2224846e+10 | G7: ='Cuadro 3'!K7 -> 6.021949e+09 | H7: ='Cuadro 4'!L7 -> 3.1473781e+09 | I7: ='Cuadro 5'!I7 -> 2.2202797e+08 | J7: =B7+SUM(G7:I7) -> 1.2432742e+10 | K7: =J7-F7 -> 2.0789673e+08 | L7: =K7/F7 -> 0.017006082
A8: Baja California | B8: 7626756012 | C8: ='Cuadro 3'!J8 -> 1.4926569e+10 | D8: ='Cuadro 4'!K8 -> 7.9166679e+09 | E8: ='Cuadro 5'!H8 -> 2.9052585e+09 | F8: =SUM(B8:E8) -> 3.3375251e+10 | G8: ='Cuadro 3'!K8 -> 1.5823742e+10 | H8: ='Cuadro 4'!L8 -> 8.3918248e+09 | I8: ='Cuadro 5'!I8 -> 3.090055e+09 | J8: =B8+SUM(G8:I8) -> 3.4932378e+10 | K8: =J8-F8 -> 1.5571271e+09 | L8: =K8/F8 -> 0.046655142
A9: Baja California Sur | B9: 1922951364 | C9: ='Cuadro 3'!J9 -> 3.6091696e+09 | D9: ='Cuadro 4'!K9 -> 1.7421861e+09 | E9: ='Cuadro 5'!H9 -> 1.3193503e+08 | F9: =SUM(B9:E9) -> 7.4062421e+09 | G9: ='Cuadro 3'!K9 -> 3.9340544e+09 | H9: ='Cuadro 4'!L9 -> 1.8988576e+09 | I9: ='Cuadro 5'!I9 -> 1.442864e+08 | J9: =B9+SUM(G9:I9) -> 7.9001497e+09 | K9: =J9-F9 -> 4.9390761e+08 | L9: =K9/F9 -> 0.066688019
A10: Campeche | B10: 2717270016 | C10: ='Cuadro 3'!J10 -> 3.0717529e+09 | D10: ='Cuadro 4'!K10 -> 1.7364984e+09 | E10: ='Cuadro 5'!H10 -> 73614292 | F10: =SUM(B10:E10) -> 7.5991356e+09 | G10: ='Cuadro 3'!K10 -> 3.2099407e+09 | H10: ='Cuadro 4'!L10 -> 1.8144704e+09 | I10: ='Cuadro 5'!I10 -> 77180055 | J10: =B10+SUM(G10:I10) -> 7.8188611e+09 | K10: =J10-F10 -> 2.1972554e+08 | L10: =K10/F10 -> 0.028914543
A11: Coahuila | B11: 6458269884 | C11: ='Cuadro 3'!J11 -> 1.3804012e+10 | D11: ='Cuadro 4'!K11 -> 7.2568125e+09 | E11: ='Cuadro 5'!H11 -> 1.358593e+09 | F11: =SUM(B11:E11) -> 2.8877688e+10 | G11: ='Cuadro 3'!K11 -> 1.363802e+10 | H11: ='Cuadro 4'!L11 -> 7.1689684e+09 | I11: ='Cuadro 5'!I11 -> 1.3466899e+09 | J11: =B11+SUM(G11:I11) -> 2.8611949e+10 | K11: =J11-F11 -> -2.6573929e+08 | L11: =K11/F11 -> -0.0092022358
A12: Colima | B12: 1970839320 | C12: ='Cuadro 3'!J12 -> 2.92003e+09 | D12: ='Cuadro 4'!K12 -> 1.4453096e+09 | E12: ='Cuadro 5'!H12 -> 54671219 | F12: =SUM(B12:E12) -> 6.3908501e+09 | G12: ='Cuadro 3'!K12 -> 3.0507263e+09 | H12: ='Cuadro 4'!L12 -> 1.509877e+09 | I12: ='Cuadro 5'!I12 -> 57306897 | J12: =B12+SUM(G12:I12) -> 6.5887495e+09 | K12: =J12-F12 -> 1.9789935e+08 | L12: =K12/F12 -> 0.030966044
A13: Chiapas | B13: 12052438704 | C13: ='Cuadro 3'!J13 -> 2.4196997e+10 | D13: ='Cuadro 4'!K13 -> 1.3288031e+10 | E13: ='Cuadro 5'!H13 -> 1.1545104e+09 | F13: =SUM(B13:E13) -> 5.0691977e+10 | G13: ='Cuadro 3'!K13 -> 2.3708172e+10 | H13: ='Cuadro 4'!L13 -> 1.3018531e+10 | I13: ='Cuadro 5'!I13 -> 1.1349237e+09 | J13: =B13+SUM(G13:I13) -> 4.9914065e+10 | K13: =J13-F13 -> -7.7791156e+08 | L13: =K13/F13 -> -0.015345852
A14: Chihuahua | B14: 7559991564 | C14: ='Cuadro 3'!J14 -> 1.5765968e+10 | D14: ='Cuadro 4'!K14 -> 7.7880028e+09 | E14: ='Cuadro 5'!H14 -> 2.8024005e+09 | F14: =SUM(B14:E14) -> 3.3916363e+10 | G14: ='Cuadro 3'!K14 -> 1.5463507e+10 | H14: ='Cuadro 4'!L14 -> 7.637975e+09 | I14: ='Cuadro 5'!I14 -> 2.7577175e+09 | J14: =B14+SUM(G14:I14) -> 3.3419191e+10 | K14: =J14-F14 -> -4.9717134e+08 | L14: =K14/F14 -> -0.014658746
A15: Ciudad de México | B15: 32936564964 | C15: ='Cuadro 3'!J15 -> 3.7996872e+10 | D15: ='Cuadro 4'!K15 -> 1.9288719e+10 | E15: ='Cuadro 5'!H15 -> 2.3241957e+10 | F15: =SUM(B15:E15) -> 1.1346411e+11 | G15: ='Cuadro 3'!K15 -> 3.7409965e+10 | H15: ='Cuadro 4'!L15 -> 1.8989241e+10 | I15: ='Cuadro 5'!I15 -> 2.2958545e+10 | J15: =B15+SUM(G15:I15) -> 1.1229432e+11 | K15: =J15-F15 -> -1.1697953e+09 | L15: =K15/F15 -> -0.010309827
A16: Durango | B16: 3462230928 | C16: ='Cuadro 3'!J16 -> 8.1603744e+09 | D16: ='Cuadro 4'!K16 -> 4.1126018e+09 | E16: ='Cuadro 5'!H16 -> 2.6573447e+08 | F16: =SUM(B16:E16) -> 1.6000942e+10 | G16: ='Cuadro 3'!K16 -> 8.1460768e+09 | H16: ='Cuadro 4'!L16 -> 4.1050631e+09 | I16: ='Cuadro 5'!I16 -> 2.6614512e+08 | J16: =B16+SUM(G16:I16) -> 1.5979516e+10 | K16: =J16-F16 -> -21425677 | L16: =K16/F16 -> -0.001339026
A17: Guanajuato | B17: 10263898068 | C17: ='Cuadro 3'!J17 -> 2.6027465e+10 | D17: ='Cuadro 4'!K17 -> 1.2506596e+10 | E17: ='Cuadro 5'!H17 -> 3.44512e+09 | F17: =SUM(B17:E17) -> 5.2243079e+10 | G17: ='Cuadro 3'!K17 -> 2.6413898e+10 | H17: ='Cuadro 4'!L17 -> 1.2691254e+10 | I17: ='Cuadro 5'!I17 -> 3.5078192e+09 | J17: =B17+SUM(G17:I17) -> 5.287687e+10 | K17: =J17-F17 -> 6.3379055e+08 | L17: =K17/F17 -> 0.01213157
A18: Guerrero | B18: 5919287988 | C18: ='Cuadro 3'!J18 -> 1.4589696e+10 | D18: ='Cuadro 4'!K18 -> 7.3451936e+09 | E18: ='Cuadro 5'!H18 -> 4.6236716e+08 | F18: =SUM(B18:E18) -> 2.8316544e+10 | G18: ='Cuadro 3'!K18 -> 1.381566e+10 | H18: ='Cuadro 4'!L18 -> 6.9549405e+09 | I18: ='Cuadro 5'!I18 -> 4.392832e+08 | J18: =B18+SUM(G18:I18) -> 2.7129172e+10 | K18: =J18-F18 -> -1.1873726e+09 | L18: =K18/F18 -> -0.041932115
... A38: Zacatecas | B38: 3206553636 | C38: ='Cuadro 3'!J38 -> 7.3364378e+09 | D38: ='Cuadro 4'!K38 -> 3.3791645e+09 | E38: ='Cuadro 5'!H38 -> 2.2073379e+08 | F38: =SUM(B38:E38) -> 1.414289e+10 | G38: ='Cuadro 3'!K38 -> 7.2885268e+09 | H38: ='Cuadro 4'!L38 -> 3.3568243e+09 | I38: ='Cuadro 5'!I38 -> 2.2001665e+08 | J38: =B38+SUM(G38:I38) -> 1.4071921e+10 | K38: =J38-F38 -> -70968361 | L38: =K38/F38 -> -0.0050179534
A39: Totales | B39: =SUM(B7:B38) -> 265828054020 | C39: =SUM(C7:C38) -> 5.2723346e+11 | D39: =SUM(D7:D38) -> 2.6361673e+11 | E39: =SUM(E7:E38) -> 8.7872244e+10 | F39: =SUM(F7:F38) -> 1.1445505e+12 | G39: =SUM(G7:G38) -> 5.2723346e+11 | H39: =SUM(H7:H38) -> 2.6361673e+11 | I39: =SUM(I7:I38) -> 8.7872244e+10 | ... K39: =SUM(K7:K38) -> 0.00013256073 | L39: =K39/F39 -> 1.1581903e-16
A42: Monto del FGP 2027
A43: 0.136% de la RFP 2027 (PPEF 2027, Ramo 28) | F43: 7782943337
A44: RFP 2027 (= 0.136% / 0.00136) | F44: =F43/0.00136 -> 5.7227525e+12
A45: FGP 2027 (20% de la RFP) | F45: =0.2*F44 -> 1.1445505e+12
A46: FGP de 2007 (12 × 22,152,337,833; DOF Cuadro 2) | F46: 265828053996
A47: Crecimiento del FGP 2027 | F47: =F45-F46 -> 8.7872244e+11
A48: Primera parte (60%) | F48: =0.6*F47 -> 5.2723346e+11
A49: Segunda parte (30%) | F49: =0.3*F47 -> 2.6361673e+11
A50: Tercera parte (10%) | F50: =0.1*F47 -> 8.7872244e+10

Sheet Validación DOF
A1: Validación: réplica de los coeficientes publicados en el DOF
A2: Mismo cálculo de cada cuadro con la población ENOE 1T-2026 que publicó el DOF de agosto 2026. La diferencia contra el coeficiente publicado debe ser ~0.
A6: Entidad | B6: Cuadro 3 replicado | C6: Cuadro 3 DOF | D6: Cuadro 3 diferencia | E6: Cuadro 4 replicado | F6: Cuadro 4 DOF | G6: Cuadro 4 diferencia | H6: Cuadro 5 replicado | I6: Cuadro 5 DOF | J6: Cuadro 5 diferencia
A7: Aguascalientes | B7: ='Cuadro 3'!D7*Población!H7/SUMPRODUCT('Cuadro 3'!$D$7:$D$38,Población!$H$7:$H$38)*100 -> 1.1343196 | C7: 1.13432 | D7: =B7-C7 -> -4.1871775e-07 | E7: ='Cuadro 4'!E7*Población!H7/SUMPRODUCT('Cuadro 4'!$E$7:$E$38,Población!$H$7:$H$38)*100 -> 1.1856771 | F7: 1.185677 | G7: =E7-F7 -> 8.0169534e-08 | H7: ='Cuadro 5'!B7*Población!H7/SUMPRODUCT('Cuadro 5'!$B$7:$B$38,Población!$H$7:$H$38)*100 -> 0.25028247 | I7: 0.250282 | J7: =H7-I7 -> 4.6893388e-07
A8: Baja California | B8: ='Cuadro 3'!D8*Población!H8/SUMPRODUCT('Cuadro 3'!$D$7:$D$38,Población!$H$7:$H$38)*100 -> 2.8617675 | C8: 2.861768 | D8: =B8-C8 -> -4.7857263e-07 | E8: ='Cuadro 4'!E8*Población!H8/SUMPRODUCT('Cuadro 4'!$E$7:$E$38,Población!$H$7:$H$38)*100 -> 3.0352936 | F8: 3.035293 | G8: =E8-F8 -> 6.2943921e-07 | H8: ='Cuadro 5'!B8*Población!H8/SUMPRODUCT('Cuadro 5'!$B$7:$B$38,Población!$H$7:$H$38)*100 -> 3.344381 | I8: 3.344381 | J8: =H8-I8 -> -2.7354771e-08
A9: Baja California Sur | B9: ='Cuadro 3'!D9*Población!H9/SUMPRODUCT('Cuadro 3'!$D$7:$D$38,Población!$H$7:$H$38)*100 -> 0.71929623 | C9: 0.719296 | D9: =B9-C9 -> 2.2619852e-07 | E9: ='Cuadro 4'!E9*Población!H9/SUMPRODUCT('Cuadro 4'!$E$7:$E$38,Población!$H$7:$H$38)*100 -> 0.69435084 | F9: 0.694351 | G9: =E9-F9 -> -1.5660769e-07 | H9: ='Cuadro 5'!B9*Población!H9/SUMPRODUCT('Cuadro 5'!$B$7:$B$38,Población!$H$7:$H$38)*100 -> 0.15787639 | I9: 0.157876 | J9: =H9-I9 -> 3.9373696e-07
A10: Campeche | B10: ='Cuadro 3'!D10*Población!H10/SUMPRODUCT('Cuadro 3'!$D$7:$D$38,Población!$H$7:$H$38)*100 -> 0.58681645 | C10: 0.586816 | D10: =B10-C10 -> 4.5136598e-07 | E10: ='Cuadro 4'!E10*Población!H10/SUMPRODUCT('Cuadro 4'!$E$7:$E$38,Población!$H$7:$H$38)*100 -> 0.66339822 | F10: 0.663398 | G10: =E10-F10 -> 2.2485538e-07 | H10: ='Cuadro 5'!B10*Población!H10/SUMPRODUCT('Cuadro 5'!$B$7:$B$38,Población!$H$7:$H$38)*100 -> 0.084437378 | I10: 0.084437 | J10: =H10-I10 -> 3.7758402e-07
A11: Coahuila | B11: ='Cuadro 3'!D11*Población!H11/SUMPRODUCT('Cuadro 3'!$D$7:$D$38,Población!$H$7:$H$38)*100 -> 2.7147367 | C11: 2.714737 | D11: =B11-C11 -> -2.5320511e-07 | E11: ='Cuadro 4'!E11*Población!H11/SUMPRODUCT('Cuadro 4'!$E$7:$E$38,Población!$H$7:$H$38)*100 -> 2.8539884 | F11: 2.853989 | G11: =E11-F11 -> -5.8958862e-07 | H11: ='Cuadro 5'!B11*Población!H11/SUMPRODUCT('Cuadro 5'!$B$7:$B$38,Población!$H$7:$H$38)*100 -> 1.6042364 | I11: 1.604236 | J11: =H11-I11 -> 3.6600224e-07
A12: Colima | B12: ='Cuadro 3'!D12*Población!H12/SUMPRODUCT('Cuadro 3'!$D$7:$D$38,Población!$H$7:$H$38)*100 -> 0.5776746 | C12: 0.577675 | D12: =B12-C12 -> -3.9607109e-07 | E12: ='Cuadro 4'!E12*Población!H12/SUMPRODUCT('Cuadro 4'!$E$7:$E$38,Población!$H$7:$H$38)*100 -> 0.57179554 | F12: 0.571796 | G12: =E12-F12 -> -4.628284e-07 | H12: ='Cuadro 5'!B12*Población!H12/SUMPRODUCT('Cuadro 5'!$B$7:$B$38,Población!$H$7:$H$38)*100 -> 0.064939854 | I12: 0.06494 | J12: =H12-I12 -> -1.4558949e-07
A13: Chiapas | B13: ='Cuadro 3'!D13*Población!H13/SUMPRODUCT('Cuadro 3'!$D$7:$D$38,Población!$H$7:$H$38)*100 -> 4.5119212 | C13: 4.511921 | D13: =B13-C13 -> 2.2352852e-07 | E13: ='Cuadro 4'!E13*Población!H13/SUMPRODUCT('Cuadro 4'!$E$7:$E$38,Población!$H$7:$H$38)*100 -> 4.9550105 | F13: 4.955011 | G13: =E13-F13 -> -4.7747475e-07 | H13: ='Cuadro 5'!B13*Población!H13/SUMPRODUCT('Cuadro 5'!$B$7:$B$38,Población!$H$7:$H$38)*100 -> 1.2925713 | I13: 1.292571 | J13: =H13-I13 -> 2.8540843e-07
A14: Chihuahua | B14: ='Cuadro 3'!D14*Población!H14/SUMPRODUCT('Cuadro 3'!$D$7:$D$38,Población!$H$7:$H$38)*100 -> 3.0112156 | C14: 3.011216 | D14: =B14-C14 -> -3.6979411e-07 | E14: ='Cuadro 4'!E14*Población!H14/SUMPRODUCT('Cuadro 4'!$E$7:$E$38,Población!$H$7:$H$38)*100 -> 2.9746183 | F14: 2.974618 | G14: =E14-F14 -> 3.0677779e-07 | H14: ='Cuadro 5'!B14*Población!H14/SUMPRODUCT('Cuadro 5'!$B$7:$B$38,Población!$H$7:$H$38)*100 -> 3.2137199 | I14: 3.21372 | J14: =H14-I14 -> -1.2541982e-07
A15: Ciudad de México | B15: ='Cuadro 3'!D15*Población!H15/SUMPRODUCT('Cuadro 3'!$D$7:$D$38,Población!$H$7:$H$38)*100 -> 7.1747511 | C15: 7.174751 | D15: =B15-C15 -> 7.8337657e-08 | E15: ='Cuadro 4'!E15*Población!H15/SUMPRODUCT('Cuadro 4'!$E$7:$E$38,Población!$H$7:$H$38)*100 -> 7.2836037 | F15: 7.283604 | G15: =E15-F15 -> -3.4258126e-07 | H15: ='Cuadro 5'!B15*Población!H15/SUMPRODUCT('Cuadro 5'!$B$7:$B$38,Población!$H$7:$H$38)*100 -> 26.350465 | I15: 26.350465 | J15: =H15-I15 -> 1.8748282e-07
A16: Durango | B16: ='Cuadro 3'!D16*Población!H16/SUMPRODUCT('Cuadro 3'!$D$7:$D$38,Población!$H$7:$H$38)*100 -> 1.5619376 | C16: 1.561938 | D16: =B16-C16 -> -4.3248975e-07 | E16: ='Cuadro 4'!E16*Población!H16/SUMPRODUCT('Cuadro 4'!$E$7:$E$38,Población!$H$7:$H$38)*100 -> 1.5741792 | F16: 1.574179 | G16: =E16-F16 -> 1.9593629e-07 | H16: ='Cuadro 5'!B16*Población!H16/SUMPRODUCT('Cuadro 5'!$B$7:$B$38,Población!$H$7:$H$38)*100 -> 0.30539229 | I16: 0.305392 | J16: =H16-I16 -> 2.8975203e-07
A17: Guanajuato | B17: ='Cuadro 3'!D17*Población!H17/SUMPRODUCT('Cuadro 3'!$D$7:$D$38,Población!$H$7:$H$38)*100 -> 4.9660414 | C17: 4.966041 | D17: =B17-C17 -> 3.9495094e-07 | E17: ='Cuadro 4'!E17*Población!H17/SUMPRODUCT('Cuadro 4'!$E$7:$E$38,Población!$H$7:$H$38)*100 -> 4.772012 | F17: 4.772012 | G17: =E17-F17 -> -4.7033784e-08 | H17: ='Cuadro 5'!B17*Población!H17/SUMPRODUCT('Cuadro 5'!$B$7:$B$38,Población!$H$7:$H$38)*100 -> 3.9467482 | I17: 3.946748 | J17: =H17-I17 -> 1.8168259e-07
A18: Guerrero | B18: ='Cuadro 3'!D18*Población!H18/SUMPRODUCT('Cuadro 3'!$D$7:$D$38,Población!$H$7:$H$38)*100 -> 2.7309083 | C18: 2.730908 | D18: =B18-C18 -> 3.2660808e-07 | E18: ='Cuadro 4'!E18*Población!H18/SUMPRODUCT('Cuadro 4'!$E$7:$E$38,Población!$H$7:$H$38)*100 -> 2.7494641 | F18: 2.749464 | G18: =E18-F18 -> 1.1359549e-07 | H18: ='Cuadro 5'!B18*Población!H18/SUMPRODUCT('Cuadro 5'!$B$7:$B$38,Población!$H$7:$H$38)*100 -> 0.51964226 | I18: 0.519642 | J18: =H18-I18 -> 2.5688815e-07
... A38: Zacatecas | B38: ='Cuadro 3'!D38*Población!H38/SUMPRODUCT('Cuadro 3'!$D$7:$D$38,Población!$H$7:$H$38)*100 -> 1.3821345 | C38: 1.382134 | D38: =B38-C38 -> 4.8879539e-07 | E38: ='Cuadro 4'!E38*Población!H38/SUMPRODUCT('Cuadro 4'!$E$7:$E$38,Población!$H$7:$H$38)*100 -> 1.2730877 | F38: 1.273088 | G38: =E38-F38 -> -3.1556573e-07 | H38: ='Cuadro 5'!B38*Población!H38/SUMPRODUCT('Cuadro 5'!$B$7:$B$38,Población!$H$7:$H$38)*100 -> 0.24968386 | I38: 0.249684 | J38: =H38-I38 -> -1.3767227e-07
A39: Totales | B39: =SUM(B7:B38) -> 100 | C39: =SUM(C7:C38) -> 100 | E39: =SUM(E7:E38) -> 100 | F39: =SUM(F7:F38) -> 100 | H39: =SUM(H7:H38) -> 100 | I39: =SUM(I7:I38) -> 99.999998
A40: Diferencia absoluta máxima | D40: =MAX(MAX(D7:D38),-MIN(D7:D38)) -> 4.8879539e-07 | G40: =MAX(MAX(G7:G38),-MIN(G7:G38)) -> 7.5893186e-07 | J40: =MAX(MAX(J7:J38),-MIN(J7:J38)) -> 4.8186034e-07
A42: Fuente: SHCP, Acuerdo 140/2026, DOF 31-ago-2026.
