Workbook

Sheet Indicador
A1: Impuestos municipales per cápita, 2024 y 2025
A2: Fuente: INEGI, EFIPEM municipal (2024 definitivas, 2025 preliminares), Censo 2020 y Encuesta Intercensal 2025. Azul = dato de INEGI; negro = fórmula; verde = vínculo a Supuestos. La fila gris bajo los encabezados dice cómo se calcula cada columna.
A4: Parámetros
A5: INPC promedio anual 2024 | F5: =Supuestos!B17 -> 135.38458
A6: INPC promedio anual 2025 | F6: =Supuestos!C17 -> 140.54217
A7: Deflactor: pesos de 2025 → pesos de 2024 = INPC 2024 ÷ INPC 2025 (F5 ÷ F6) | F7: =F5/F6 -> 0.96330224
A8: Fracción del periodo Censo 2020 → EIC 2025 transcurrida al 1-jul-2024 | F8: =Supuestos!B25 -> 0.76911765
A9: Fracción del periodo Censo 2020 → EIC 2025 transcurrida al 1-jul-2025 | F9: =Supuestos!B26 -> 0.94803922
A11: Identificación | F11: Insumos EFIPEM | H11: Población | M11: A pesos reales | N11: Indicador
A12: Clave INEGI | B12: Clave entidad | C12: Entidad | D12: Clave municipio | E12: Municipio | F12: Impuestos 2024 (pesos corrientes) | G12: Impuestos 2025 (pesos corrientes) | H12: Población Censo 2020 (15-mar-2020) | I12: Población EIC 2025 (15-oct-2025) | J12: Factor de crecimiento 2020–2025 | K12: Población 2024 (1-jul-2024) | L12: Población 2025 (1-jul-2025) | M12: Impuestos 2025 en pesos de 2024 | N12: Impuestos per cápita 2024 ($) | O12: Impuestos per cápita 2025 (pesos corrientes) | P12: Impuestos per cápita 2025 (pesos de 2024) | Q12: Variación real per cápita 2025 vs 2024
A13: Catálogo INEGI | B13: Catálogo INEGI | C13: Catálogo INEGI | D13: Catálogo INEGI | E13: Catálogo INEGI | F13: Dato EFIPEM 2024 | G13: Dato EFIPEM 2025 | H13: Dato Censo 2020 | I13: Dato EIC 2025 | J13: = I ÷ H | K13: = I × J ^ (F8 − 1) | L13: = I × J ^ (F9 − 1) | M13: = G × F7 | N13: = F ÷ K | O13: = G ÷ L | P13: = M ÷ L | Q13: = P ÷ N − 1
A14: 01001 | B14: 01 | C14: Aguascalientes | D14: 001 | E14: Aguascalientes | F14: 937439759 | G14: 1074805208 | H14: 945505 | I14: 1025505 | J14: =I14/H14 -> 1.0846109 | K14: =ROUND(I14*J14^($F$8-1),0) -> 1006453 | L14: =ROUND(I14*J14^($F$9-1),0) -> 1021186 | M14: =G14*$F$7 -> 1.0353623e+09 | N14: =F14/K14 -> 931.42925 | O14: =G14/L14 -> 1052.5068 | P14: =M14/L14 -> 1013.8822 | Q14: =IF(N14=0,"n.a.",P14/N14-1) -> 0.088522995
A15: 01002 | B15: 01 | C15: Aguascalientes | D15: 002 | E15: Asientos | F15: 20404976 | G15: 26923989 | H15: 51474 | I15: 53631 | J15: =I15/H15 -> 1.0419047 | K15: =ROUND(I15*J15^($F$8-1),0) -> 53125 | L15: =ROUND(I15*J15^($F$9-1),0) -> 53517 | M15: =G15*$F$7 -> 25935939 | N15: =F15/K15 -> 384.09367 | O15: =G15/L15 -> 503.09227 | P15: =M15/L15 -> 484.62991 | Q15: =IF(N15=0,"n.a.",P15/N15-1) -> 0.26174928
A16: 01003 | B16: 01 | C16: Aguascalientes | D16: 003 | E16: Calvillo | F16: 31704483 | G16: 45581111 | H16: 58155 | I16: 55794 | J16: =I16/H16 -> 0.9594016 | K16: =ROUND(I16*J16^($F$8-1),0) -> 56330 | L16: =ROUND(I16*J16^($F$9-1),0) -> 55914 | M16: =G16*$F$7 -> 43908386 | N16: =F16/K16 -> 562.83478 | O16: =G16/L16 -> 815.20033 | P16: =M16/L16 -> 785.2843 | Q16: =IF(N16=0,"n.a.",P16/N16-1) -> 0.39523059
A17: 01004 | B17: 01 | C17: Aguascalientes | D17: 004 | E17: Cosío | F17: 2551309 | G17: 3903044 | H17: 16997 | I17: 17504 | J17: =I17/H17 -> 1.0298288 | K17: =ROUND(I17*J17^($F$8-1),0) -> 17386 | L17: =ROUND(I17*J17^($F$9-1),0) -> 17477 | M17: =G17*$F$7 -> 3759811 | N17: =F17/K17 -> 146.74502 | O17: =G17/L17 -> 223.3246 | P17: =M17/L17 -> 215.12908 | Q17: =IF(N17=0,"n.a.",P17/N17-1) -> 0.46600599
A18: 01005 | B18: 01 | C18: Aguascalientes | D18: 005 | E18: Jesús María | F18: 216506353 | G18: 247343832 | H18: 129860 | I18: 147302 | J18: =I18/H18 -> 1.1343139 | K18: =ROUND(I18*J18^($F$8-1),0) -> 143078 | L18: =ROUND(I18*J18^($F$9-1),0) -> 146341 | M18: =G18*$F$7 -> 2.3826687e+08 | N18: =F18/K18 -> 1513.2051 | O18: =G18/L18 -> 1690.1882 | P18: =M18/L18 -> 1628.1621 | Q18: =IF(N18=0,"n.a.",P18/N18-1) -> 0.075969228
A19: 01006 | B19: 01 | C19: Aguascalientes | D19: 006 | E19: Pabellón de Arteaga | F19: 31047206 | G19: 25726276 | H19: 47558 | I19: 49372 | J19: =I19/H19 -> 1.0381429 | K19: =ROUND(I19*J19^($F$8-1),0) -> 48947 | L19: =ROUND(I19*J19^($F$9-1),0) -> 49276 | M19: =G19*$F$7 -> 24782179 | N19: =F19/K19 -> 634.30253 | O19: =G19/L19 -> 522.08532 | P19: =M19/L19 -> 502.92595 | Q19: =IF(N19=0,"n.a.",P19/N19-1) -> -0.20711975
A20: 01007 | B20: 01 | C20: Aguascalientes | D20: 007 | E20: Rincón de Romos | F20: 17367512 | G20: 24513203 | H20: 57269 | I20: 59964 | J20: =I20/H20 -> 1.0470586 | K20: =ROUND(I20*J20^($F$8-1),0) -> 59331 | L20: =ROUND(I20*J20^($F$9-1),0) -> 59821 | M20: =G20*$F$7 -> 23613623 | N20: =F20/K20 -> 292.72239 | O20: =G20/L20 -> 409.77588 | P20: =M20/L20 -> 394.73802 | Q20: =IF(N20=0,"n.a.",P20/N20-1) -> 0.34850643
A21: 01008 | B21: 01 | C21: Aguascalientes | D21: 008 | E21: San José de Gracia | F21: 2812300 | G21: 5725390 | H21: 9552 | I21: 10849 | J21: =I21/H21 -> 1.1357831 | K21: =ROUND(I21*J21^($F$8-1),0) -> 10535 | L21: =ROUND(I21*J21^($F$9-1),0) -> 10777 | M21: =G21*$F$7 -> 5515281 | N21: =F21/K21 -> 266.94827 | O21: =G21/L21 -> 531.26009 | P21: =M21/L21 -> 511.76403 | Q21: =IF(N21=0,"n.a.",P21/N21-1) -> 0.91709067
A22: 01009 | B22: 01 | C22: Aguascalientes | D22: 009 | E22: Tepezalá | F22: 6110645 | G22: 7557810 | H22: 22461 | I22: 24616 | J22: =I22/H22 -> 1.0959441 | K22: =ROUND(I22*J22^($F$8-1),0) -> 24101 | L22: =ROUND(I22*J22^($F$9-1),0) -> 24499 | M22: =G22*$F$7 -> 7280455.3 | N22: =F22/K22 -> 253.54321 | O22: =G22/L22 -> 308.49463 | P22: =M22/L22 -> 297.17357 | Q22: =IF(N22=0,"n.a.",P22/N22-1) -> 0.17208252
A23: 01010 | B23: 01 | C23: Aguascalientes | D23: 010 | E23: El Llano | F23: 5917337 | G23: 7355185 | H23: 20383 | I23: 21676 | J23: =I23/H23 -> 1.0634352 | K23: =ROUND(I23*J23^($F$8-1),0) -> 21370 | L23: =ROUND(I23*J23^($F$9-1),0) -> 21607 | M23: =G23*$F$7 -> 7085266.2 | N23: =F23/K23 -> 276.89925 | O23: =G23/L23 -> 340.40751 | P23: =M23/L23 -> 327.91531 | Q23: =IF(N23=0,"n.a.",P23/N23-1) -> 0.18424052
A24: 01011 | B24: 01 | C24: Aguascalientes | D24: 011 | E24: San Francisco de los Romo | F24: 77857769 | G24: 108302310 | H24: 61986 | I24: 68203 | J24: =I24/H24 -> 1.1002968 | K24: =ROUND(I24*J24^($F$8-1),0) -> 66714 | L24: =ROUND(I24*J24^($F$9-1),0) -> 67865 | M24: =G24*$F$7 -> 1.0432786e+08 | N24: =F24/K24 -> 1167.0379 | O24: =G24/L24 -> 1595.8493 | P24: =M24/L24 -> 1537.2852 | Q24: =IF(N24=0,"n.a.",P24/N24-1) -> 0.3172538
A25: 02001 | B25: 02 | C25: Baja California | D25: 001 | E25: Ensenada | F25: 879915907 | G25: 870800845 | H25: 440625 | I25: 480527 | J25: =I25/H25 -> 1.0905577 | K25: =ROUND(I25*J25^($F$8-1),0) -> 471005 | L25: =ROUND(I25*J25^($F$9-1),0) -> 478367 | M25: =G25*$F$7 -> 8.388444e+08 | N25: =F25/K25 -> 1868.1668 | O25: =G25/L25 -> 1820.3614 | P25: =M25/L25 -> 1753.5583 | Q25: =IF(N25=0,"n.a.",P25/N25-1) -> -0.061348138
A26: 02002 | B26: 02 | C26: Baja California | D26: 002 | E26: Mexicali | F26: 1541064062 | G26: 1777583625 | H26: 1042395 | I26: 1080999 | J26: =(I26+I31)/(H26) -> 1.0567194 | K26: =ROUND(I26*J26^($F$8-1),0) -> 1067317 | L26: =ROUND(I26*J26^($F$9-1),0) -> 1077905 | M26: =G26*$F$7 -> 1.7123503e+09 | N26: =F26/K26 -> 1443.8673 | O26: =G26/L26 -> 1649.1097 | P26: =M26/L26 -> 1588.5911 | Q26: =IF(N26=0,"n.a.",P26/N26-1) -> 0.10023348
A27: 02003 | B27: 02 | C27: Baja California | D27: 003 | E27: Tecate | F27: 55809125 | G27: 115506894 | H27: 102896 | I27: 111640 | J27: =I27/H27 -> 1.084979 | K27: =ROUND(I27*J27^($F$8-1),0) -> 109557 | L27: =ROUND(I27*J27^($F$9-1),0) -> 111168 | M27: =G27*$F$7 -> 1.1126805e+08 | N27: =F27/K27 -> 509.4072 | O27: =G27/L27 -> 1039.0301 | P27: =M27/L27 -> 1000.9 | Q27: =IF(N27=0,"n.a.",P27/N27-1) -> 0.9648328
A28: 02004 | B28: 02 | C28: Baja California | D28: 004 | E28: Tijuana | F28: 2721120556 | G28: 2891996435 | H28: 1910570 | I28: 1999816 | J28: =I28/H28 -> 1.0467117 | K28: =ROUND(I28*J28^($F$8-1),0) -> 1978847 | L28: =ROUND(I28*J28^($F$9-1),0) -> 1995078 | M28: =G28*$F$7 -> 2.7858666e+09 | N28: =F28/K28 -> 1375.1041 | O28: =G28/L28 -> 1449.5656 | P28: =M28/L28 -> 1396.3698 | Q28: =IF(N28=0,"n.a.",P28/N28-1) -> 0.015464804
A29: 02005 | B29: 02 | C29: Baja California | D29: 005 | E29: Playas de Rosarito | F29: 272628414 | G29: 299825118 | H29: 126264 | I29: 159768 | J29: =I29/H29 -> 1.2653488 | K29: =ROUND(I29*J29^($F$8-1),0) -> 151318 | L29: =ROUND(I29*J29^($F$9-1),0) -> 157826 | M29: =G29*$F$7 -> 2.8882221e+08 | N29: =F29/K29 -> 1801.6919 | O29: =G29/L29 -> 1899.7194 | P29: =M29/L29 -> 1830.004 | Q29: =IF(N29=0,"n.a.",P29/N29-1) -> 0.01571416
A30: 02006 | B30: 02 | C30: Baja California | D30: 006 | E30: San Quintín | F30: 26504980 | G30: 45584590 | H30: 117050 | I30: 125323 | J30: =I30/H30 -> 1.0706792 | K30: =ROUND(I30*J30^($F$8-1),0) -> 123362 | L30: =ROUND(I30*J30^($F$9-1),0) -> 124879 | M30: =G30*$F$7 -> 43911737 | N30: =F30/K30 -> 214.8553 | O30: =G30/L30 -> 365.03007 | P30: =M30/L30 -> 351.63428 | Q30: =IF(N30=0,"n.a.",P30/N30-1) -> 0.63660973
A31: 02007 | B31: 02 | C31: Baja California | D31: 007 | E31: San Felipe | F31: 40721486 | G31: 46665918 | I31: 20520 | J31: =J26 -> 1.0567194 | K31: =ROUND(I31*J31^($F$8-1),0) -> 20260 | L31: =ROUND(I31*J31^($F$9-1),0) -> 20461 | M31: =G31*$F$7 -> 44953383 | N31: =F31/K31 -> 2009.945 | O31: =G31/L31 -> 2280.7252 | P31: =M31/L31 -> 2197.0277 | Q31: =IF(N31=0,"n.a.",P31/N31-1) -> 0.093078494
A32: 03001 | B32: 03 | C32: Baja California Sur | D32: 001 | E32: Comondú | F32: 45123796 | G32: 49685591 | H32: 72358 | I32: 77434 | J32: =I32/H32 -> 1.0701512 | K32: =ROUND(I32*J32^($F$8-1),0) -> 76231 | L32: =ROUND(I32*J32^($F$9-1),0) -> 77162 | M32: =G32*$F$7 -> 47862241 | N32: =F32/K32 -> 591.93499 | O32: =G32/L32 -> 643.91269 | P32: =M32/L32 -> 620.28253 | Q32: =IF(N32=0,"n.a.",P32/N32-1) -> 0.047889629
A33: 03002 | B33: 03 | C33: Baja California Sur | D33: 002 | E33: Mulegé | F33: 31486935 | G33: 41958417 | H33: 62884 | I33: 59589 | J33: =I33/H33 -> 0.94760193 | K33: =ROUND(I33*J33^($F$8-1),0) -> 60334 | L33: =ROUND(I33*J33^($F$9-1),0) -> 59756 | M33: =G33*$F$7 -> 40418637 | N33: =F33/K33 -> 521.87713 | O33: =G33/L33 -> 702.16241 | P33: =M33/L33 -> 676.39462 | Q33: =IF(N33=0,"n.a.",P33/N33-1) -> 0.2960802
A34: 03003 | B34: 03 | C34: Baja California Sur | D34: 003 | E34: La Paz | F34: 575782711 | G34: 650713173 | H34: 290063 | I34: 330957 | J34: =I34/H34 -> 1.1409832 | K34: =ROUND(I34*J34^($F$8-1),0) -> 321031 | L34: =ROUND(I34*J34^($F$9-1),0) -> 328697 | M34: =G34*$F$7 -> 6.2683345e+08 | N34: =F34/K34 -> 1793.5424 | O34: =G34/L34 -> 1979.6748 | P34: =M34/L34 -> 1907.0252 | Q34: =IF(N34=0,"n.a.",P34/N34-1) -> 0.06327298
A35: 03008 | B35: 03 | C35: Baja California Sur | D35: 008 | E35: Los Cabos | F35: 1984132439 | G35: 2850037951 | H35: 350193 | I35: 469163 | J35: =I35/H35 -> 1.339727 | K35: =ROUND(I35*J35^($F$8-1),0) -> 438529 | L35: =ROUND(I35*J35^($F$9-1),0) -> 462087 | M35: =G35*$F$7 -> 2.7454479e+09 | N35: =F35/K35 -> 4524.5182 | O35: =G35/L35 -> 6167.7519 | P35: =M35/L35 -> 5941.4091 | Q35: =IF(N35=0,"n.a.",P35/N35-1) -> 0.31315842
A36: 03009 | B36: 03 | C36: Baja California Sur | D36: 009 | E36: Loreto | F36: 79033332 | G36: 68184664 | H36: 17926 | I36: 18322 | J36: =I36/H36 -> 1.0220908 | K36: =ROUND(I36*J36^($F$8-1),0) -> 18230 | L36: =ROUND(I36*J36^($F$9-1),0) -> 18301 | M36: =G36*$F$7 -> 65682439 | N36: =F36/K36 -> 4335.3446 | O36: =G36/L36 -> 3725.7343 | P36: =M36/L36 -> 3589.0082 | Q36: =IF(N36=0,"n.a.",P36/N36-1) -> -0.17215157
A37: 04001 | B37: 04 | C37: Campeche | D37: 001 | E37: Calkiní | F37: 5083658 | G37: 7174192 | H37: 59192 | I37: 47031 | J37: =(I37+I49)/(H37) -> 1.1048284 | K37: =ROUND(I37*J37^($F$8-1),0) -> 45961 | L37: =ROUND(I37*J37^($F$9-1),0) -> 46788 | M37: =G37*$F$7 -> 6910915.2 | N37: =F37/K37 -> 110.60808 | O37: =G37/L37 -> 153.33402 | P37: =M37/L37 -> 147.707 | Q37: =IF(N37=0,"n.a.",P37/N37-1) -> 0.33540877
A38: 04002 | B38: 04 | C38: Campeche | D38: 002 | E38: Campeche | F38: 115017083 | G38: 131329589 | H38: 293199 | I38: 294335 | J38: =I38/H38 -> 1.0038745 | K38: =ROUND(I38*J38^($F$8-1),0) -> 294072 | L38: =ROUND(I38*J38^($F$9-1),0) -> 294276 | M38: =G38*$F$7 -> 1.2651009e+08 | N38: =F38/K38 -> 391.11878 | O38: =G38/L38 -> 446.28033 | P38: =M38/L38 -> 429.90283 | Q38: =IF(N38=0,"n.a.",P38/N38-1) -> 0.099161822
A39: 04003 | B39: 04 | C39: Campeche | D39: 003 | E39: Carmen | F39: 127869216 | G39: 134482785 | H39: 248359 | I39: 252593 | J39: =I39/H39 -> 1.0170479 | K39: =ROUND(I39*J39^($F$8-1),0) -> 251609 | L39: =ROUND(I39*J39^($F$9-1),0) -> 252371 | M39: =G39*$F$7 -> 1.2954757e+08 | N39: =F39/K39 -> 508.20605 | O39: =G39/L39 -> 532.87733 | P39: =M39/L39 -> 513.32192 | Q39: =IF(N39=0,"n.a.",P39/N39-1) -> 0.010066536
A40: 04004 | B40: 04 | C40: Campeche | D40: 004 | E40: Champotón | F40: 12271013 | G40: 13504409 | H40: 78140 | I40: 84424 | J40: =I40/H40 -> 1.0804198 | K40: =ROUND(I40*J40^($F$8-1),0) -> 82930 | L40: =ROUND(I40*J40^($F$9-1),0) -> 84085 | M40: =G40*$F$7 -> 13008827 | N40: =F40/K40 -> 147.96832 | O40: =G40/L40 -> 160.60426 | P40: =M40/L40 -> 154.71044 | Q40: =IF(N40=0,"n.a.",P40/N40-1) -> 0.045564602
A41: 04005 | B41: 04 | C41: Campeche | D41: 005 | E41: Hecelchakán | F41: 3743257 | G41: 4397800 | H41: 31914 | I41: 33335 | J41: =I41/H41 -> 1.0445259 | K41: =ROUND(I41*J41^($F$8-1),0) -> 33001 | L41: =ROUND(I41*J41^($F$9-1),0) -> 33260 | M41: =G41*$F$7 -> 4236410.6 | N41: =F41/K41 -> 113.42859 | O41: =G41/L41 -> 132.22489 | P41: =M41/L41 -> 127.37254 | Q41: =IF(N41=0,"n.a.",P41/N41-1) -> 0.12293147
A42: 04006 | B42: 04 | C42: Campeche | D42: 006 | E42: Hopelchén | F42: 4346245 | G42: 5134941 | H42: 42130 | I42: 46458 | J42: =I42/H42 -> 1.1027296 | K42: =ROUND(I42*J42^($F$8-1),0) -> 45421 | L42: =ROUND(I42*J42^($F$9-1),0) -> 46223 | M42: =G42*$F$7 -> 4946500.1 | N42: =F42/K42 -> 95.688008 | O42: =G42/L42 -> 111.0906 | P42: =M42/L42 -> 107.01383 | Q42: =IF(N42=0,"n.a.",P42/N42-1) -> 0.11836195
...

Sheet Supuestos
A1: Supuestos
A3: INPC mensual (base 2a quincena de julio 2018 = 100)
A4: Mes | B4: 2024 | C4: 2025
A5: Enero | B5: 133.555 | C5: 138.343
A6: Febrero | B6: 133.681 | C6: 138.726
A7: Marzo | B7: 134.065 | C7: 139.161
A8: Abril | B8: 134.336 | C8: 139.62
A9: Mayo | B9: 134.087 | C9: 140.012
A10: Junio | B10: 134.594 | C10: 140.405
A11: Julio | B11: 136.003 | C11: 140.78
A12: Agosto | B12: 136.013 | C12: 140.867
A13: Septiembre | B13: 136.08 | C13: 141.197
A14: Octubre | B14: 136.828 | C14: 141.708
A15: Noviembre | B15: 137.424 | C15: 142.645
A16: Diciembre | B16: 137.949 | C16: 143.042
A17: Promedio anual | B17: =AVERAGE(B5:B16) -> 135.38458 | C17: =AVERAGE(C5:C16) -> 140.54217
A18: Fuente: INEGI, INPC (valores mensuales de calcu.mx/inpc; nov-2025 = 142.645 verificado con el boletín INEGI 718/25).
A20: Fechas para interpolar la población
A21: Fecha de referencia del Censo 2020 | B21: =DATE(2020,3,15) -> 43905
A22: Fecha de referencia de la Encuesta Intercensal 2025 | B22: =DATE(2025,10,15) -> 45945
A23: Población 2024 se estima al | B23: =DATE(2024,7,1) -> 45474
A24: Población 2025 se estima al | B24: =DATE(2025,7,1) -> 45839
A25: Fracción del periodo Censo→EIC transcurrida al 1-jul-2024 = (B23 − B21) ÷ (B22 − B21) | B25: =(B23-B21)/(B22-B21) -> 0.76911765
A26: Fracción del periodo Censo→EIC transcurrida al 1-jul-2025 = (B24 − B21) ÷ (B22 − B21) | B26: =(B24-B21)/(B22-B21) -> 0.94803922
A28: Notas
A29: • Impuestos = capítulo 'Impuestos' de los ingresos municipales de la EFIPEM (predial, traslado de dominio, espectáculos, etc.). No incluye los impuestos participables (Fondo ISR, IEPS, ISAN), que INEGI registra en Participaciones federales.
A30: • EFIPEM 2024 son cifras definitivas; 2025 son cifras preliminares (INEGI publica actualización el 30-nov-2026).
A31: • Solo se incluyen municipios que reportan a la EFIPEM en 2024 y en 2025 (1,691). Un municipio que reporta ingresos pero no tiene renglón de Impuestos aparece con impuestos = 0.
A32: • Se excluyen las 16 alcaldías de la CDMX: el predial y demás impuestos los recauda el gobierno central de la Ciudad.
A33: • Población: personas en viviendas particulares habitadas en el Censo 2020 y en la EIC 2025 (mismo concepto en ambos años).
A34: • Municipios creados después de 2020 (San Felipe, Dzitbalché) y municipios que perdieron territorio (Mexicali, Calkiní, San Luis Potosí, Culiacán, Guasave, Ahome): el factor de crecimiento se calcula con la población conjunta del municipio de origen y el nuevo, para que la escisión no se lea como caída de población. Ver comentarios en la columna J de la hoja Indicador.
A35: • Colores: azul = dato de INEGI o supuesto capturado; negro = fórmula; verde = vínculo a otra hoja.

Sheet Resumen estatal
A1: Resumen por entidad federativa
A2: Suma de los municipios de la hoja Indicador. Per cápita estatal = impuestos totales ÷ población total de esos municipios. Todas las cifras en pesos de 2024 salvo la columna H.
A4: Clave | B4: Entidad | C4: Municipios en la tabla | D4: Población 2024 | E4: Impuestos 2024 | F4: Per cápita 2024 ($) | G4: Población 2025 | H4: Impuestos 2025 (pesos corrientes) | I4: Impuestos 2025 (pesos de 2024) | J4: Per cápita 2025 (pesos de 2024) | K4: Variación real per cápita
A5: Catálogo INEGI | B5: Catálogo INEGI | C5: Conteo en Indicador | D5: Suma col. K | E5: Suma col. F | F5: = E ÷ D | G5: Suma col. L | H5: Suma col. G | I5: = H × deflactor | J5: = I ÷ G | K5: = J ÷ F − 1
A6: 01 | B6: Aguascalientes | C6: =COUNTIF(Indicador!$B$14:$B$1704,$A6) -> 11 | D6: =SUMIFS(Indicador!$K$14:$K$1704,Indicador!$B$14:$B$1704,$A6) -> 1507370 | E6: =SUMIFS(Indicador!$F$14:$F$1704,Indicador!$B$14:$B$1704,$A6) -> 1349719649 | F6: =E6/D6 -> 895.41363 | G6: =SUMIFS(Indicador!$L$14:$L$1704,Indicador!$B$14:$B$1704,$A6) -> 1528280 | H6: =SUMIFS(Indicador!$G$14:$G$1704,Indicador!$B$14:$B$1704,$A6) -> 1577737358 | I6: =H6*Indicador!$F$7 -> 1.5198379e+09 | J6: =I6/G6 -> 994.47609 | K6: =J6/F6-1 -> 0.11063318
A7: 02 | B7: Baja California | C7: =COUNTIF(Indicador!$B$14:$B$1704,$A7) -> 7 | D7: =SUMIFS(Indicador!$K$14:$K$1704,Indicador!$B$14:$B$1704,$A7) -> 3921666 | E7: =SUMIFS(Indicador!$F$14:$F$1704,Indicador!$B$14:$B$1704,$A7) -> 5537764530 | F7: =E7/D7 -> 1412.0949 | G7: =SUMIFS(Indicador!$L$14:$L$1704,Indicador!$B$14:$B$1704,$A7) -> 3965684 | H7: =SUMIFS(Indicador!$G$14:$G$1704,Indicador!$B$14:$B$1704,$A7) -> 6047963425 | I7: =H7*Indicador!$F$7 -> 5.8260167e+09 | J7: =I7/G7 -> 1469.1076 | K7: =J7/F7-1 -> 0.040374591
A8: 03 | B8: Baja California Sur | C8: =COUNTIF(Indicador!$B$14:$B$1704,$A8) -> 5 | D8: =SUMIFS(Indicador!$K$14:$K$1704,Indicador!$B$14:$B$1704,$A8) -> 914355 | E8: =SUMIFS(Indicador!$F$14:$F$1704,Indicador!$B$14:$B$1704,$A8) -> 2715559213 | F8: =E8/D8 -> 2969.9178 | G8: =SUMIFS(Indicador!$L$14:$L$1704,Indicador!$B$14:$B$1704,$A8) -> 946003 | H8: =SUMIFS(Indicador!$G$14:$G$1704,Indicador!$B$14:$B$1704,$A8) -> 3660579796 | I8: =H8*Indicador!$F$7 -> 3.5262447e+09 | J8: =I8/G8 -> 3727.5196 | K8: =J8/F8-1 -> 0.25509182
A9: 04 | B9: Campeche | C9: =COUNTIF(Indicador!$B$14:$B$1704,$A9) -> 13 | D9: =SUMIFS(Indicador!$K$14:$K$1704,Indicador!$B$14:$B$1704,$A9) -> 957500 | E9: =SUMIFS(Indicador!$F$14:$F$1704,Indicador!$B$14:$B$1704,$A9) -> 305199751 | F9: =E9/D9 -> 318.74648 | G9: =SUMIFS(Indicador!$L$14:$L$1704,Indicador!$B$14:$B$1704,$A9) -> 964922 | H9: =SUMIFS(Indicador!$G$14:$G$1704,Indicador!$B$14:$B$1704,$A9) -> 337198911 | I9: =H9*Indicador!$F$7 -> 3.2482446e+08 | J9: =I9/G9 -> 336.63287 | K9: =J9/F9-1 -> 0.056114805
A10: 05 | B10: Coahuila de Zaragoza | C10: =COUNTIF(Indicador!$B$14:$B$1704,$A10) -> 38 | D10: =SUMIFS(Indicador!$K$14:$K$1704,Indicador!$B$14:$B$1704,$A10) -> 3339543 | E10: =SUMIFS(Indicador!$F$14:$F$1704,Indicador!$B$14:$B$1704,$A10) -> 3312894325 | F10: =E10/D10 -> 992.02026 | G10: =SUMIFS(Indicador!$L$14:$L$1704,Indicador!$B$14:$B$1704,$A10) -> 3389752 | H10: =SUMIFS(Indicador!$G$14:$G$1704,Indicador!$B$14:$B$1704,$A10) -> 3621110244 | I10: =H10*Indicador!$F$7 -> 3.4882236e+09 | J10: =I10/G10 -> 1029.0498 | K10: =J10/F10-1 -> 0.037327393
A11: 06 | B11: Colima | C11: =COUNTIF(Indicador!$B$14:$B$1704,$A11) -> 10 | D11: =SUMIFS(Indicador!$K$14:$K$1704,Indicador!$B$14:$B$1704,$A11) -> 751704 | E11: =SUMIFS(Indicador!$F$14:$F$1704,Indicador!$B$14:$B$1704,$A11) -> 946824030 | F11: =E11/D11 -> 1259.5703 | G11: =SUMIFS(Indicador!$L$14:$L$1704,Indicador!$B$14:$B$1704,$A11) -> 757339 | H11: =SUMIFS(Indicador!$G$14:$G$1704,Indicador!$B$14:$B$1704,$A11) -> 1080504797 | I11: =H11*Indicador!$F$7 -> 1.0408527e+09 | J11: =I11/G11 -> 1374.3551 | K11: =J11/F11-1 -> 0.091130097
A12: 07 | B12: Chiapas | C12: =COUNTIF(Indicador!$B$14:$B$1704,$A12) -> 98 | D12: =SUMIFS(Indicador!$K$14:$K$1704,Indicador!$B$14:$B$1704,$A12) -> 4918408 | E12: =SUMIFS(Indicador!$F$14:$F$1704,Indicador!$B$14:$B$1704,$A12) -> 923071439 | F12: =E12/D12 -> 187.67687 | G12: =SUMIFS(Indicador!$L$14:$L$1704,Indicador!$B$14:$B$1704,$A12) -> 4974882 | H12: =SUMIFS(Indicador!$G$14:$G$1704,Indicador!$B$14:$B$1704,$A12) -> 1008703136 | I12: =H12*Indicador!$F$7 -> 9.7168599e+08 | J12: =I12/G12 -> 195.3184 | K12: =J12/F12-1 -> 0.040716389
A13: 08 | B13: Chihuahua | C13: =COUNTIF(Indicador!$B$14:$B$1704,$A13) -> 64 | D13: =SUMIFS(Indicador!$K$14:$K$1704,Indicador!$B$14:$B$1704,$A13) -> 3793520 | E13: =SUMIFS(Indicador!$F$14:$F$1704,Indicador!$B$14:$B$1704,$A13) -> 4742500905 | F13: =E13/D13 -> 1250.1584 | G13: =SUMIFS(Indicador!$L$14:$L$1704,Indicador!$B$14:$B$1704,$A13) -> 3825448 | H13: =SUMIFS(Indicador!$G$14:$G$1704,Indicador!$B$14:$B$1704,$A13) -> 5357344772 | I13: =H13*Indicador!$F$7 -> 5.1607422e+09 | J13: =I13/G13 -> 1349.0556 | K13: =J13/F13-1 -> 0.079107764
A14: 10 | B14: Durango | C14: =COUNTIF(Indicador!$B$14:$B$1704,$A14) -> 3 | D14: =SUMIFS(Indicador!$K$14:$K$1704,Indicador!$B$14:$B$1704,$A14) -> 1302725 | E14: =SUMIFS(Indicador!$F$14:$F$1704,Indicador!$B$14:$B$1704,$A14) -> 1002139231 | F14: =E14/D14 -> 769.26384 | G14: =SUMIFS(Indicador!$L$14:$L$1704,Indicador!$B$14:$B$1704,$A14) -> 1323551 | H14: =SUMIFS(Indicador!$G$14:$G$1704,Indicador!$B$14:$B$1704,$A14) -> 1217801320 | I14: =H14*Indicador!$F$7 -> 1.1731107e+09 | J14: =I14/G14 -> 886.33588 | K14: =J14/F14-1 -> 0.15218711
A15: 11 | B15: Guanajuato | C15: =COUNTIF(Indicador!$B$14:$B$1704,$A15) -> 34 | D15: =SUMIFS(Indicador!$K$14:$K$1704,Indicador!$B$14:$B$1704,$A15) -> 5690209 | E15: =SUMIFS(Indicador!$F$14:$F$1704,Indicador!$B$14:$B$1704,$A15) -> 4556706968 | F15: =E15/D15 -> 800.79782 | G15: =SUMIFS(Indicador!$L$14:$L$1704,Indicador!$B$14:$B$1704,$A15) -> 5737062 | H15: =SUMIFS(Indicador!$G$14:$G$1704,Indicador!$B$14:$B$1704,$A15) -> 5044634478 | I15: =H15*Indicador!$F$7 -> 4.8595077e+09 | J15: =I15/G15 -> 847.03768 | K15: =J15/F15-1 -> 0.057742235
A16: 12 | B16: Guerrero | C16: =COUNTIF(Indicador!$B$14:$B$1704,$A16) -> 8 | D16: =SUMIFS(Indicador!$K$14:$K$1704,Indicador!$B$14:$B$1704,$A16) -> 1640134 | E16: =SUMIFS(Indicador!$F$14:$F$1704,Indicador!$B$14:$B$1704,$A16) -> 1136297441 | F16: =E16/D16 -> 692.80769 | G16: =SUMIFS(Indicador!$L$14:$L$1704,Indicador!$B$14:$B$1704,$A16) -> 1635501 | H16: =SUMIFS(Indicador!$G$14:$G$1704,Indicador!$B$14:$B$1704,$A16) -> 1269566401 | I16: =H16*Indicador!$F$7 -> 1.2229762e+09 | J16: =I16/G16 -> 747.76851 | K16: =J16/F16-1 -> 0.079330569
A17: 13 | B17: Hidalgo | C17: =COUNTIF(Indicador!$B$14:$B$1704,$A17) -> 5 | D17: =SUMIFS(Indicador!$K$14:$K$1704,Indicador!$B$14:$B$1704,$A17) -> 823458 | E17: =SUMIFS(Indicador!$F$14:$F$1704,Indicador!$B$14:$B$1704,$A17) -> 585801189 | F17: =E17/D17 -> 711.3917 | G17: =SUMIFS(Indicador!$L$14:$L$1704,Indicador!$B$14:$B$1704,$A17) -> 826506 | H17: =SUMIFS(Indicador!$G$14:$G$1704,Indicador!$B$14:$B$1704,$A17) -> 548919420 | I17: =H17*Indicador!$F$7 -> 5.287753e+08 | J17: =I17/G17 -> 639.77189 | K17: =J17/F17-1 -> -0.10067564
... A36: 32 | B36: Zacatecas | C36: =COUNTIF(Indicador!$B$14:$B$1704,$A36) -> 44 | D36: =SUMIFS(Indicador!$K$14:$K$1704,Indicador!$B$14:$B$1704,$A36) -> 1349667 | E36: =SUMIFS(Indicador!$F$14:$F$1704,Indicador!$B$14:$B$1704,$A36) -> 752801036 | F36: =E36/D36 -> 557.76798 | G36: =SUMIFS(Indicador!$L$14:$L$1704,Indicador!$B$14:$B$1704,$A36) -> 1360288 | H36: =SUMIFS(Indicador!$G$14:$G$1704,Indicador!$B$14:$B$1704,$A36) -> 835329019 | I36: =H36*Indicador!$F$7 -> 8.0467431e+08 | J36: =I36/G36 -> 591.54702 | K36: =J36/F36-1 -> 0.060561094
B37: Nacional (sin CDMX) | C37: =SUM(C6:C36) -> 1691 | D37: =SUM(D6:D36) -> 101571350 | E37: =SUM(E6:E36) -> 97594966712 | F37: =E37/D37 -> 960.85133 | G37: =SUM(G6:G36) -> 102406508 | H37: =SUM(H6:H36) -> 107225503859 | I37: =H37*Indicador!$F$7 -> 1.0329057e+11 | J37: =I37/G37 -> 1008.6328 | K37: =J37/F37-1 -> 0.049728313
