Workbook

Sheet Resumen
A1: 2027: qué cambiaría en las participaciones si la población de la Encuesta Intercensal 2025 sustituye a la ENOE
A2: Millones de pesos al año. FGP, FFM 70%, FOFIR y Fondo de Compensación; montos del PPEF 2027 y variables del DOF de agosto 2026.
A3: Escenario de esta hoja: ENOE 1T-2026 (la que usa hoy la SHCP). Ver también: Escenario ENOE 4T-2025 (misma fecha que la Intercensal) y Rango entre trimestres.
A4: En resumen
A5: ="• Con todo lo demás igual, la población de la Intercensal movería unos "&TEXT(-SUMIF($G$91:$G$122,"<0"),"#,##0")&" millones al año entre estados. "&COUNTIF($G$91:$G$122,"<0")&" estados perderían y "&COUNTIF($G$91:$G$122,">0")&" ganarían. La mayor pérdida sería para "&INDEX($B$91:$B$122,MATCH(MIN($G$91:$G$122),$G$91:$G$122,0))&" ("&TEXT(MIN($G$91:$G$122),"#,##0")&" millones"&IF(INDEX($B$91:$B$122,MATCH(MIN($G$91:$G$122),$G$91:$G$122,0))=INDEX($B$91:$B$122,MATCH(MIN($I$91:$I$122),$I$91:$I$122,0)),", que también sería la mayor en proporción: "&TEXT(MIN($I$91:$I$122),"0.0%")&" de sus participaciones).",") y, en proporción, para "&INDEX($B$91:$B$122,MATCH(MIN($I$91:$I$122),$I$91:$I$122,0))&" ("&TEXT(MIN($I$91:$I$122),"0.0%")&" de sus participaciones).") -> • Con todo lo demás igual, la población de la Intercensal movería unos 7,672 millones al año entre estados. 15 estados perderían y 17 ganarían. La mayor pérdida sería para Coahuila (-1,171 millones, que también sería la mayor en proporción: -3.6% de sus participaciones).
A6: • Las entidades afectadas podrían registrar reducciones importantes, pero por lo observado en 2021-2022 el cambio se aplicaría de forma gradual: entra con la ENOE trimestral que publique el INEGI con la nueva base, y lo ya pagado se corrige con los ajustes cuatrimestrales y el definitivo. Ver el calendario de abajo.
A7: • Referencia histórica: en 2021 el cambio por el Censo 2020 movió unos 7,500 millones al año y el Estado de México perdió 3.7% de sus participaciones (archivo 2021-2022). La magnitud ahora es parecida.
B9: Redistribución anual estimada | D9: Mayor pérdida en pesos | F9: Mayor pérdida en % | H9: Estados que pierden / ganan
B10: =-SUMIF($G$91:$G$122,"<0") -> 7671.5526 | D10: =MIN($G$91:$G$122) -> -1170.6414 | F10: =MIN($I$91:$I$122) -> -0.036144789 | H10: =COUNTIF($G$91:$G$122,"<0")&" / "&COUNTIF($G$91:$G$122,">0") -> 15 / 17
B11: millones de pesos por año | D11: =INDEX($B$91:$B$122,MATCH(MIN($G$91:$G$122),$G$91:$G$122,0)) -> Coahuila | F11: =INDEX($B$91:$B$122,MATCH(MIN($I$91:$I$122),$I$91:$I$122,0)) -> Coahuila | H11: de 32 entidades
A13: Quiénes perderían y quiénes ganarían (efecto anual, ceteris paribus) | P13: Datos de la gráfica
A14: Más afectados: en millones de pesos | F14: Más beneficiados: en millones de pesos | P14: Estado (ordenado) | Q14: Gana (%) | R14: Pierde (%)
A15: # | B15: Estado | C15: mdp | D15: % partic. | F15: # | G15: Estado | H15: mdp | I15: % partic. | P15: =INDEX($B$91:$B$122,MATCH(SMALL($I$91:$I$122,1),$I$91:$I$122,0)) -> Coahuila | Q15: =MAX(SMALL($I$91:$I$122,1),0) -> 0 | R15: =MIN(SMALL($I$91:$I$122,1),0) -> -0.036144789
A16: 1 | B16: =INDEX($B$91:$B$122,MATCH(SMALL($G$91:$G$122,1),$G$91:$G$122,0)) -> Coahuila | C16: =INDEX($G$91:$G$122,MATCH(SMALL($G$91:$G$122,1),$G$91:$G$122,0)) -> -1170.6414 | D16: =INDEX($I$91:$I$122,MATCH(SMALL($G$91:$G$122,1),$G$91:$G$122,0)) -> -0.036144789 | F16: 1 | G16: =INDEX($B$91:$B$122,MATCH(LARGE($G$91:$G$122,1),$G$91:$G$122,0)) -> Puebla | H16: =INDEX($G$91:$G$122,MATCH(LARGE($G$91:$G$122,1),$G$91:$G$122,0)) -> 2233.6538 | I16: =INDEX($I$91:$I$122,MATCH(LARGE($G$91:$G$122,1),$G$91:$G$122,0)) -> 0.037997454 | P16: =INDEX($B$91:$B$122,MATCH(SMALL($I$91:$I$122,2),$I$91:$I$122,0)) -> Guerrero | Q16: =MAX(SMALL($I$91:$I$122,2),0) -> 0 | R16: =MIN(SMALL($I$91:$I$122,2),0) -> -0.031471206
A17: 2 | B17: =INDEX($B$91:$B$122,MATCH(SMALL($G$91:$G$122,2),$G$91:$G$122,0)) -> Guerrero | C17: =INDEX($G$91:$G$122,MATCH(SMALL($G$91:$G$122,2),$G$91:$G$122,0)) -> -993.99518 | D17: =INDEX($I$91:$I$122,MATCH(SMALL($G$91:$G$122,2),$G$91:$G$122,0)) -> -0.031471206 | F17: 2 | G17: =INDEX($B$91:$B$122,MATCH(LARGE($G$91:$G$122,2),$G$91:$G$122,0)) -> Baja California | H17: =INDEX($G$91:$G$122,MATCH(LARGE($G$91:$G$122,2),$G$91:$G$122,0)) -> 1384.584 | I17: =INDEX($I$91:$I$122,MATCH(LARGE($G$91:$G$122,2),$G$91:$G$122,0)) -> 0.036944668 | P17: =INDEX($B$91:$B$122,MATCH(SMALL($I$91:$I$122,3),$I$91:$I$122,0)) -> Chihuahua | Q17: =MAX(SMALL($I$91:$I$122,3),0) -> 0 | R17: =MIN(SMALL($I$91:$I$122,3),0) -> -0.019560919
A18: 3 | B18: =INDEX($B$91:$B$122,MATCH(SMALL($G$91:$G$122,3),$G$91:$G$122,0)) -> Veracruz | C18: =INDEX($G$91:$G$122,MATCH(SMALL($G$91:$G$122,3),$G$91:$G$122,0)) -> -897.07125 | D18: =INDEX($I$91:$I$122,MATCH(SMALL($G$91:$G$122,3),$G$91:$G$122,0)) -> -0.012132902 | F18: 3 | G18: =INDEX($B$91:$B$122,MATCH(LARGE($G$91:$G$122,3),$G$91:$G$122,0)) -> Quintana Roo | H18: =INDEX($G$91:$G$122,MATCH(LARGE($G$91:$G$122,3),$G$91:$G$122,0)) -> 945.9536 | I18: =INDEX($I$91:$I$122,MATCH(LARGE($G$91:$G$122,3),$G$91:$G$122,0)) -> 0.051457276 | P18: =INDEX($B$91:$B$122,MATCH(SMALL($I$91:$I$122,4),$I$91:$I$122,0)) -> San Luis Potosí | Q18: =MAX(SMALL($I$91:$I$122,4),0) -> 0 | R18: =MIN(SMALL($I$91:$I$122,4),0) -> -0.014477143
A19: 4 | B19: =INDEX($B$91:$B$122,MATCH(SMALL($G$91:$G$122,4),$G$91:$G$122,0)) -> Ciudad de México | C19: =INDEX($G$91:$G$122,MATCH(SMALL($G$91:$G$122,4),$G$91:$G$122,0)) -> -884.41692 | D19: =INDEX($I$91:$I$122,MATCH(SMALL($G$91:$G$122,4),$G$91:$G$122,0)) -> -0.0071077827 | F19: 4 | G19: =INDEX($B$91:$B$122,MATCH(LARGE($G$91:$G$122,4),$G$91:$G$122,0)) -> Nuevo León | H19: =INDEX($G$91:$G$122,MATCH(LARGE($G$91:$G$122,4),$G$91:$G$122,0)) -> 546.83358 | I19: =INDEX($I$91:$I$122,MATCH(LARGE($G$91:$G$122,4),$G$91:$G$122,0)) -> 0.0086695967 | P19: =INDEX($B$91:$B$122,MATCH(SMALL($I$91:$I$122,5),$I$91:$I$122,0)) -> Hidalgo | Q19: =MAX(SMALL($I$91:$I$122,5),0) -> 0 | R19: =MIN(SMALL($I$91:$I$122,5),0) -> -0.014267507
A20: 5 | B20: =INDEX($B$91:$B$122,MATCH(SMALL($G$91:$G$122,5),$G$91:$G$122,0)) -> México | C20: =INDEX($G$91:$G$122,MATCH(SMALL($G$91:$G$122,5),$G$91:$G$122,0)) -> -837.82081 | D20: =INDEX($I$91:$I$122,MATCH(SMALL($G$91:$G$122,5),$G$91:$G$122,0)) -> -0.004596737 | F20: 5 | G20: =INDEX($B$91:$B$122,MATCH(LARGE($G$91:$G$122,5),$G$91:$G$122,0)) -> Querétaro | H20: =INDEX($G$91:$G$122,MATCH(LARGE($G$91:$G$122,5),$G$91:$G$122,0)) -> 533.17003 | I20: =INDEX($I$91:$I$122,MATCH(LARGE($G$91:$G$122,5),$G$91:$G$122,0)) -> 0.022723624 | P20: =INDEX($B$91:$B$122,MATCH(SMALL($I$91:$I$122,6),$I$91:$I$122,0)) -> Veracruz | Q20: =MAX(SMALL($I$91:$I$122,6),0) -> 0 | R20: =MIN(SMALL($I$91:$I$122,6),0) -> -0.012132902
P21: =INDEX($B$91:$B$122,MATCH(SMALL($I$91:$I$122,7),$I$91:$I$122,0)) -> Tabasco | Q21: =MAX(SMALL($I$91:$I$122,7),0) -> 0 | R21: =MIN(SMALL($I$91:$I$122,7),0) -> -0.0093755007
A22: Más afectados: en % de sus participaciones | F22: Más beneficiados: en % de sus participaciones | P22: =INDEX($B$91:$B$122,MATCH(SMALL($I$91:$I$122,8),$I$91:$I$122,0)) -> Durango | Q22: =MAX(SMALL($I$91:$I$122,8),0) -> 0 | R22: =MIN(SMALL($I$91:$I$122,8),0) -> -0.0083548875
A23: # | B23: Estado | C23: mdp | D23: % partic. | F23: # | G23: Estado | H23: mdp | I23: % partic. | P23: =INDEX($B$91:$B$122,MATCH(SMALL($I$91:$I$122,9),$I$91:$I$122,0)) -> Michoacán | Q23: =MAX(SMALL($I$91:$I$122,9),0) -> 0 | R23: =MIN(SMALL($I$91:$I$122,9),0) -> -0.0074302306
A24: 1 | B24: =INDEX($B$91:$B$122,MATCH(SMALL($I$91:$I$122,1),$I$91:$I$122,0)) -> Coahuila | C24: =INDEX($G$91:$G$122,MATCH(SMALL($I$91:$I$122,1),$I$91:$I$122,0)) -> -1170.6414 | D24: =INDEX($I$91:$I$122,MATCH(SMALL($I$91:$I$122,1),$I$91:$I$122,0)) -> -0.036144789 | F24: 1 | G24: =INDEX($B$91:$B$122,MATCH(LARGE($I$91:$I$122,1),$I$91:$I$122,0)) -> Quintana Roo | H24: =INDEX($G$91:$G$122,MATCH(LARGE($I$91:$I$122,1),$I$91:$I$122,0)) -> 945.9536 | I24: =INDEX($I$91:$I$122,MATCH(LARGE($I$91:$I$122,1),$I$91:$I$122,0)) -> 0.051457276 | P24: =INDEX($B$91:$B$122,MATCH(SMALL($I$91:$I$122,10),$I$91:$I$122,0)) -> Ciudad de México | Q24: =MAX(SMALL($I$91:$I$122,10),0) -> 0 | R24: =MIN(SMALL($I$91:$I$122,10),0) -> -0.0071077827
A25: 2 | B25: =INDEX($B$91:$B$122,MATCH(SMALL($I$91:$I$122,2),$I$91:$I$122,0)) -> Guerrero | C25: =INDEX($G$91:$G$122,MATCH(SMALL($I$91:$I$122,2),$I$91:$I$122,0)) -> -993.99518 | D25: =INDEX($I$91:$I$122,MATCH(SMALL($I$91:$I$122,2),$I$91:$I$122,0)) -> -0.031471206 | F25: 2 | G25: =INDEX($B$91:$B$122,MATCH(LARGE($I$91:$I$122,2),$I$91:$I$122,0)) -> Puebla | H25: =INDEX($G$91:$G$122,MATCH(LARGE($I$91:$I$122,2),$I$91:$I$122,0)) -> 2233.6538 | I25: =INDEX($I$91:$I$122,MATCH(LARGE($I$91:$I$122,2),$I$91:$I$122,0)) -> 0.037997454 | P25: =INDEX($B$91:$B$122,MATCH(SMALL($I$91:$I$122,11),$I$91:$I$122,0)) -> México | Q25: =MAX(SMALL($I$91:$I$122,11),0) -> 0 | R25: =MIN(SMALL($I$91:$I$122,11),0) -> -0.004596737
A26: 3 | B26: =INDEX($B$91:$B$122,MATCH(SMALL($I$91:$I$122,3),$I$91:$I$122,0)) -> Chihuahua | C26: =INDEX($G$91:$G$122,MATCH(SMALL($I$91:$I$122,3),$I$91:$I$122,0)) -> -748.04586 | D26: =INDEX($I$91:$I$122,MATCH(SMALL($I$91:$I$122,3),$I$91:$I$122,0)) -> -0.019560919 | F26: 3 | G26: =INDEX($B$91:$B$122,MATCH(LARGE($I$91:$I$122,3),$I$91:$I$122,0)) -> Baja California | H26: =INDEX($G$91:$G$122,MATCH(LARGE($I$91:$I$122,3),$I$91:$I$122,0)) -> 1384.584 | I26: =INDEX($I$91:$I$122,MATCH(LARGE($I$91:$I$122,3),$I$91:$I$122,0)) -> 0.036944668 | P26: =INDEX($B$91:$B$122,MATCH(SMALL($I$91:$I$122,12),$I$91:$I$122,0)) -> Jalisco | Q26: =MAX(SMALL($I$91:$I$122,12),0) -> 0 | R26: =MIN(SMALL($I$91:$I$122,12),0) -> -0.0045705598
A27: 4 | B27: =INDEX($B$91:$B$122,MATCH(SMALL($I$91:$I$122,4),$I$91:$I$122,0)) -> San Luis Potosí | C27: =INDEX($G$91:$G$122,MATCH(SMALL($I$91:$I$122,4),$I$91:$I$122,0)) -> -381.15666 | D27: =INDEX($I$91:$I$122,MATCH(SMALL($I$91:$I$122,4),$I$91:$I$122,0)) -> -0.014477143 | F27: 4 | G27: =INDEX($B$91:$B$122,MATCH(LARGE($I$91:$I$122,4),$I$91:$I$122,0)) -> Baja California Sur | H27: =INDEX($G$91:$G$122,MATCH(LARGE($I$91:$I$122,4),$I$91:$I$122,0)) -> 233.85718 | I27: =INDEX($I$91:$I$122,MATCH(LARGE($I$91:$I$122,4),$I$91:$I$122,0)) -> 0.027503349 | P27: =INDEX($B$91:$B$122,MATCH(SMALL($I$91:$I$122,13),$I$91:$I$122,0)) -> Tlaxcala | Q27: =MAX(SMALL($I$91:$I$122,13),0) -> 0 | R27: =MIN(SMALL($I$91:$I$122,13),0) -> -0.0036984564
A28: 5 | B28: =INDEX($B$91:$B$122,MATCH(SMALL($I$91:$I$122,5),$I$91:$I$122,0)) -> Hidalgo | C28: =INDEX($G$91:$G$122,MATCH(SMALL($I$91:$I$122,5),$I$91:$I$122,0)) -> -412.38267 | D28: =INDEX($I$91:$I$122,MATCH(SMALL($I$91:$I$122,5),$I$91:$I$122,0)) -> -0.014267507 | F28: 5 | G28: =INDEX($B$91:$B$122,MATCH(LARGE($I$91:$I$122,5),$I$91:$I$122,0)) -> Campeche | H28: =INDEX($G$91:$G$122,MATCH(LARGE($I$91:$I$122,5),$I$91:$I$122,0)) -> 196.98141 | I28: =INDEX($I$91:$I$122,MATCH(LARGE($I$91:$I$122,5),$I$91:$I$122,0)) -> 0.02316048 | P28: =INDEX($B$91:$B$122,MATCH(SMALL($I$91:$I$122,14),$I$91:$I$122,0)) -> Chiapas | Q28: =MAX(SMALL($I$91:$I$122,14),0) -> 0 | R28: =MIN(SMALL($I$91:$I$122,14),0) -> -0.0024307091
P29: =INDEX($B$91:$B$122,MATCH(SMALL($I$91:$I$122,15),$I$91:$I$122,0)) -> Oaxaca | Q29: =MAX(SMALL($I$91:$I$122,15),0) -> 0 | R29: =MIN(SMALL($I$91:$I$122,15),0) -> -0.00058329686
A30: Efecto por estado (% de sus participaciones 2027 estimadas) | P30: =INDEX($B$91:$B$122,MATCH(SMALL($I$91:$I$122,16),$I$91:$I$122,0)) -> Zacatecas | Q30: =MAX(SMALL($I$91:$I$122,16),0) -> 0.00078429921 | R30: =MIN(SMALL($I$91:$I$122,16),0) -> 0
P31: =INDEX($B$91:$B$122,MATCH(SMALL($I$91:$I$122,17),$I$91:$I$122,0)) -> Colima | Q31: =MAX(SMALL($I$91:$I$122,17),0) -> 0.0011091833 | R31: =MIN(SMALL($I$91:$I$122,17),0) -> 0
P32: =INDEX($B$91:$B$122,MATCH(SMALL($I$91:$I$122,18),$I$91:$I$122,0)) -> Sonora | Q32: =MAX(SMALL($I$91:$I$122,18),0) -> 0.0043837337 | R32: =MIN(SMALL($I$91:$I$122,18),0) -> 0
P33: =INDEX($B$91:$B$122,MATCH(SMALL($I$91:$I$122,19),$I$91:$I$122,0)) -> Morelos | Q33: =MAX(SMALL($I$91:$I$122,19),0) -> 0.0045577784 | R33: =MIN(SMALL($I$91:$I$122,19),0) -> 0
P34: =INDEX($B$91:$B$122,MATCH(SMALL($I$91:$I$122,20),$I$91:$I$122,0)) -> Aguascalientes | Q34: =MAX(SMALL($I$91:$I$122,20),0) -> 0.0049298768 | R34: =MIN(SMALL($I$91:$I$122,20),0) -> 0
P35: =INDEX($B$91:$B$122,MATCH(SMALL($I$91:$I$122,21),$I$91:$I$122,0)) -> Tamaulipas | Q35: =MAX(SMALL($I$91:$I$122,21),0) -> 0.0051274122 | R35: =MIN(SMALL($I$91:$I$122,21),0) -> 0
P36: =INDEX($B$91:$B$122,MATCH(SMALL($I$91:$I$122,22),$I$91:$I$122,0)) -> Sinaloa | Q36: =MAX(SMALL($I$91:$I$122,22),0) -> 0.005221782 | R36: =MIN(SMALL($I$91:$I$122,22),0) -> 0
P37: =INDEX($B$91:$B$122,MATCH(SMALL($I$91:$I$122,23),$I$91:$I$122,0)) -> Guanajuato | Q37: =MAX(SMALL($I$91:$I$122,23),0) -> 0.0069280256 | R37: =MIN(SMALL($I$91:$I$122,23),0) -> 0
P38: =INDEX($B$91:$B$122,MATCH(SMALL($I$91:$I$122,24),$I$91:$I$122,0)) -> Nuevo León | Q38: =MAX(SMALL($I$91:$I$122,24),0) -> 0.0086695967 | R38: =MIN(SMALL($I$91:$I$122,24),0) -> 0
P39: =INDEX($B$91:$B$122,MATCH(SMALL($I$91:$I$122,25),$I$91:$I$122,0)) -> Nayarit | Q39: =MAX(SMALL($I$91:$I$122,25),0) -> 0.014908909 | R39: =MIN(SMALL($I$91:$I$122,25),0) -> 0
P40: =INDEX($B$91:$B$122,MATCH(SMALL($I$91:$I$122,26),$I$91:$I$122,0)) -> Yucatán | Q40: =MAX(SMALL($I$91:$I$122,26),0) -> 0.016424825 | R40: =MIN(SMALL($I$91:$I$122,26),0) -> 0
P41: =INDEX($B$91:$B$122,MATCH(SMALL($I$91:$I$122,27),$I$91:$I$122,0)) -> Querétaro | Q41: =MAX(SMALL($I$91:$I$122,27),0) -> 0.022723624 | R41: =MIN(SMALL($I$91:$I$122,27),0) -> 0
P42: =INDEX($B$91:$B$122,MATCH(SMALL($I$91:$I$122,28),$I$91:$I$122,0)) -> Campeche | Q42: =MAX(SMALL($I$91:$I$122,28),0) -> 0.02316048 | R42: =MIN(SMALL($I$91:$I$122,28),0) -> 0
...

Sheet Escenario ENOE 4T-2025
A1: Escenario ENOE 4T-2025: misma fecha que la Intercensal (oct-dic 2025)
A2: Compara la misma población medida con dos fuentes: aísla el efecto de cambiar la base de población (como la comparación 2021 del Censo). Montos PPEF 2027 y variables del DOF de agosto 2026.
A3: Redistribución anual (FGP+FFM+FOFIR, mdp) | D3: Estados que pierden / ganan | G3: Mayor pérdida (mdp) | I3: Mayor pérdida (%)
A4: =-SUMIF($H$7:$H$38,"<0") -> 8140.5731 | D4: =COUNTIF($H$7:$H$38,"<0")&" / "&COUNTIF($H$7:$H$38,">0") -> 17 / 15 | G4: =INDEX($A$7:$A$38,MATCH(MIN($H$7:$H$38),$H$7:$H$38,0))&": "&TEXT(MIN($H$7:$H$38),"#,##0") -> México: -1,259 | I4: =INDEX($A$7:$A$38,MATCH(MIN($I$7:$I$38),$I$7:$I$38,0))&": "&TEXT(MIN($I$7:$I$38),"0.0%") -> Coahuila: -3.5%
A6: Estado | B6: Población ENOE 4T-2025 | C6: Población Intercensal 2025 | D6: Cambio en población | E6: FGP | F6: FFM 70% | G6: FOFIR | H6: Total FGP+FFM+FOFIR (mdp) | I6: % de sus participaciones 2027 | J6: Fondo de Compensación (mdp) | K6: Total con FoCo (mdp)
A7: Aguascalientes | B7: =Población!L5 -> 1519678 | C7: =Población!D5 -> 1539174 | D7: =C7/B7-1 -> 0.012829034 | E7: =SUMIFS('Cálculo FGP-FFM-FOFIR'!$Y$5:$Y$260,'Cálculo FGP-FFM-FOFIR'!$B$5:$B$260,$A7,'Cálculo FGP-FFM-FOFIR'!$A$5:$A$260,"FGP*")/1000000 -> 126.60537 | F7: =SUMIFS('Cálculo FGP-FFM-FOFIR'!$Y$5:$Y$260,'Cálculo FGP-FFM-FOFIR'!$B$5:$B$260,$A7,'Cálculo FGP-FFM-FOFIR'!$A$5:$A$260,"FFM*")/1000000 -> 4.1097308 | G7: =SUMIFS('Cálculo FGP-FFM-FOFIR'!$Y$5:$Y$260,'Cálculo FGP-FFM-FOFIR'!$B$5:$B$260,$A7,'Cálculo FGP-FFM-FOFIR'!$A$5:$A$260,"FOFIR*")/1000000 -> 5.7549689 | H7: =SUM(E7:G7) -> 136.47007 | I7: =H7/('Base 2027'!N5/1000000) -> 0.0096337901 | J7: ='Cálculo FoCo'!Q5/1000000 -> 0 | K7: =H7+J7 -> 136.47007
A8: Baja California | B8: =Población!L6 -> 3790412 | C8: =Población!D6 -> 4009678 | D8: =C8/B8-1 -> 0.057847537 | E8: =SUMIFS('Cálculo FGP-FFM-FOFIR'!$Y$5:$Y$260,'Cálculo FGP-FFM-FOFIR'!$B$5:$B$260,$A8,'Cálculo FGP-FFM-FOFIR'!$A$5:$A$260,"FGP*")/1000000 -> 1522.545 | F8: =SUMIFS('Cálculo FGP-FFM-FOFIR'!$Y$5:$Y$260,'Cálculo FGP-FFM-FOFIR'!$B$5:$B$260,$A8,'Cálculo FGP-FFM-FOFIR'!$A$5:$A$260,"FFM*")/1000000 -> 43.577978 | G8: =SUMIFS('Cálculo FGP-FFM-FOFIR'!$Y$5:$Y$260,'Cálculo FGP-FFM-FOFIR'!$B$5:$B$260,$A8,'Cálculo FGP-FFM-FOFIR'!$A$5:$A$260,"FOFIR*")/1000000 -> 85.197474 | H8: =SUM(E8:G8) -> 1651.3205 | I8: =H8/('Base 2027'!N6/1000000) -> 0.044061961 | J8: ='Cálculo FoCo'!Q6/1000000 -> 0 | K8: =H8+J8 -> 1651.3205
A9: Baja California Sur | B9: =Población!L7 -> 906940 | C9: =Población!D7 -> 961514 | D9: =C9/B9-1 -> 0.060173771 | E9: =SUMIFS('Cálculo FGP-FFM-FOFIR'!$Y$5:$Y$260,'Cálculo FGP-FFM-FOFIR'!$B$5:$B$260,$A9,'Cálculo FGP-FFM-FOFIR'!$A$5:$A$260,"FGP*")/1000000 -> 343.9255 | F9: =SUMIFS('Cálculo FGP-FFM-FOFIR'!$Y$5:$Y$260,'Cálculo FGP-FFM-FOFIR'!$B$5:$B$260,$A9,'Cálculo FGP-FFM-FOFIR'!$A$5:$A$260,"FFM*")/1000000 -> 10.078375 | G9: =SUMIFS('Cálculo FGP-FFM-FOFIR'!$Y$5:$Y$260,'Cálculo FGP-FFM-FOFIR'!$B$5:$B$260,$A9,'Cálculo FGP-FFM-FOFIR'!$A$5:$A$260,"FOFIR*")/1000000 -> 19.207062 | H9: =SUM(E9:G9) -> 373.21094 | I9: =H9/('Base 2027'!N7/1000000) -> 0.043892391 | J9: ='Cálculo FoCo'!Q7/1000000 -> 0 | K9: =H9+J9 -> 373.21094
A10: Campeche | B10: =Población!L8 -> 918817 | C10: =Población!D8 -> 968673 | D10: =C10/B10-1 -> 0.054261077 | E10: =SUMIFS('Cálculo FGP-FFM-FOFIR'!$Y$5:$Y$260,'Cálculo FGP-FFM-FOFIR'!$B$5:$B$260,$A10,'Cálculo FGP-FFM-FOFIR'!$A$5:$A$260,"FGP*")/1000000 -> 266.41135 | F10: =SUMIFS('Cálculo FGP-FFM-FOFIR'!$Y$5:$Y$260,'Cálculo FGP-FFM-FOFIR'!$B$5:$B$260,$A10,'Cálculo FGP-FFM-FOFIR'!$A$5:$A$260,"FFM*")/1000000 -> 9.3173357 | G10: =SUMIFS('Cálculo FGP-FFM-FOFIR'!$Y$5:$Y$260,'Cálculo FGP-FFM-FOFIR'!$B$5:$B$260,$A10,'Cálculo FGP-FFM-FOFIR'!$A$5:$A$260,"FOFIR*")/1000000 -> 8.4208395 | H10: =SUM(E10:G10) -> 284.14953 | I10: =H10/('Base 2027'!N8/1000000) -> 0.033409445 | J10: ='Cálculo FoCo'!Q8/1000000 -> 0 | K10: =H10+J10 -> 284.14953
A11: Coahuila | B11: =Población!L9 -> 3582441 | C11: =Población!D9 -> 3415128 | D11: =C11/B11-1 -> -0.04670363 | E11: =SUMIFS('Cálculo FGP-FFM-FOFIR'!$Y$5:$Y$260,'Cálculo FGP-FFM-FOFIR'!$B$5:$B$260,$A11,'Cálculo FGP-FFM-FOFIR'!$A$5:$A$260,"FGP*")/1000000 -> -1063.1627 | F11: =SUMIFS('Cálculo FGP-FFM-FOFIR'!$Y$5:$Y$260,'Cálculo FGP-FFM-FOFIR'!$B$5:$B$260,$A11,'Cálculo FGP-FFM-FOFIR'!$A$5:$A$260,"FFM*")/1000000 -> -31.289415 | G11: =SUMIFS('Cálculo FGP-FFM-FOFIR'!$Y$5:$Y$260,'Cálculo FGP-FFM-FOFIR'!$B$5:$B$260,$A11,'Cálculo FGP-FFM-FOFIR'!$A$5:$A$260,"FOFIR*")/1000000 -> -45.230158 | H11: =SUM(E11:G11) -> -1139.6822 | I11: =H11/('Base 2027'!N9/1000000) -> -0.035188891 | J11: ='Cálculo FoCo'!Q9/1000000 -> 0 | K11: =H11+J11 -> -1139.6822
A12: Colima | B12: =Población!L10 -> 745394 | C12: =Población!D10 -> 762212 | D12: =C12/B12-1 -> 0.022562564 | E12: =SUMIFS('Cálculo FGP-FFM-FOFIR'!$Y$5:$Y$260,'Cálculo FGP-FFM-FOFIR'!$B$5:$B$260,$A12,'Cálculo FGP-FFM-FOFIR'!$A$5:$A$260,"FGP*")/1000000 -> 105.44598 | F12: =SUMIFS('Cálculo FGP-FFM-FOFIR'!$Y$5:$Y$260,'Cálculo FGP-FFM-FOFIR'!$B$5:$B$260,$A12,'Cálculo FGP-FFM-FOFIR'!$A$5:$A$260,"FFM*")/1000000 -> 3.3635019 | G12: =SUMIFS('Cálculo FGP-FFM-FOFIR'!$Y$5:$Y$260,'Cálculo FGP-FFM-FOFIR'!$B$5:$B$260,$A12,'Cálculo FGP-FFM-FOFIR'!$A$5:$A$260,"FOFIR*")/1000000 -> 3.8499729 | H12: =SUM(E12:G12) -> 112.65946 | I12: =H12/('Base 2027'!N10/1000000) -> 0.015366031 | J12: ='Cálculo FoCo'!Q10/1000000 -> 0 | K12: =H12+J12 -> 112.65946
A13: Chiapas | B13: =Población!L11 -> 5900473 | C13: =Población!D11 -> 5860728 | D13: =C13/B13-1 -> -0.0067359007 | E13: =SUMIFS('Cálculo FGP-FFM-FOFIR'!$Y$5:$Y$260,'Cálculo FGP-FFM-FOFIR'!$B$5:$B$260,$A13,'Cálculo FGP-FFM-FOFIR'!$A$5:$A$260,"FGP*")/1000000 -> -224.50733 | F13: =SUMIFS('Cálculo FGP-FFM-FOFIR'!$Y$5:$Y$260,'Cálculo FGP-FFM-FOFIR'!$B$5:$B$260,$A13,'Cálculo FGP-FFM-FOFIR'!$A$5:$A$260,"FFM*")/1000000 -> -6.8739706 | G13: =SUMIFS('Cálculo FGP-FFM-FOFIR'!$Y$5:$Y$260,'Cálculo FGP-FFM-FOFIR'!$B$5:$B$260,$A13,'Cálculo FGP-FFM-FOFIR'!$A$5:$A$260,"FOFIR*")/1000000 -> -8.9882187 | H13: =SUM(E13:G13) -> -240.36952 | I13: =H13/('Base 2027'!N11/1000000) -> -0.0043244817 | J13: ='Cálculo FoCo'!Q11/1000000 -> -1.2837507 | K13: =H13+J13 -> -241.65327
A14: Chihuahua | B14: =Población!L12 -> 3991333 | C14: =Población!D12 -> 3903944 | D14: =C14/B14-1 -> -0.02189469 | E14: =SUMIFS('Cálculo FGP-FFM-FOFIR'!$Y$5:$Y$260,'Cálculo FGP-FFM-FOFIR'!$B$5:$B$260,$A14,'Cálculo FGP-FFM-FOFIR'!$A$5:$A$260,"FGP*")/1000000 -> -549.35241 | F14: =SUMIFS('Cálculo FGP-FFM-FOFIR'!$Y$5:$Y$260,'Cálculo FGP-FFM-FOFIR'!$B$5:$B$260,$A14,'Cálculo FGP-FFM-FOFIR'!$A$5:$A$260,"FFM*")/1000000 -> -16.328463 | G14: =SUMIFS('Cálculo FGP-FFM-FOFIR'!$Y$5:$Y$260,'Cálculo FGP-FFM-FOFIR'!$B$5:$B$260,$A14,'Cálculo FGP-FFM-FOFIR'!$A$5:$A$260,"FOFIR*")/1000000 -> -38.165873 | H14: =SUM(E14:G14) -> -603.84675 | I14: =H14/('Base 2027'!N12/1000000) -> -0.015790204 | J14: ='Cálculo FoCo'!Q12/1000000 -> 0 | K14: =H14+J14 -> -603.84675
A15: Ciudad de México | B15: =Población!L13 -> 9319955 | C15: =Población!D13 -> 9216407 | D15: =C15/B15-1 -> -0.011110354 | E15: =SUMIFS('Cálculo FGP-FFM-FOFIR'!$Y$5:$Y$260,'Cálculo FGP-FFM-FOFIR'!$B$5:$B$260,$A15,'Cálculo FGP-FFM-FOFIR'!$A$5:$A$260,"FGP*")/1000000 -> -750.90091 | F15: =SUMIFS('Cálculo FGP-FFM-FOFIR'!$Y$5:$Y$260,'Cálculo FGP-FFM-FOFIR'!$B$5:$B$260,$A15,'Cálculo FGP-FFM-FOFIR'!$A$5:$A$260,"FFM*")/1000000 -> -19.568815 | G15: =SUMIFS('Cálculo FGP-FFM-FOFIR'!$Y$5:$Y$260,'Cálculo FGP-FFM-FOFIR'!$B$5:$B$260,$A15,'Cálculo FGP-FFM-FOFIR'!$A$5:$A$260,"FOFIR*")/1000000 -> -36.947213 | H15: =SUM(E15:G15) -> -807.41694 | I15: =H15/('Base 2027'!N13/1000000) -> -0.0064889579 | J15: ='Cálculo FoCo'!Q13/1000000 -> 0 | K15: =H15+J15 -> -807.41694
A16: Durango | B16: =Población!L14 -> 1954301 | C16: =Población!D14 -> 1943290 | D16: =C16/B16-1 -> -0.0056342396 | E16: =SUMIFS('Cálculo FGP-FFM-FOFIR'!$Y$5:$Y$260,'Cálculo FGP-FFM-FOFIR'!$B$5:$B$260,$A16,'Cálculo FGP-FFM-FOFIR'!$A$5:$A$260,"FGP*")/1000000 -> -60.636109 | F16: =SUMIFS('Cálculo FGP-FFM-FOFIR'!$Y$5:$Y$260,'Cálculo FGP-FFM-FOFIR'!$B$5:$B$260,$A16,'Cálculo FGP-FFM-FOFIR'!$A$5:$A$260,"FFM*")/1000000 -> -1.8642901 | G16: =SUMIFS('Cálculo FGP-FFM-FOFIR'!$Y$5:$Y$260,'Cálculo FGP-FFM-FOFIR'!$B$5:$B$260,$A16,'Cálculo FGP-FFM-FOFIR'!$A$5:$A$260,"FOFIR*")/1000000 -> -10.271353 | H16: =SUM(E16:G16) -> -72.771752 | I16: =H16/('Base 2027'!N14/1000000) -> -0.0038891897 | J16: ='Cálculo FoCo'!Q14/1000000 -> 0 | K16: =H16+J16 -> -72.771752
A17: Guanajuato | B17: =Población!L15 -> 6376710 | C17: =Población!D15 -> 6446935 | D17: =C17/B17-1 -> 0.011012732 | E17: =SUMIFS('Cálculo FGP-FFM-FOFIR'!$Y$5:$Y$260,'Cálculo FGP-FFM-FOFIR'!$B$5:$B$260,$A17,'Cálculo FGP-FFM-FOFIR'!$A$5:$A$260,"FGP*")/1000000 -> 507.64479 | F17: =SUMIFS('Cálculo FGP-FFM-FOFIR'!$Y$5:$Y$260,'Cálculo FGP-FFM-FOFIR'!$B$5:$B$260,$A17,'Cálculo FGP-FFM-FOFIR'!$A$5:$A$260,"FFM*")/1000000 -> 14.209334 | G17: =SUMIFS('Cálculo FGP-FFM-FOFIR'!$Y$5:$Y$260,'Cálculo FGP-FFM-FOFIR'!$B$5:$B$260,$A17,'Cálculo FGP-FFM-FOFIR'!$A$5:$A$260,"FOFIR*")/1000000 -> 22.040495 | H17: =SUM(E17:G17) -> 543.89462 | I17: =H17/('Base 2027'!N15/1000000) -> 0.009223547 | J17: ='Cálculo FoCo'!Q15/1000000 -> 0 | K17: =H17+J17 -> 543.89462
A18: Guerrero | B18: =Población!L16 -> 3578620 | C18: =Población!D16 -> 3418902 | D18: =C18/B18-1 -> -0.044631171 | E18: =SUMIFS('Cálculo FGP-FFM-FOFIR'!$Y$5:$Y$260,'Cálculo FGP-FFM-FOFIR'!$B$5:$B$260,$A18,'Cálculo FGP-FFM-FOFIR'!$A$5:$A$260,"FGP*")/1000000 -> -972.74118 | F18: =SUMIFS('Cálculo FGP-FFM-FOFIR'!$Y$5:$Y$260,'Cálculo FGP-FFM-FOFIR'!$B$5:$B$260,$A18,'Cálculo FGP-FFM-FOFIR'!$A$5:$A$260,"FFM*")/1000000 -> -29.935775 | G18: =SUMIFS('Cálculo FGP-FFM-FOFIR'!$Y$5:$Y$260,'Cálculo FGP-FFM-FOFIR'!$B$5:$B$260,$A18,'Cálculo FGP-FFM-FOFIR'!$A$5:$A$260,"FOFIR*")/1000000 -> -32.713741 | H18: =SUM(E18:G18) -> -1035.3907 | I18: =H18/('Base 2027'!N16/1000000) -> -0.032781843 | J18: ='Cálculo FoCo'!Q16/1000000 -> -43.648385 | K18: =H18+J18 -> -1079.0391
... A38: Zacatecas | B38: =Población!L36 -> 1703991 | C38: =Población!D36 -> 1686419 | D38: =C38/B38-1 -> -0.010312261 | E38: =SUMIFS('Cálculo FGP-FFM-FOFIR'!$Y$5:$Y$260,'Cálculo FGP-FFM-FOFIR'!$B$5:$B$260,$A38,'Cálculo FGP-FFM-FOFIR'!$A$5:$A$260,"FGP*")/1000000 -> -104.26142 | F38: =SUMIFS('Cálculo FGP-FFM-FOFIR'!$Y$5:$Y$260,'Cálculo FGP-FFM-FOFIR'!$B$5:$B$260,$A38,'Cálculo FGP-FFM-FOFIR'!$A$5:$A$260,"FFM*")/1000000 -> -3.0642391 | G38: =SUMIFS('Cálculo FGP-FFM-FOFIR'!$Y$5:$Y$260,'Cálculo FGP-FFM-FOFIR'!$B$5:$B$260,$A38,'Cálculo FGP-FFM-FOFIR'!$A$5:$A$260,"FOFIR*")/1000000 -> -4.1387961 | H38: =SUM(E38:G38) -> -111.46445 | I38: =H38/('Base 2027'!N36/1000000) -> -0.0067321056 | J38: ='Cálculo FoCo'!Q36/1000000 -> 10.404434 | K38: =H38+J38 -> -101.06002
A39: Total | B39: =SUM(B7:B38) -> 131001723 | C39: =SUM(C7:C38) -> 130911314 | D39: =C39/B39-1 -> -0.00069013596 | E39: =SUM(E7:E38) -> -2.0747848e-11 | F39: =SUM(F7:F38) -> -3.9701575e-12 | G39: =SUM(G7:G38) -> 2.354561e-12 | H39: =SUM(H7:H38) -> -2.1657343e-11 | J39: =SUM(J7:J38) -> -4.7251092e-13 | K39: =SUM(K7:K38) -> -2.2055247e-11
A41: Fondo de Compensación: se calcula aparte con la ENOE 4T-2024 que usa la SHCP para ese fondo; es igual en todos los escenarios. % sobre las participaciones 2027 estimadas (pestaña Base 2027).

Sheet Escenario ENOE 1T-2026
A1: Escenario ENOE 1T-2026: frente al cálculo vigente de la SHCP (ene-mar 2026)
A2: Población que usa hoy la SHCP (DOF de agosto 2026). Mezcla fechas (oct-2025 vs. ene-mar 2026): parte de la diferencia es movimiento de la ENOE entre trimestres.
A3: Redistribución anual (FGP+FFM+FOFIR, mdp) | D3: Estados que pierden / ganan | G3: Mayor pérdida (mdp) | I3: Mayor pérdida (%)
A4: =-SUMIF($H$7:$H$38,"<0") -> 7178.6253 | D4: =COUNTIF($H$7:$H$38,"<0")&" / "&COUNTIF($H$7:$H$38,">0") -> 14 / 18 | G4: =INDEX($A$7:$A$38,MATCH(MIN($H$7:$H$38),$H$7:$H$38,0))&": "&TEXT(MIN($H$7:$H$38),"#,##0") -> Coahuila: -1,171 | I4: =INDEX($A$7:$A$38,MATCH(MIN($I$7:$I$38),$I$7:$I$38,0))&": "&TEXT(MIN($I$7:$I$38),"0.0%") -> Coahuila: -3.6%
A6: Estado | B6: Población ENOE 1T-2026 | C6: Población Intercensal 2025 | D6: Cambio en población | E6: FGP | F6: FFM 70% | G6: FOFIR | H6: Total FGP+FFM+FOFIR (mdp) | I6: % de sus participaciones 2027 | J6: Fondo de Compensación (mdp) | K6: Total con FoCo (mdp)
A7: Aguascalientes | B7: =Población!B5 -> 1531396 | C7: =Población!D5 -> 1539174 | D7: =C7/B7-1 -> 0.0050790259 | E7: =SUMIFS('Cálculo FGP-FFM-FOFIR'!$Q$5:$Q$260,'Cálculo FGP-FFM-FOFIR'!$B$5:$B$260,$A7,'Cálculo FGP-FFM-FOFIR'!$A$5:$A$260,"FGP*")/1000000 -> 65.2707 | F7: =SUMIFS('Cálculo FGP-FFM-FOFIR'!$Q$5:$Q$260,'Cálculo FGP-FFM-FOFIR'!$B$5:$B$260,$A7,'Cálculo FGP-FFM-FOFIR'!$A$5:$A$260,"FFM*")/1000000 -> 2.1210539 | G7: =SUMIFS('Cálculo FGP-FFM-FOFIR'!$Q$5:$Q$260,'Cálculo FGP-FFM-FOFIR'!$B$5:$B$260,$A7,'Cálculo FGP-FFM-FOFIR'!$A$5:$A$260,"FOFIR*")/1000000 -> 2.4437558 | H7: =SUM(E7:G7) -> 69.83551 | I7: =H7/('Base 2027'!N5/1000000) -> 0.0049298768 | J7: ='Cálculo FoCo'!Q5/1000000 -> 0 | K7: =H7+J7 -> 69.83551
A8: Baja California | B8: =Población!B6 -> 3830329 | C8: =Población!D6 -> 4009678 | D8: =C8/B8-1 -> 0.046823393 | E8: =SUMIFS('Cálculo FGP-FFM-FOFIR'!$Q$5:$Q$260,'Cálculo FGP-FFM-FOFIR'!$B$5:$B$260,$A8,'Cálculo FGP-FFM-FOFIR'!$A$5:$A$260,"FGP*")/1000000 -> 1277.1019 | F8: =SUMIFS('Cálculo FGP-FFM-FOFIR'!$Q$5:$Q$260,'Cálculo FGP-FFM-FOFIR'!$B$5:$B$260,$A8,'Cálculo FGP-FFM-FOFIR'!$A$5:$A$260,"FFM*")/1000000 -> 36.613813 | G8: =SUMIFS('Cálculo FGP-FFM-FOFIR'!$Q$5:$Q$260,'Cálculo FGP-FFM-FOFIR'!$B$5:$B$260,$A8,'Cálculo FGP-FFM-FOFIR'!$A$5:$A$260,"FOFIR*")/1000000 -> 70.868296 | H8: =SUM(E8:G8) -> 1384.584 | I8: =H8/('Base 2027'!N6/1000000) -> 0.036944668 | J8: ='Cálculo FoCo'!Q6/1000000 -> 0 | K8: =H8+J8 -> 1384.584
A9: Baja California Sur | B9: =Población!B7 -> 928591 | C9: =Población!D7 -> 961514 | D9: =C9/B9-1 -> 0.035454791 | E9: =SUMIFS('Cálculo FGP-FFM-FOFIR'!$Q$5:$Q$260,'Cálculo FGP-FFM-FOFIR'!$B$5:$B$260,$A9,'Cálculo FGP-FFM-FOFIR'!$A$5:$A$260,"FGP*")/1000000 -> 215.67343 | F9: =SUMIFS('Cálculo FGP-FFM-FOFIR'!$Q$5:$Q$260,'Cálculo FGP-FFM-FOFIR'!$B$5:$B$260,$A9,'Cálculo FGP-FFM-FOFIR'!$A$5:$A$260,"FFM*")/1000000 -> 6.323959 | G9: =SUMIFS('Cálculo FGP-FFM-FOFIR'!$Q$5:$Q$260,'Cálculo FGP-FFM-FOFIR'!$B$5:$B$260,$A9,'Cálculo FGP-FFM-FOFIR'!$A$5:$A$260,"FOFIR*")/1000000 -> 11.859789 | H9: =SUM(E9:G9) -> 233.85718 | I9: =H9/('Base 2027'!N7/1000000) -> 0.027503349 | J9: ='Cálculo FoCo'!Q7/1000000 -> 0 | K9: =H9+J9 -> 233.85718
A10: Campeche | B10: =Población!B8 -> 935371 | C10: =Población!D8 -> 968673 | D10: =C10/B10-1 -> 0.035602985 | E10: =SUMIFS('Cálculo FGP-FFM-FOFIR'!$Q$5:$Q$260,'Cálculo FGP-FFM-FOFIR'!$B$5:$B$260,$A10,'Cálculo FGP-FFM-FOFIR'!$A$5:$A$260,"FGP*")/1000000 -> 184.6727 | F10: =SUMIFS('Cálculo FGP-FFM-FOFIR'!$Q$5:$Q$260,'Cálculo FGP-FFM-FOFIR'!$B$5:$B$260,$A10,'Cálculo FGP-FFM-FOFIR'!$A$5:$A$260,"FFM*")/1000000 -> 6.4641101 | G10: =SUMIFS('Cálculo FGP-FFM-FOFIR'!$Q$5:$Q$260,'Cálculo FGP-FFM-FOFIR'!$B$5:$B$260,$A10,'Cálculo FGP-FFM-FOFIR'!$A$5:$A$260,"FOFIR*")/1000000 -> 5.844597 | H10: =SUM(E10:G10) -> 196.98141 | I10: =H10/('Base 2027'!N8/1000000) -> 0.02316048 | J10: ='Cálculo FoCo'!Q8/1000000 -> 0 | K10: =H10+J10 -> 196.98141
A11: Coahuila | B11: =Población!B9 -> 3590747 | C11: =Población!D9 -> 3415128 | D11: =C11/B11-1 -> -0.048908765 | E11: =SUMIFS('Cálculo FGP-FFM-FOFIR'!$Q$5:$Q$260,'Cálculo FGP-FFM-FOFIR'!$B$5:$B$260,$A11,'Cálculo FGP-FFM-FOFIR'!$A$5:$A$260,"FGP*")/1000000 -> -1092.5913 | F11: =SUMIFS('Cálculo FGP-FFM-FOFIR'!$Q$5:$Q$260,'Cálculo FGP-FFM-FOFIR'!$B$5:$B$260,$A11,'Cálculo FGP-FFM-FOFIR'!$A$5:$A$260,"FFM*")/1000000 -> -32.075728 | G11: =SUMIFS('Cálculo FGP-FFM-FOFIR'!$Q$5:$Q$260,'Cálculo FGP-FFM-FOFIR'!$B$5:$B$260,$A11,'Cálculo FGP-FFM-FOFIR'!$A$5:$A$260,"FOFIR*")/1000000 -> -45.974416 | H11: =SUM(E11:G11) -> -1170.6414 | I11: =H11/('Base 2027'!N9/1000000) -> -0.036144789 | J11: ='Cálculo FoCo'!Q9/1000000 -> 0 | K11: =H11+J11 -> -1170.6414
A12: Colima | B12: =Población!B10 -> 762355 | C12: =Población!D10 -> 762212 | D12: =C12/B12-1 -> -0.00018757665 | E12: =SUMIFS('Cálculo FGP-FFM-FOFIR'!$Q$5:$Q$260,'Cálculo FGP-FFM-FOFIR'!$B$5:$B$260,$A12,'Cálculo FGP-FFM-FOFIR'!$A$5:$A$260,"FGP*")/1000000 -> 7.8035347 | F12: =SUMIFS('Cálculo FGP-FFM-FOFIR'!$Q$5:$Q$260,'Cálculo FGP-FFM-FOFIR'!$B$5:$B$260,$A12,'Cálculo FGP-FFM-FOFIR'!$A$5:$A$260,"FFM*")/1000000 -> 0.2447844 | G12: =SUMIFS('Cálculo FGP-FFM-FOFIR'!$Q$5:$Q$260,'Cálculo FGP-FFM-FOFIR'!$B$5:$B$260,$A12,'Cálculo FGP-FFM-FOFIR'!$A$5:$A$260,"FOFIR*")/1000000 -> 0.083903961 | H12: =SUM(E12:G12) -> 8.132223 | I12: =H12/('Base 2027'!N10/1000000) -> 0.0011091833 | J12: ='Cálculo FoCo'!Q10/1000000 -> 0 | K12: =H12+J12 -> 8.132223
A13: Chiapas | B13: =Población!B11 -> 5891372 | C13: =Población!D11 -> 5860728 | D13: =C13/B13-1 -> -0.0052015048 | E13: =SUMIFS('Cálculo FGP-FFM-FOFIR'!$Q$5:$Q$260,'Cálculo FGP-FFM-FOFIR'!$B$5:$B$260,$A13,'Cálculo FGP-FFM-FOFIR'!$A$5:$A$260,"FGP*")/1000000 -> -124.7802 | F13: =SUMIFS('Cálculo FGP-FFM-FOFIR'!$Q$5:$Q$260,'Cálculo FGP-FFM-FOFIR'!$B$5:$B$260,$A13,'Cálculo FGP-FFM-FOFIR'!$A$5:$A$260,"FFM*")/1000000 -> -3.8102367 | G13: =SUMIFS('Cálculo FGP-FFM-FOFIR'!$Q$5:$Q$260,'Cálculo FGP-FFM-FOFIR'!$B$5:$B$260,$A13,'Cálculo FGP-FFM-FOFIR'!$A$5:$A$260,"FOFIR*")/1000000 -> -5.2329582 | H13: =SUM(E13:G13) -> -133.8234 | I13: =H13/('Base 2027'!N11/1000000) -> -0.0024076132 | J13: ='Cálculo FoCo'!Q11/1000000 -> -1.2837507 | K13: =H13+J13 -> -135.10715
A14: Chihuahua | B14: =Población!B12 -> 4015493 | C14: =Población!D12 -> 3903944 | D14: =C14/B14-1 -> -0.027779652 | E14: =SUMIFS('Cálculo FGP-FFM-FOFIR'!$Q$5:$Q$260,'Cálculo FGP-FFM-FOFIR'!$B$5:$B$260,$A14,'Cálculo FGP-FFM-FOFIR'!$A$5:$A$260,"FGP*")/1000000 -> -682.4961 | F14: =SUMIFS('Cálculo FGP-FFM-FOFIR'!$Q$5:$Q$260,'Cálculo FGP-FFM-FOFIR'!$B$5:$B$260,$A14,'Cálculo FGP-FFM-FOFIR'!$A$5:$A$260,"FFM*")/1000000 -> -20.08842 | G14: =SUMIFS('Cálculo FGP-FFM-FOFIR'!$Q$5:$Q$260,'Cálculo FGP-FFM-FOFIR'!$B$5:$B$260,$A14,'Cálculo FGP-FFM-FOFIR'!$A$5:$A$260,"FOFIR*")/1000000 -> -45.461337 | H14: =SUM(E14:G14) -> -748.04586 | I14: =H14/('Base 2027'!N12/1000000) -> -0.019560919 | J14: ='Cálculo FoCo'!Q12/1000000 -> 0 | K14: =H14+J14 -> -748.04586
A15: Ciudad de México | B15: =Población!B13 -> 9336468 | C15: =Población!D13 -> 9216407 | D15: =C15/B15-1 -> -0.01285936 | E15: =SUMIFS('Cálculo FGP-FFM-FOFIR'!$Q$5:$Q$260,'Cálculo FGP-FFM-FOFIR'!$B$5:$B$260,$A15,'Cálculo FGP-FFM-FOFIR'!$A$5:$A$260,"FGP*")/1000000 -> -825.47902 | F15: =SUMIFS('Cálculo FGP-FFM-FOFIR'!$Q$5:$Q$260,'Cálculo FGP-FFM-FOFIR'!$B$5:$B$260,$A15,'Cálculo FGP-FFM-FOFIR'!$A$5:$A$260,"FFM*")/1000000 -> -20.715112 | G15: =SUMIFS('Cálculo FGP-FFM-FOFIR'!$Q$5:$Q$260,'Cálculo FGP-FFM-FOFIR'!$B$5:$B$260,$A15,'Cálculo FGP-FFM-FOFIR'!$A$5:$A$260,"FOFIR*")/1000000 -> -38.222793 | H15: =SUM(E15:G15) -> -884.41692 | I15: =H15/('Base 2027'!N13/1000000) -> -0.0071077827 | J15: ='Cálculo FoCo'!Q13/1000000 -> 0 | K15: =H15+J15 -> -884.41692
A16: Durango | B16: =Población!B14 -> 1968132 | C16: =Población!D14 -> 1943290 | D16: =C16/B16-1 -> -0.012622121 | E16: =SUMIFS('Cálculo FGP-FFM-FOFIR'!$Q$5:$Q$260,'Cálculo FGP-FFM-FOFIR'!$B$5:$B$260,$A16,'Cálculo FGP-FFM-FOFIR'!$A$5:$A$260,"FGP*")/1000000 -> -135.92724 | F16: =SUMIFS('Cálculo FGP-FFM-FOFIR'!$Q$5:$Q$260,'Cálculo FGP-FFM-FOFIR'!$B$5:$B$260,$A16,'Cálculo FGP-FFM-FOFIR'!$A$5:$A$260,"FFM*")/1000000 -> -4.088664 | G16: =SUMIFS('Cálculo FGP-FFM-FOFIR'!$Q$5:$Q$260,'Cálculo FGP-FFM-FOFIR'!$B$5:$B$260,$A16,'Cálculo FGP-FFM-FOFIR'!$A$5:$A$260,"FOFIR*")/1000000 -> -16.314807 | H16: =SUM(E16:G16) -> -156.33071 | I16: =H16/('Base 2027'!N14/1000000) -> -0.0083548875 | J16: ='Cálculo FoCo'!Q14/1000000 -> 0 | K16: =H16+J16 -> -156.33071
A17: Guanajuato | B17: =Población!B15 -> 6402249 | C17: =Población!D15 -> 6446935 | D17: =C17/B17-1 -> 0.0069797348 | E17: =SUMIFS('Cálculo FGP-FFM-FOFIR'!$Q$5:$Q$260,'Cálculo FGP-FFM-FOFIR'!$B$5:$B$260,$A17,'Cálculo FGP-FFM-FOFIR'!$A$5:$A$260,"FGP*")/1000000 -> 382.42139 | F17: =SUMIFS('Cálculo FGP-FFM-FOFIR'!$Q$5:$Q$260,'Cálculo FGP-FFM-FOFIR'!$B$5:$B$260,$A17,'Cálculo FGP-FFM-FOFIR'!$A$5:$A$260,"FFM*")/1000000 -> 10.759386 | G17: =SUMIFS('Cálculo FGP-FFM-FOFIR'!$Q$5:$Q$260,'Cálculo FGP-FFM-FOFIR'!$B$5:$B$260,$A17,'Cálculo FGP-FFM-FOFIR'!$A$5:$A$260,"FOFIR*")/1000000 -> 15.35141 | H17: =SUM(E17:G17) -> 408.53218 | I17: =H17/('Base 2027'!N15/1000000) -> 0.0069280256 | J17: ='Cálculo FoCo'!Q15/1000000 -> 0 | K17: =H17+J17 -> 408.53218
A18: Guerrero | B18: =Población!B16 -> 3569633 | C18: =Población!D16 -> 3418902 | D18: =C18/B18-1 -> -0.042225909 | E18: =SUMIFS('Cálculo FGP-FFM-FOFIR'!$Q$5:$Q$260,'Cálculo FGP-FFM-FOFIR'!$B$5:$B$260,$A18,'Cálculo FGP-FFM-FOFIR'!$A$5:$A$260,"FGP*")/1000000 -> -893.04735 | F18: =SUMIFS('Cálculo FGP-FFM-FOFIR'!$Q$5:$Q$260,'Cálculo FGP-FFM-FOFIR'!$B$5:$B$260,$A18,'Cálculo FGP-FFM-FOFIR'!$A$5:$A$260,"FFM*")/1000000 -> -27.43964 | G18: =SUMIFS('Cálculo FGP-FFM-FOFIR'!$Q$5:$Q$260,'Cálculo FGP-FFM-FOFIR'!$B$5:$B$260,$A18,'Cálculo FGP-FFM-FOFIR'!$A$5:$A$260,"FOFIR*")/1000000 -> -29.859805 | H18: =SUM(E18:G18) -> -950.34679 | I18: =H18/('Base 2027'!N16/1000000) -> -0.03008924 | J18: ='Cálculo FoCo'!Q16/1000000 -> -43.648385 | K18: =H18+J18 -> -993.99518
... A38: Zacatecas | B38: =Población!B36 -> 1689186 | C38: =Población!D36 -> 1686419 | D38: =C38/B38-1 -> -0.0016380671 | E38: =SUMIFS('Cálculo FGP-FFM-FOFIR'!$Q$5:$Q$260,'Cálculo FGP-FFM-FOFIR'!$B$5:$B$260,$A38,'Cálculo FGP-FFM-FOFIR'!$A$5:$A$260,"FGP*")/1000000 -> 2.8172551 | F38: =SUMIFS('Cálculo FGP-FFM-FOFIR'!$Q$5:$Q$260,'Cálculo FGP-FFM-FOFIR'!$B$5:$B$260,$A38,'Cálculo FGP-FFM-FOFIR'!$A$5:$A$260,"FFM*")/1000000 -> 0.064257101 | G38: =SUMIFS('Cálculo FGP-FFM-FOFIR'!$Q$5:$Q$260,'Cálculo FGP-FFM-FOFIR'!$B$5:$B$260,$A38,'Cálculo FGP-FFM-FOFIR'!$A$5:$A$260,"FOFIR*")/1000000 -> -0.3001897 | H38: =SUM(E38:G38) -> 2.5813225 | I38: =H38/('Base 2027'!N36/1000000) -> 0.00015590383 | J38: ='Cálculo FoCo'!Q36/1000000 -> 10.404434 | K38: =H38+J38 -> 12.985756
A39: Total | B39: =SUM(B7:B38) -> 131150866 | C39: =SUM(C7:C38) -> 130911314 | D39: =C39/B39-1 -> -0.0018265377 | E39: =SUM(E7:E38) -> -2.9310332e-11 | F39: =SUM(F7:F38) -> -3.3998498e-12 | G39: =SUM(G7:G38) -> 4.4917403e-12 | H39: =SUM(H7:H38) -> -2.8728131e-11 | J39: =SUM(J7:J38) -> -4.7251092e-13 | K39: =SUM(K7:K38) -> -2.8212099e-11
A41: Fondo de Compensación: se calcula aparte con la ENOE 4T-2024 que usa la SHCP para ese fondo; es igual en todos los escenarios. % sobre las participaciones 2027 estimadas (pestaña Base 2027).

Sheet Rango entre trimestres
A1: Rango entre trimestres: efecto anual 2027 (FGP+FFM+FOFIR, mdp) según la ENOE que se tome como base
A2: Misma Intercensal, mismas variables y montos; solo cambia el trimestre de la ENOE con el que se compara. Un rango grande indica que el resultado del estado depende del trimestre (la ENOE varía entre trimestres).
A4: Estado | B4: ENOE 3T-2025 | C4: ENOE 4T-2025 (misma fecha) | D4: ENOE 1T-2026 (vigente SHCP) | E4: ENOE 2T-2026 | F4: Mínimo | G4: Máximo | H4: Rango (máx − mín) | I4: Promedio | J4: Lectura
A5: Aguascalientes | B5: =SUMIFS('Cálculo FGP-FFM-FOFIR'!$U$5:$U$260,'Cálculo FGP-FFM-FOFIR'!$B$5:$B$260,$A5)/1000000 -> 225.30185 | C5: =SUMIFS('Cálculo FGP-FFM-FOFIR'!$Y$5:$Y$260,'Cálculo FGP-FFM-FOFIR'!$B$5:$B$260,$A5)/1000000 -> 136.47007 | D5: =SUMIFS('Cálculo FGP-FFM-FOFIR'!$Q$5:$Q$260,'Cálculo FGP-FFM-FOFIR'!$B$5:$B$260,$A5)/1000000 -> 69.83551 | E5: =SUMIFS('Cálculo FGP-FFM-FOFIR'!$AC$5:$AC$260,'Cálculo FGP-FFM-FOFIR'!$B$5:$B$260,$A5)/1000000 -> -101.97922 | F5: =MIN(B5:E5) -> -101.97922 | G5: =MAX(B5:E5) -> 225.30185 | H5: =G5-F5 -> 327.28107 | I5: =AVERAGE(B5:E5) -> 82.407054 | J5: =IF(G5<0,"Pierde en todos los trimestres",IF(F5>0,"Gana en todos los trimestres","Depende del trimestre")) -> Depende del trimestre
A6: Baja California | B6: =SUMIFS('Cálculo FGP-FFM-FOFIR'!$U$5:$U$260,'Cálculo FGP-FFM-FOFIR'!$B$5:$B$260,$A6)/1000000 -> 1687.0551 | C6: =SUMIFS('Cálculo FGP-FFM-FOFIR'!$Y$5:$Y$260,'Cálculo FGP-FFM-FOFIR'!$B$5:$B$260,$A6)/1000000 -> 1651.3205 | D6: =SUMIFS('Cálculo FGP-FFM-FOFIR'!$Q$5:$Q$260,'Cálculo FGP-FFM-FOFIR'!$B$5:$B$260,$A6)/1000000 -> 1384.584 | E6: =SUMIFS('Cálculo FGP-FFM-FOFIR'!$AC$5:$AC$260,'Cálculo FGP-FFM-FOFIR'!$B$5:$B$260,$A6)/1000000 -> 1158.8432 | F6: =MIN(B6:E6) -> 1158.8432 | G6: =MAX(B6:E6) -> 1687.0551 | H6: =G6-F6 -> 528.21198 | I6: =AVERAGE(B6:E6) -> 1470.4507 | J6: =IF(G6<0,"Pierde en todos los trimestres",IF(F6>0,"Gana en todos los trimestres","Depende del trimestre")) -> Gana en todos los trimestres
A7: Baja California Sur | B7: =SUMIFS('Cálculo FGP-FFM-FOFIR'!$U$5:$U$260,'Cálculo FGP-FFM-FOFIR'!$B$5:$B$260,$A7)/1000000 -> 536.39164 | C7: =SUMIFS('Cálculo FGP-FFM-FOFIR'!$Y$5:$Y$260,'Cálculo FGP-FFM-FOFIR'!$B$5:$B$260,$A7)/1000000 -> 373.21094 | D7: =SUMIFS('Cálculo FGP-FFM-FOFIR'!$Q$5:$Q$260,'Cálculo FGP-FFM-FOFIR'!$B$5:$B$260,$A7)/1000000 -> 233.85718 | E7: =SUMIFS('Cálculo FGP-FFM-FOFIR'!$AC$5:$AC$260,'Cálculo FGP-FFM-FOFIR'!$B$5:$B$260,$A7)/1000000 -> 23.412748 | F7: =MIN(B7:E7) -> 23.412748 | G7: =MAX(B7:E7) -> 536.39164 | H7: =G7-F7 -> 512.9789 | I7: =AVERAGE(B7:E7) -> 291.71813 | J7: =IF(G7<0,"Pierde en todos los trimestres",IF(F7>0,"Gana en todos los trimestres","Depende del trimestre")) -> Gana en todos los trimestres
A8: Campeche | B8: =SUMIFS('Cálculo FGP-FFM-FOFIR'!$U$5:$U$260,'Cálculo FGP-FFM-FOFIR'!$B$5:$B$260,$A8)/1000000 -> 234.20832 | C8: =SUMIFS('Cálculo FGP-FFM-FOFIR'!$Y$5:$Y$260,'Cálculo FGP-FFM-FOFIR'!$B$5:$B$260,$A8)/1000000 -> 284.14953 | D8: =SUMIFS('Cálculo FGP-FFM-FOFIR'!$Q$5:$Q$260,'Cálculo FGP-FFM-FOFIR'!$B$5:$B$260,$A8)/1000000 -> 196.98141 | E8: =SUMIFS('Cálculo FGP-FFM-FOFIR'!$AC$5:$AC$260,'Cálculo FGP-FFM-FOFIR'!$B$5:$B$260,$A8)/1000000 -> 106.29982 | F8: =MIN(B8:E8) -> 106.29982 | G8: =MAX(B8:E8) -> 284.14953 | H8: =G8-F8 -> 177.84971 | I8: =AVERAGE(B8:E8) -> 205.40977 | J8: =IF(G8<0,"Pierde en todos los trimestres",IF(F8>0,"Gana en todos los trimestres","Depende del trimestre")) -> Gana en todos los trimestres
A9: Coahuila | B9: =SUMIFS('Cálculo FGP-FFM-FOFIR'!$U$5:$U$260,'Cálculo FGP-FFM-FOFIR'!$B$5:$B$260,$A9)/1000000 -> -286.70974 | C9: =SUMIFS('Cálculo FGP-FFM-FOFIR'!$Y$5:$Y$260,'Cálculo FGP-FFM-FOFIR'!$B$5:$B$260,$A9)/1000000 -> -1139.6822 | D9: =SUMIFS('Cálculo FGP-FFM-FOFIR'!$Q$5:$Q$260,'Cálculo FGP-FFM-FOFIR'!$B$5:$B$260,$A9)/1000000 -> -1170.6414 | E9: =SUMIFS('Cálculo FGP-FFM-FOFIR'!$AC$5:$AC$260,'Cálculo FGP-FFM-FOFIR'!$B$5:$B$260,$A9)/1000000 -> -604.76308 | F9: =MIN(B9:E9) -> -1170.6414 | G9: =MAX(B9:E9) -> -286.70974 | H9: =G9-F9 -> 883.9317 | I9: =AVERAGE(B9:E9) -> -800.44912 | J9: =IF(G9<0,"Pierde en todos los trimestres",IF(F9>0,"Gana en todos los trimestres","Depende del trimestre")) -> Pierde en todos los trimestres
A10: Colima | B10: =SUMIFS('Cálculo FGP-FFM-FOFIR'!$U$5:$U$260,'Cálculo FGP-FFM-FOFIR'!$B$5:$B$260,$A10)/1000000 -> 211.63876 | C10: =SUMIFS('Cálculo FGP-FFM-FOFIR'!$Y$5:$Y$260,'Cálculo FGP-FFM-FOFIR'!$B$5:$B$260,$A10)/1000000 -> 112.65946 | D10: =SUMIFS('Cálculo FGP-FFM-FOFIR'!$Q$5:$Q$260,'Cálculo FGP-FFM-FOFIR'!$B$5:$B$260,$A10)/1000000 -> 8.132223 | E10: =SUMIFS('Cálculo FGP-FFM-FOFIR'!$AC$5:$AC$260,'Cálculo FGP-FFM-FOFIR'!$B$5:$B$260,$A10)/1000000 -> -45.466153 | F10: =MIN(B10:E10) -> -45.466153 | G10: =MAX(B10:E10) -> 211.63876 | H10: =G10-F10 -> 257.10492 | I10: =AVERAGE(B10:E10) -> 71.741073 | J10: =IF(G10<0,"Pierde en todos los trimestres",IF(F10>0,"Gana en todos los trimestres","Depende del trimestre")) -> Depende del trimestre
A11: Chiapas | B11: =SUMIFS('Cálculo FGP-FFM-FOFIR'!$U$5:$U$260,'Cálculo FGP-FFM-FOFIR'!$B$5:$B$260,$A11)/1000000 -> -829.21199 | C11: =SUMIFS('Cálculo FGP-FFM-FOFIR'!$Y$5:$Y$260,'Cálculo FGP-FFM-FOFIR'!$B$5:$B$260,$A11)/1000000 -> -240.36952 | D11: =SUMIFS('Cálculo FGP-FFM-FOFIR'!$Q$5:$Q$260,'Cálculo FGP-FFM-FOFIR'!$B$5:$B$260,$A11)/1000000 -> -133.8234 | E11: =SUMIFS('Cálculo FGP-FFM-FOFIR'!$AC$5:$AC$260,'Cálculo FGP-FFM-FOFIR'!$B$5:$B$260,$A11)/1000000 -> -70.701695 | F11: =MIN(B11:E11) -> -829.21199 | G11: =MAX(B11:E11) -> -70.701695 | H11: =G11-F11 -> 758.51029 | I11: =AVERAGE(B11:E11) -> -318.52665 | J11: =IF(G11<0,"Pierde en todos los trimestres",IF(F11>0,"Gana en todos los trimestres","Depende del trimestre")) -> Pierde en todos los trimestres
A12: Chihuahua | B12: =SUMIFS('Cálculo FGP-FFM-FOFIR'!$U$5:$U$260,'Cálculo FGP-FFM-FOFIR'!$B$5:$B$260,$A12)/1000000 -> -547.56752 | C12: =SUMIFS('Cálculo FGP-FFM-FOFIR'!$Y$5:$Y$260,'Cálculo FGP-FFM-FOFIR'!$B$5:$B$260,$A12)/1000000 -> -603.84675 | D12: =SUMIFS('Cálculo FGP-FFM-FOFIR'!$Q$5:$Q$260,'Cálculo FGP-FFM-FOFIR'!$B$5:$B$260,$A12)/1000000 -> -748.04586 | E12: =SUMIFS('Cálculo FGP-FFM-FOFIR'!$AC$5:$AC$260,'Cálculo FGP-FFM-FOFIR'!$B$5:$B$260,$A12)/1000000 -> -520.53144 | F12: =MIN(B12:E12) -> -748.04586 | G12: =MAX(B12:E12) -> -520.53144 | H12: =G12-F12 -> 227.51441 | I12: =AVERAGE(B12:E12) -> -604.99789 | J12: =IF(G12<0,"Pierde en todos los trimestres",IF(F12>0,"Gana en todos los trimestres","Depende del trimestre")) -> Pierde en todos los trimestres
A13: Ciudad de México | B13: =SUMIFS('Cálculo FGP-FFM-FOFIR'!$U$5:$U$260,'Cálculo FGP-FFM-FOFIR'!$B$5:$B$260,$A13)/1000000 -> -1255.07 | C13: =SUMIFS('Cálculo FGP-FFM-FOFIR'!$Y$5:$Y$260,'Cálculo FGP-FFM-FOFIR'!$B$5:$B$260,$A13)/1000000 -> -807.41694 | D13: =SUMIFS('Cálculo FGP-FFM-FOFIR'!$Q$5:$Q$260,'Cálculo FGP-FFM-FOFIR'!$B$5:$B$260,$A13)/1000000 -> -884.41692 | E13: =SUMIFS('Cálculo FGP-FFM-FOFIR'!$AC$5:$AC$260,'Cálculo FGP-FFM-FOFIR'!$B$5:$B$260,$A13)/1000000 -> -503.07673 | F13: =MIN(B13:E13) -> -1255.07 | G13: =MAX(B13:E13) -> -503.07673 | H13: =G13-F13 -> 751.99323 | I13: =AVERAGE(B13:E13) -> -862.49514 | J13: =IF(G13<0,"Pierde en todos los trimestres",IF(F13>0,"Gana en todos los trimestres","Depende del trimestre")) -> Pierde en todos los trimestres
A14: Durango | B14: =SUMIFS('Cálculo FGP-FFM-FOFIR'!$U$5:$U$260,'Cálculo FGP-FFM-FOFIR'!$B$5:$B$260,$A14)/1000000 -> -27.943752 | C14: =SUMIFS('Cálculo FGP-FFM-FOFIR'!$Y$5:$Y$260,'Cálculo FGP-FFM-FOFIR'!$B$5:$B$260,$A14)/1000000 -> -72.771752 | D14: =SUMIFS('Cálculo FGP-FFM-FOFIR'!$Q$5:$Q$260,'Cálculo FGP-FFM-FOFIR'!$B$5:$B$260,$A14)/1000000 -> -156.33071 | E14: =SUMIFS('Cálculo FGP-FFM-FOFIR'!$AC$5:$AC$260,'Cálculo FGP-FFM-FOFIR'!$B$5:$B$260,$A14)/1000000 -> -85.49567 | F14: =MIN(B14:E14) -> -156.33071 | G14: =MAX(B14:E14) -> -27.943752 | H14: =G14-F14 -> 128.38696 | I14: =AVERAGE(B14:E14) -> -85.635472 | J14: =IF(G14<0,"Pierde en todos los trimestres",IF(F14>0,"Gana en todos los trimestres","Depende del trimestre")) -> Pierde en todos los trimestres
A15: Guanajuato | B15: =SUMIFS('Cálculo FGP-FFM-FOFIR'!$U$5:$U$260,'Cálculo FGP-FFM-FOFIR'!$B$5:$B$260,$A15)/1000000 -> 680.499 | C15: =SUMIFS('Cálculo FGP-FFM-FOFIR'!$Y$5:$Y$260,'Cálculo FGP-FFM-FOFIR'!$B$5:$B$260,$A15)/1000000 -> 543.89462 | D15: =SUMIFS('Cálculo FGP-FFM-FOFIR'!$Q$5:$Q$260,'Cálculo FGP-FFM-FOFIR'!$B$5:$B$260,$A15)/1000000 -> 408.53218 | E15: =SUMIFS('Cálculo FGP-FFM-FOFIR'!$AC$5:$AC$260,'Cálculo FGP-FFM-FOFIR'!$B$5:$B$260,$A15)/1000000 -> 217.12081 | F15: =MIN(B15:E15) -> 217.12081 | G15: =MAX(B15:E15) -> 680.499 | H15: =G15-F15 -> 463.37819 | I15: =AVERAGE(B15:E15) -> 462.51165 | J15: =IF(G15<0,"Pierde en todos los trimestres",IF(F15>0,"Gana en todos los trimestres","Depende del trimestre")) -> Gana en todos los trimestres
A16: Guerrero | B16: =SUMIFS('Cálculo FGP-FFM-FOFIR'!$U$5:$U$260,'Cálculo FGP-FFM-FOFIR'!$B$5:$B$260,$A16)/1000000 -> -1263.7342 | C16: =SUMIFS('Cálculo FGP-FFM-FOFIR'!$Y$5:$Y$260,'Cálculo FGP-FFM-FOFIR'!$B$5:$B$260,$A16)/1000000 -> -1035.3907 | D16: =SUMIFS('Cálculo FGP-FFM-FOFIR'!$Q$5:$Q$260,'Cálculo FGP-FFM-FOFIR'!$B$5:$B$260,$A16)/1000000 -> -950.34679 | E16: =SUMIFS('Cálculo FGP-FFM-FOFIR'!$AC$5:$AC$260,'Cálculo FGP-FFM-FOFIR'!$B$5:$B$260,$A16)/1000000 -> -730.10613 | F16: =MIN(B16:E16) -> -1263.7342 | G16: =MAX(B16:E16) -> -730.10613 | H16: =G16-F16 -> 533.62805 | I16: =AVERAGE(B16:E16) -> -994.89445 | J16: =IF(G16<0,"Pierde en todos los trimestres",IF(F16>0,"Gana en todos los trimestres","Depende del trimestre")) -> Pierde en todos los trimestres
... A36: Zacatecas | B36: =SUMIFS('Cálculo FGP-FFM-FOFIR'!$U$5:$U$260,'Cálculo FGP-FFM-FOFIR'!$B$5:$B$260,$A36)/1000000 -> -76.246381 | C36: =SUMIFS('Cálculo FGP-FFM-FOFIR'!$Y$5:$Y$260,'Cálculo FGP-FFM-FOFIR'!$B$5:$B$260,$A36)/1000000 -> -111.46445 | D36: =SUMIFS('Cálculo FGP-FFM-FOFIR'!$Q$5:$Q$260,'Cálculo FGP-FFM-FOFIR'!$B$5:$B$260,$A36)/1000000 -> 2.5813225 | E36: =SUMIFS('Cálculo FGP-FFM-FOFIR'!$AC$5:$AC$260,'Cálculo FGP-FFM-FOFIR'!$B$5:$B$260,$A36)/1000000 -> -31.316445 | F36: =MIN(B36:E36) -> -111.46445 | G36: =MAX(B36:E36) -> 2.5813225 | H36: =G36-F36 -> 114.04578 | I36: =AVERAGE(B36:E36) -> -54.111489 | J36: =IF(G36<0,"Pierde en todos los trimestres",IF(F36>0,"Gana en todos los trimestres","Depende del trimestre")) -> Depende del trimestre
A37: Redistribución total | B37: =-SUMIF(B5:B36,"<0") -> 9502.7497 | C37: =-SUMIF(C5:C36,"<0") -> 8140.5731 | D37: =-SUMIF(D5:D36,"<0") -> 7178.6253 | E37: =-SUMIF(E5:E36,"<0") -> 4439.5252
A38: Población ENOE total | B38: =Población!K37 -> 130760049 | C38: =Población!L37 -> 131001723 | D38: =Población!B37 -> 131150866 | E38: =Población!M37 -> 131231919
A39: Intercensal 2025 (15-oct-2025): 130,911,314 personas.
A41: No incluye el Fondo de Compensación (usa la ENOE 4T-2024 y no depende de este trimestre).

Sheet Evidencia ajuste 2026
A1: Evidencia 2026: el 1er ajuste cuatrimestral ya corrigió enero-abril con una población más reciente
A2: Millones de pesos. Fuente: DOF de junio 2026 (publicado 27-jul-2026), Cuadro 35, y DOF de enero a abril 2026.
A3: Enero y febrero 2026 se pagaron con la ENOE 3T-2025 y marzo y abril con la 4T-2025. En junio la SHCP recalculó enero-abril con la ENOE 1T-2026 y con variables de recaudación local más recientes, y pagó la diferencia en el ajuste. Aquí se separa qué parte se debió solo al cambio de población (con las variables de junio fijas) y qué parte a las variables; el resto es la recaudación federal participable observada y el IEPS.
A5: Estado | B5: Diferencia total del ajuste (DOF) | C5: Por cambio de población (FGP y FFM 70%) | D5: Por cambio de variables (FGP y FFM 70%) | E5: Resto (recaudación federal participable, IEPS)
A6: Aguascalientes | B6: 260.94771 | C6: =SUMIFS('Cálculo ajuste 2026'!$Z$5:$Z$516,'Cálculo ajuste 2026'!$C$5:$C$516,$A6)/1000000 -> 33.183222 | D6: =SUMIFS('Cálculo ajuste 2026'!$AA$5:$AA$516,'Cálculo ajuste 2026'!$C$5:$C$516,$A6)/1000000 -> 34.827281 | E6: =B6-C6-D6 -> 192.9372
A7: Baja California | B7: 512.75678 | C7: =SUMIFS('Cálculo ajuste 2026'!$Z$5:$Z$516,'Cálculo ajuste 2026'!$C$5:$C$516,$A7)/1000000 -> 84.876027 | D7: =SUMIFS('Cálculo ajuste 2026'!$AA$5:$AA$516,'Cálculo ajuste 2026'!$C$5:$C$516,$A7)/1000000 -> -93.0834 | E7: =B7-C7-D7 -> 520.96415
A8: Baja California Sur | B8: 119.04174 | C8: =SUMIFS('Cálculo ajuste 2026'!$Z$5:$Z$516,'Cálculo ajuste 2026'!$C$5:$C$516,$A8)/1000000 -> 65.838983 | D8: =SUMIFS('Cálculo ajuste 2026'!$AA$5:$AA$516,'Cálculo ajuste 2026'!$C$5:$C$516,$A8)/1000000 -> -26.289219 | E8: =B8-C8-D8 -> 79.491979
A9: Campeche | B9: 43.92298 | C9: =SUMIFS('Cálculo ajuste 2026'!$Z$5:$Z$516,'Cálculo ajuste 2026'!$C$5:$C$516,$A9)/1000000 -> 18.863099 | D9: =SUMIFS('Cálculo ajuste 2026'!$AA$5:$AA$516,'Cálculo ajuste 2026'!$C$5:$C$516,$A9)/1000000 -> -46.708042 | E9: =B9-C9-D9 -> 71.767924
A10: Coahuila | B10: 602.70014 | C10: =SUMIFS('Cálculo ajuste 2026'!$Z$5:$Z$516,'Cálculo ajuste 2026'!$C$5:$C$516,$A10)/1000000 -> 139.51855 | D10: =SUMIFS('Cálculo ajuste 2026'!$AA$5:$AA$516,'Cálculo ajuste 2026'!$C$5:$C$516,$A10)/1000000 -> 75.991906 | E10: =B10-C10-D10 -> 387.18969
A11: Colima | B11: 127.25678 | C11: =SUMIFS('Cálculo ajuste 2026'!$Z$5:$Z$516,'Cálculo ajuste 2026'!$C$5:$C$516,$A11)/1000000 -> 46.759877 | D11: =SUMIFS('Cálculo ajuste 2026'!$AA$5:$AA$516,'Cálculo ajuste 2026'!$C$5:$C$516,$A11)/1000000 -> 9.8610644 | E11: =B11-C11-D11 -> 70.635834
A12: Chiapas | B12: 1099.3201 | C12: =SUMIFS('Cálculo ajuste 2026'!$Z$5:$Z$516,'Cálculo ajuste 2026'!$C$5:$C$516,$A12)/1000000 -> -122.86348 | D12: =SUMIFS('Cálculo ajuste 2026'!$AA$5:$AA$516,'Cálculo ajuste 2026'!$C$5:$C$516,$A12)/1000000 -> 584.5101 | E12: =B12-C12-D12 -> 637.67352
A13: Chihuahua | B13: 304.90928 | C13: =SUMIFS('Cálculo ajuste 2026'!$Z$5:$Z$516,'Cálculo ajuste 2026'!$C$5:$C$516,$A13)/1000000 -> 51.46114 | D13: =SUMIFS('Cálculo ajuste 2026'!$AA$5:$AA$516,'Cálculo ajuste 2026'!$C$5:$C$516,$A13)/1000000 -> -167.40063 | E13: =B13-C13-D13 -> 420.84877
A14: Ciudad de México | B14: 2505.9281 | C14: =SUMIFS('Cálculo ajuste 2026'!$Z$5:$Z$516,'Cálculo ajuste 2026'!$C$5:$C$516,$A14)/1000000 -> -44.086462 | D14: =SUMIFS('Cálculo ajuste 2026'!$AA$5:$AA$516,'Cálculo ajuste 2026'!$C$5:$C$516,$A14)/1000000 -> 931.94637 | E14: =B14-C14-D14 -> 1618.0682
A15: Durango | B15: 242.81293 | C15: =SUMIFS('Cálculo ajuste 2026'!$Z$5:$Z$516,'Cálculo ajuste 2026'!$C$5:$C$516,$A15)/1000000 -> 30.648873 | D15: =SUMIFS('Cálculo ajuste 2026'!$AA$5:$AA$516,'Cálculo ajuste 2026'!$C$5:$C$516,$A15)/1000000 -> 0.53234892 | E15: =B15-C15-D15 -> 211.6317
A16: Guanajuato | B16: 642.57966 | C16: =SUMIFS('Cálculo ajuste 2026'!$Z$5:$Z$516,'Cálculo ajuste 2026'!$C$5:$C$516,$A16)/1000000 -> 61.038785 | D16: =SUMIFS('Cálculo ajuste 2026'!$AA$5:$AA$516,'Cálculo ajuste 2026'!$C$5:$C$516,$A16)/1000000 -> -93.252768 | E16: =B16-C16-D16 -> 674.79364
A17: Guerrero | B17: 503.28469 | C17: =SUMIFS('Cálculo ajuste 2026'!$Z$5:$Z$516,'Cálculo ajuste 2026'!$C$5:$C$516,$A17)/1000000 -> -60.815218 | D17: =SUMIFS('Cálculo ajuste 2026'!$AA$5:$AA$516,'Cálculo ajuste 2026'!$C$5:$C$516,$A17)/1000000 -> 134.71998 | E17: =B17-C17-D17 -> 429.37993
... A37: Zacatecas | B37: 197.09086 | C37: =SUMIFS('Cálculo ajuste 2026'!$Z$5:$Z$516,'Cálculo ajuste 2026'!$C$5:$C$516,$A37)/1000000 -> -29.210024 | D37: =SUMIFS('Cálculo ajuste 2026'!$AA$5:$AA$516,'Cálculo ajuste 2026'!$C$5:$C$516,$A37)/1000000 -> 61.535897 | E37: =B37-C37-D37 -> 164.76498
A38: Total | B38: =SUM(B6:B37) -> 15151.455 | C38: =SUM(C6:C37) -> -9.2121866e-12 | D38: =SUM(D6:D37) -> 1.8836488e-11 | E38: =SUM(E6:E37) -> 15151.455
A39: Monto movido solo por población (suma de lo que pierden los que pierden): | C39: =-SUMIF(C6:C37,"<0") -> 938.96382

Sheet Fondos 2027
A1: Montos 2027 a distribuir (PPEF 2027, Ramo 28) y partes que usan población
A2: Pesos. Fuente: PPEF 2027, Tomo IV, Ramo 28, Análisis Funcional Programático Económico (septiembre 2026). Azul = dato; negro = fórmula.
A4: Concepto | B4: Monto (pesos) | C4: Cómo se obtiene
A5: Fondo General de Participaciones (PPEF 2027) | B5: 1146547607219 | C5: PPEF 2027, C001
A6: Fondo de Fomento Municipal (PPEF 2027) | B6: 57227524535 | C6: PPEF 2027, C002
A7: Fondo de Fiscalización y Recaudación (PPEF 2027) | B7: 71534405671 | C7: PPEF 2027, C005
A8: Fondo de Compensación (PPEF 2027) | B8: 8041200000 | C8: PPEF 2027, C006
A9: 0.136% de la RFP (PPEF 2027) | B9: 7782943337 | C9: PPEF 2027, C009
A10: Recaudación federal participable 2027 implícita | B10: =B9/0.00136 -> 5.7227525e+12 | C10: 0.136% de la RFP / 0.00136 (cuadra con FFM = 1% de la RFP)
A11: FGP base 2007 (anual) | B11: 265828053996 | C11: 12 × 22,152,337,833 (DOF, Cuadro 2, renglón 4)
A12: FFM base 2013 (anual) | B12: 21339511050 | C12: DOF, ajuste definitivo (Integración del FFM)
A13: FOFIR base 2013 (anual) | B13: 26674388812 | C13: 2 × 13,337,194,406 (DOF jul-2026, Cuadro 26, renglón 4, semestral)
A14: Crecimiento FGP 2027 (20% RFP − base 2007) | B14: =0.2*B10-B11 -> 8.7872244e+11
A15: Crecimiento FFM 2027 (1% RFP − base 2013) | B15: =0.01*B10-B12 -> 3.5888013e+10
A16: Crecimiento FOFIR 2027 (1.25% RFP − base 2013) | B16: =0.0125*B10-B13 -> 4.4860017e+10
A18: Partes que se reparten con población
A19: Parte | B19: Monto 2027 (pesos) | C19: Regla
A20: FGP primera parte (60%) | B20: =B14*0.6 -> 5.2723346e+11 | C20: 60% del crecimiento: crecimiento del PIB × población
A21: FGP segunda parte (30%) | B21: =B14*0.3 -> 2.6361673e+11 | C21: 30%: media móvil del crecimiento de recaudación local × población
A22: FGP tercera parte (10%) | B22: =B14*0.1 -> 8.7872244e+10 | C22: 10%: recaudación local × población
A23: FFM 70% | B23: =B15*0.7 -> 2.5121609e+10 | C23: 70% del crecimiento: variación de agua y predial × población
A24: FOFIR primera parte (30%) | B24: =B16*0.3 -> 1.3458005e+10 | C24: Cifras virtuales / PIB × población
A25: FOFIR segunda parte (10%) | B25: =B16*0.1 -> 4.4860017e+09 | C25: Mercancía embargada × población
A26: FOFIR tercera parte (30%) | B26: =B16*0.3 -> 1.3458005e+10 | C26: Crecimiento de recaudación local × población
A27: FOFIR cuarta parte (30%) | B27: =B16*0.3 -> 1.3458005e+10 | C27: Recaudación local / ingresos de libre disposición × población
A28: Fondo de Compensación | B28: =B8 -> 8041200000 | C28: 10 entidades con menor PIB per cápita no minero (población en el denominador)
A29: Total que depende de población | B29: =SUM(B20:B28) -> 9.5674526e+11
A31: No se recalculan: bases 2007 y 2013, BET, FFM 30% (población municipal del Censo 2020), IEPS, gasolinas 9/11, FEXHI, Fondo ISR, ISAN, incentivos.

Sheet Base 2027
A1: Participaciones 2027 estimadas por estado en FGP, FFM, FOFIR y FoCo (escenario base, población ENOE)
A2: Pesos. Partes fijas repartidas con la participación de cada estado en el último DOF (ago-2026; FOFIR jul-2026); partes que dependen de población con los coeficientes base. Se usa para expresar los efectos en %.
A4: Entidad | B4: FGP base 2007 (DOF ago-26, mensual) | C4: BET (DOF ago-26, mensual) | D4: FFM base 2013 (DOF ago-26, mensual) | E4: FFM 30% (DOF ago-26, mensual) | F4: FOFIR base 2013 (DOF jul-26, semestral) | G4: FGP base 2007 2027 | H4: BET 2027 | I4: FFM base 2013 2027 | J4: FFM 30% 2027 | K4: FOFIR base 2013 2027 | L4: Partes con población (base) | M4: FoCo (base) | N4: Total estimado 2027
A5: Aguascalientes | B5: 253448939 | C5: 1407175 | D5: 42831004 | E5: 12124756 | F5: 115157096 | G5: =B5/B$37*'Fondos 2027'!$B$11 -> 3.0413873e+09 | H5: =C5/C$37*('Fondos 2027'!$B$5-0.2*'Fondos 2027'!$B$10) -> 17431012 | I5: =D5/D$37*'Fondos 2027'!$B$12 -> 5.1397205e+08 | J5: =E5/E$37*'Fondos 2027'!$B$15*0.3 -> 1.8168924e+08 | K5: =F5/F$37*'Fondos 2027'!$B$13 -> 2.3031419e+08 | L5: =SUMIFS('Cálculo FGP-FFM-FOFIR'!$O$5:$O$260,'Cálculo FGP-FFM-FOFIR'!$B$5:$B$260,A5) -> 1.0180978e+10 | M5: ='Cálculo FoCo'!O5 -> 0 | N5: =SUM(G5:M5) -> 1.4165772e+10
A6: Baja California | B6: 635563001 | C6: 5275161 | D6: 29439346 | E6: 31249007 | F6: 327996822 | G6: =B6/B$37*'Fondos 2027'!$B$11 -> 7.626756e+09 | H6: =C6/C$37*('Fondos 2027'!$B$5-0.2*'Fondos 2027'!$B$10) -> 65344677 | I6: =D6/D$37*'Fondos 2027'!$B$12 -> 3.5327215e+08 | J6: =E6/E$37*'Fondos 2027'!$B$15*0.3 -> 4.6826579e+08 | K6: =F6/F$37*'Fondos 2027'!$B$13 -> 6.5599364e+08 | L6: =SUMIFS('Cálculo FGP-FFM-FOFIR'!$O$5:$O$260,'Cálculo FGP-FFM-FOFIR'!$B$5:$B$260,A6) -> 2.8307603e+10 | M6: ='Cálculo FoCo'!O6 -> 0 | N6: =SUM(G6:M6) -> 3.7477235e+10
A7: Baja California Sur | B7: 160245947 | C7: 1379021 | D7: 13281123 | E7: 0 | F7: 67064946 | G7: =B7/B$37*'Fondos 2027'!$B$11 -> 1.9229514e+09 | H7: =C7/C$37*('Fondos 2027'!$B$5-0.2*'Fondos 2027'!$B$10) -> 17082262 | I7: =D7/D$37*'Fondos 2027'!$B$12 -> 1.5937348e+08 | J7: =E7/E$37*'Fondos 2027'!$B$15*0.3 -> 0 | K7: =F7/F$37*'Fondos 2027'!$B$13 -> 1.3412989e+08 | L7: =SUMIFS('Cálculo FGP-FFM-FOFIR'!$O$5:$O$260,'Cálculo FGP-FFM-FOFIR'!$B$5:$B$260,A7) -> 6.2693249e+09 | M7: ='Cálculo FoCo'!O7 -> 0 | N7: =SUM(G7:M7) -> 8.5028619e+09
A8: Campeche | B8: 226439168 | C8: 1451237 | D8: 19893110 | E8: 6840785 | F8: 90342337 | G8: =B8/B$37*'Fondos 2027'!$B$11 -> 2.71727e+09 | H8: =C8/C$37*('Fondos 2027'!$B$5-0.2*'Fondos 2027'!$B$10) -> 17976819 | I8: =D8/D$37*'Fondos 2027'!$B$12 -> 2.3871732e+08 | J8: =E8/E$37*'Fondos 2027'!$B$15*0.3 -> 1.0250904e+08 | K8: =F8/F$37*'Fondos 2027'!$B$13 -> 1.8068467e+08 | L8: =SUMIFS('Cálculo FGP-FFM-FOFIR'!$O$5:$O$260,'Cálculo FGP-FFM-FOFIR'!$B$5:$B$260,A8) -> 5.247908e+09 | M8: ='Cálculo FoCo'!O8 -> 0 | N8: =SUM(G8:M8) -> 8.5050658e+09
A9: Coahuila | B9: 538189157 | C9: 4012589 | D9: 30379818 | E9: 8930495 | F9: 250445349 | G9: =B9/B$37*'Fondos 2027'!$B$11 -> 6.4582699e+09 | H9: =C9/C$37*('Fondos 2027'!$B$5-0.2*'Fondos 2027'!$B$10) -> 49704896 | I9: =D9/D$37*'Fondos 2027'!$B$12 -> 3.6455782e+08 | J9: =E9/E$37*'Fondos 2027'!$B$15*0.3 -> 1.338233e+08 | K9: =F9/F$37*'Fondos 2027'!$B$13 -> 5.008907e+08 | L9: =SUMIFS('Cálculo FGP-FFM-FOFIR'!$O$5:$O$260,'Cálculo FGP-FFM-FOFIR'!$B$5:$B$260,A9) -> 2.4880311e+10 | M9: ='Cálculo FoCo'!O9 -> 0 | N9: =SUM(G9:M9) -> 3.2387557e+10
A10: Colima | B10: 164236610 | C10: 578089 | D10: 23005209 | E10: 0 | F10: 69149770 | G10: =B10/B$37*'Fondos 2027'!$B$11 -> 1.9708393e+09 | H10: =C10/C$37*('Fondos 2027'!$B$5-0.2*'Fondos 2027'!$B$10) -> 7160926.2 | I10: =D10/D$37*'Fondos 2027'!$B$12 -> 2.7606251e+08 | J10: =E10/E$37*'Fondos 2027'!$B$15*0.3 -> 0 | K10: =F10/F$37*'Fondos 2027'!$B$13 -> 1.3829954e+08 | L10: =SUMIFS('Cálculo FGP-FFM-FOFIR'!$O$5:$O$260,'Cálculo FGP-FFM-FOFIR'!$B$5:$B$260,A10) -> 4.939359e+09 | M10: ='Cálculo FoCo'!O10 -> 0 | N10: =SUM(G10:M10) -> 7.3317213e+09
A11: Chiapas | B11: 1004369892 | C11: 13002615 | D11: 39872920 | E11: 17108259 | F11: 448422249 | G11: =B11/B$37*'Fondos 2027'!$B$11 -> 1.2052439e+10 | H11: =C11/C$37*('Fondos 2027'!$B$5-0.2*'Fondos 2027'!$B$10) -> 1.6106649e+08 | I11: =D11/D$37*'Fondos 2027'!$B$12 -> 4.7847504e+08 | J11: =E11/E$37*'Fondos 2027'!$B$15*0.3 -> 2.5636694e+08 | K11: =F11/F$37*'Fondos 2027'!$B$13 -> 8.968445e+08 | L11: =SUMIFS('Cálculo FGP-FFM-FOFIR'!$O$5:$O$260,'Cálculo FGP-FFM-FOFIR'!$B$5:$B$260,A11) -> 4.0409225e+10 | M11: ='Cálculo FoCo'!O11 -> 1.3290114e+09 | N11: =SUM(G11:M11) -> 5.5583429e+10
A12: Chihuahua | B12: 629999297 | C12: 14543564 | D12: 39996201 | E12: 29051215 | F12: 330999416 | G12: =B12/B$37*'Fondos 2027'!$B$11 -> 7.5599916e+09 | H12: =C12/C$37*('Fondos 2027'!$B$5-0.2*'Fondos 2027'!$B$10) -> 1.8015459e+08 | I12: =D12/D$37*'Fondos 2027'!$B$12 -> 4.7995441e+08 | J12: =E12/E$37*'Fondos 2027'!$B$15*0.3 -> 4.3533192e+08 | K12: =F12/F$37*'Fondos 2027'!$B$13 -> 6.6199883e+08 | L12: =SUMIFS('Cálculo FGP-FFM-FOFIR'!$O$5:$O$260,'Cálculo FGP-FFM-FOFIR'!$B$5:$B$260,A12) -> 2.8924426e+10 | M12: ='Cálculo FoCo'!O12 -> 0 | N12: =SUM(G12:M12) -> 3.8241857e+10
